Workbook
Name A11000000: #REF!
Name B11000000: #REF!
Name B1200000: #REF!
Name B9034357: #REF!
Name B9934357: #REF!
Name bizforms: "bizforms.co.kr"

Sheet 홀짝 소자배 기본
AN1: 9단위* 5분 | BK1: 10단위 | CH1: 이격수 | CT1: 15 | CW1: 15
A2: =COUNTA(B4:B56559) -> 300 | B2: 6조합 | I2: 1 | J2: 2 | K2: 3 | L2: 4 | M2: 5 | N2: 6 | P2: 홀 | Q2: 짝 | S2: 저 | T2: 고 | V2: 끝저고 | Y2: 소수 | Z2: 자연수 | AA2: 3배수 | AC2: 소 | AH2: 배 | AJ2: 1~14 | AK2: 15~30 | AL2: 31~45 | AN2: 9 | AO2: 18 | AP2: 27 | AQ2: 36 | AR2: 45 | AS2: 1 2 3 4 5 6 | BE2: =SUM(#REF!) -> #REF! | BG2: =SUM(#REF!) -> #REF! | BH2: 13하23상 | BK2: 단-10-20-30-40 | BP2: 1 2 3 4 5 6 | CB2: =SUM(#REF!) -> #REF! | CD2: =SUM(#REF!) -> #REF! | CE2: 13하23상 | CH2: 1 | CI2: 2 | CJ2: 3 | CK2: 4 | CL2: 5 | CN2: 1 | CO2: 2 | CP2: 3 | CQ2: 4 | CR2: 5 | CT2: 홀 | CU2: 짝 | CW2: 끝저고 | CZ2: 소 | DA2: 자 | DB2: 배 | DD2: 1 | DF2: 2 | DH2: 3 | DJ2: 4 | DL2: 5 | DS2: 배
B3: 1 | C3: 2 | D3: 3 | E3: 4 | F3: 5 | G3: 6
B4: 4 | C4: 7 | D4: 17 | E4: 18 | F4: 38 | G4: 44 | I4: =IF(OR(B4="",ISBLANK(B4),B4=0),0,IF(MOD(B4,2)=1,1,2)) -> 2 | J4: =IF(OR(C4="",ISBLANK(C4),C4=0),0,IF(MOD(C4,2)=1,1,2)) -> 1 | K4: =IF(OR(D4="",ISBLANK(D4),D4=0),0,IF(MOD(D4,2)=1,1,2)) -> 1 | L4: =IF(OR(E4="",ISBLANK(E4),E4=0),0,IF(MOD(E4,2)=1,1,2)) -> 2 | M4: =IF(OR(F4="",ISBLANK(F4),F4=0),0,IF(MOD(F4,2)=1,1,2)) -> 2 | N4: =IF(OR(G4="",ISBLANK(G4),G4=0),0,IF(MOD(G4,2)=1,1,2)) -> 2 | P4: {=SUMPRODUCT(--(MOD(B4:G4,2)=1))} -> 2 | Q4: =6-P4 -> 4 | S4: =COUNTIFS(B4:G4,">=1",B4:G4,"<=23") -> 4 | T4: =6-S4 -> 2 | V4: {=SUMPRODUCT(--(MOD(B4:G4,10)>=1), --(MOD(B4:G4,10)<=5))} -> 2 | W4: =6-V4 -> 4 | Y4: {=IFERROR(COUNT(_xlfn._xlws.FILTER(B4:G4, ISNUMBER(MATCH(B4:G4, {2,3,5,7,11,13,17,19,23,29,31,37,41,43}, 0)))), 0)} -> 2 | Z4: {=IFERROR(COUNT(_xlfn._xlws.FILTER(B4:G4, ISNUMBER(MATCH(B4:G4, {1,4,8,10,14,16,20,22,25,26,28,32,34,35,38,40,44}, 0)))), 0)} -> 3 | AA4: {=IFERROR(COUNT(_xlfn._xlws.FILTER(B4:G4, ISNUMBER(MATCH(B4:G4, {6,9,12,15,18,21,24,27,30,33,36,39,42,45}, 0)))), 0)} -> 1 | AJ4: =COUNTIFS(B4:G4,">=1",B4:G4,"<=14") -> 2 | AK4: =COUNTIFS(B4:G4,">=15",B4:G4,"<=31") -> 2 | AL4: =6-AK4-AJ4 -> 2 | AN4: =COUNTIFS($B4:$G4, ">=1",$B4:$G4, "<=9") -> 2 | AO4: =COUNTIFS($B4:$G4, ">=10",$B4:$G4, "<=18") -> 2 | AP4: =COUNTIFS($B4:$G4, ">=19",$B4:$G4, "<=27") -> 0 | AQ4: =COUNTIFS($B4:$G4, ">=28",$B4:$G4, "<=36") -> 0 | AR4: =COUNTIFS($B4:$G4, ">=37",$B4:$G4, "<=45") -> 2 | AS4: =#REF! -> #REF! | AT4: =#REF!*2 -> #REF! | AU4: =#REF! -> #REF! | AV4: =#REF!*2 -> #REF! | AW4: =#REF! -> #REF! | AX4: =#REF!*2 -> #REF! | AY4: =#REF! -> #REF! | AZ4: =#REF!*2 -> #REF! | BA4: =#REF! -> #REF! | BB4: =#REF!*2 -> #REF! | BC4: =#REF! -> #REF! | BD4: =#REF!*2 -> #REF! | BE4: =#REF!-#REF! -> #REF! | BF4: =#REF!-#REF! -> #REF! | BG4: =#REF!-#REF! -> #REF! | BH4: =#REF!-#REF! -> #REF! | BI4: =#REF!-#REF! -> #REF! | BK4: =COUNTIFS(B4:G4, ">=1", B4:G4, "<=9") -> 2 | BL4: =COUNTIFS(B4:G4, ">=10", B4:G4, "<=19") -> 2 | BM4: =COUNTIFS(B4:G4, ">=20", B4:G4, "<=29") -> 0 | BN4: =COUNTIFS(B4:G4, ">=30", B4:G4, "<=39") -> 1 | BO4: =COUNTIFS(B4:G4, ">=40", B4:G4, "<=45") -> 1 | BP4: =#REF! -> #REF! | BQ4: =#REF!*2 -> #REF! | BR4: =#REF! -> #REF! | BS4: =#REF!*2 -> #REF! | BT4: =#REF! -> #REF! | BU4: =#REF!*2 -> #REF! | BV4: =#REF! -> #REF! | BW4: =#REF!*2 -> #REF! | BX4: =#REF! -> #REF! | BY4: =#REF!*2 -> #REF! | BZ4: =#REF! -> #REF! | CA4: =#REF!*2 -> #REF! | CB4: =C4-B4 -> 3 | CC4: =D4-C4 -> 10 | CD4: =E4-D4 -> 1 | CE4: =F4-E4 -> 20 | CF4: =G4-F4 -> 6 | CH4: =C4-B4 -> 3 | CI4: =D4-C4 -> 10 | CJ4: =E4-D4 -> 1 | CK4: =F4-E4 -> 20 | CL4: =G4-F4 -> 6 | CN4: =IF(OR(CH4="",ISBLANK(CH4),CH4=0),0,IF(MOD(CH4,2)=1,1,2)) -> 1 | CO4: =IF(OR(CI4="",ISBLANK(CI4),CI4=0),0,IF(MOD(CI4,2)=1,1,2)) -> 2 | CP4: =IF(OR(CJ4="",ISBLANK(CJ4),CJ4=0),0,IF(MOD(CJ4,2)=1,1,2)) -> 1 | CQ4: =IF(OR(CK4="",ISBLANK(CK4),CK4=0),0,IF(MOD(CK4,2)=1,1,2)) -> 2 | CR4: =IF(OR(CL4="",ISBLANK(CL4),CL4=0),0,IF(MOD(CL4,2)=1,1,2)) -> 2 | CT4: {=SUMPRODUCT(--(MOD(CH4:CL4,2)=1))} -> 2 | CU4: =5-CT4 -> 3 | CW4: {=SUMPRODUCT(--(MOD(CH4:CL4,10)>=1), --(MOD(CH4:CL4,10)<=5))} -> 2 | CX4: =5-CW4 -> 3 | CZ4: {=IFERROR(COUNT(_xlfn._xlws.FILTER(CH4:CL4, ISNUMBER(MATCH(CH4:CL4, {2,3,5,7,11,13,17,19,23,29,31,37,41,43}, 0)))), 0)} -> 1 | DA4: {=IFERROR(COUNT(_xlfn._xlws.FILTER(CH4:CL4, ISNUMBER(MATCH(CH4:CL4, {1,4,8,10,14,16,20,22,25,26,28,32,34,35,38,40,44}, 0)))), 0)} -> 3 | DB4: {=IFERROR(COUNT(_xlfn._xlws.FILTER(CH4:CL4, ISNUMBER(MATCH(CH4:CL4, {6,9,12,15,18,21,24,27,30,33,36,39,42,45}, 0)))), 0)} -> 1 | DD4: =#REF! -> #REF! | DE4: =#REF!*2 -> #REF! | DF4: =#REF! -> #REF! | DG4: =#REF!*2 -> #REF! | DH4: =#REF! -> #REF! | DI4: =#REF!*2 -> #REF! | DJ4: =#REF! -> #REF! | DK4: =#REF!*2 -> #REF! | DL4: =#REF! -> #REF! | DM4: =#REF!*2 -> #REF!
B5: 11 | C5: 16 | D5: 25 | E5: 27 | F5: 35 | G5: 36 | I5: =IF(OR(B5="",ISBLANK(B5),B5=0),0,IF(MOD(B5,2)=1,1,2)) -> 1 | J5: =IF(OR(C5="",ISBLANK(C5),C5=0),0,IF(MOD(C5,2)=1,1,2)) -> 2 | K5: =IF(OR(D5="",ISBLANK(D5),D5=0),0,IF(MOD(D5,2)=1,1,2)) -> 1 | L5: =IF(OR(E5="",ISBLANK(E5),E5=0),0,IF(MOD(E5,2)=1,1,2)) -> 1 | M5: =IF(OR(F5="",ISBLANK(F5),F5=0),0,IF(MOD(F5,2)=1,1,2)) -> 1 | N5: =IF(OR(G5="",ISBLANK(G5),G5=0),0,IF(MOD(G5,2)=1,1,2)) -> 2 | P5: {=SUMPRODUCT(--(MOD(B5:G5,2)=1))} -> 4 | Q5: =6-P5 -> 2 | S5: =COUNTIFS(B5:G5,">=1",B5:G5,"<=23") -> 2 | T5: =6-S5 -> 4 | V5: {=SUMPRODUCT(--(MOD(B5:G5,10)>=1), --(MOD(B5:G5,10)<=5))} -> 3 | W5: =6-V5 -> 3 | Y5: {=IFERROR(COUNT(_xlfn._xlws.FILTER(B5:G5, ISNUMBER(MATCH(B5:G5, {2,3,5,7,11,13,17,19,23,29,31,37,41,43}, 0)))), 0)} -> 1 | Z5: {=IFERROR(COUNT(_xlfn._xlws.FILTER(B5:G5, ISNUMBER(MATCH(B5:G5, {1,4,8,10,14,16,20,22,25,26,28,32,34,35,38,40,44}, 0)))), 0)} -> 3 | AA5: {=IFERROR(COUNT(_xlfn._xlws.FILTER(B5:G5, ISNUMBER(MATCH(B5:G5, {6,9,12,15,18,21,24,27,30,33,36,39,42,45}, 0)))), 0)} -> 2 | AJ5: =COUNTIFS(B5:G5,">=1",B5:G5,"<=14") -> 1 | AK5: =COUNTIFS(B5:G5,">=15",B5:G5,"<=31") -> 3 | AL5: =6-AK5-AJ5 -> 2 | AN5: =COUNTIFS($B5:$G5, ">=1",$B5:$G5, "<=9") -> 0 | AO5: =COUNTIFS($B5:$G5, ">=10",$B5:$G5, "<=18") -> 2 | AP5: =COUNTIFS($B5:$G5, ">=19",$B5:$G5, "<=27") -> 2 | AQ5: =COUNTIFS($B5:$G5, ">=28",$B5:$G5, "<=36") -> 2 | AR5: =COUNTIFS($B5:$G5, ">=37",$B5:$G5, "<=45") -> 0 | AS5: =#REF! -> #REF! | AT5: =#REF!*2 -> #REF! | AU5: =#REF! -> #REF! | AV5: =#REF!*2 -> #REF! | AW5: =#REF! -> #REF! | AX5: =#REF!*2 -> #REF! | AY5: =#REF! -> #REF! | AZ5: =#REF!*2 -> #REF! | BA5: =#REF! -> #REF! | BB5: =#REF!*2 -> #REF! | BC5: =#REF! -> #REF! | BD5: =#REF!*2 -> #REF! | BE5: =#REF!-#REF! -> #REF! | BF5: =#REF!-#REF! -> #REF! | BG5: =#REF!-#REF! -> #REF! | BH5: =#REF!-#REF! -> #REF! | BI5: =#REF!-#REF! -> #REF! | BK5: =COUNTIFS(B5:G5, ">=1", B5:G5, "<=9") -> 0 | BL5: =COUNTIFS(B5:G5, ">=10", B5:G5, "<=19") -> 2 | BM5: =COUNTIFS(B5:G5, ">=20", B5:G5, "<=29") -> 2 | BN5: =COUNTIFS(B5:G5, ">=30", B5:G5, "<=39") -> 2 | BO5: =COUNTIFS(B5:G5, ">=40", B5:G5, "<=45") -> 0 | BP5: =#REF! -> #REF! | BQ5: =#REF!*2 -> #REF! | BR5: =#REF! -> #REF! | BS5: =#REF!*2 -> #REF! | BT5: =#REF! -> #REF! | BU5: =#REF!*2 -> #REF! | BV5: =#REF! -> #REF! | BW5: =#REF!*2 -> #REF! | BX5: =#REF! -> #REF! | BY5: =#REF!*2 -> #REF! | BZ5: =#REF! -> #REF! | CA5: =#REF!*2 -> #REF! | CB5: =C5-B5 -> 5 | CC5: =D5-C5 -> 9 | CD5: =E5-D5 -> 2 | CE5: =F5-E5 -> 8 | CF5: =G5-F5 -> 1 | CH5: =C5-B5 -> 5 | CI5: =D5-C5 -> 9 | CJ5: =E5-D5 -> 2 | CK5: =F5-E5 -> 8 | CL5: =G5-F5 -> 1 | CN5: =IF(OR(CH5="",ISBLANK(CH5),CH5=0),0,IF(MOD(CH5,2)=1,1,2)) -> 1 | CO5: =IF(OR(CI5="",ISBLANK(CI5),CI5=0),0,IF(MOD(CI5,2)=1,1,2)) -> 1 | CP5: =IF(OR(CJ5="",ISBLANK(CJ5),CJ5=0),0,IF(MOD(CJ5,2)=1,1,2)) -> 2 | CQ5: =IF(OR(CK5="",ISBLANK(CK5),CK5=0),0,IF(MOD(CK5,2)=1,1,2)) -> 2 | CR5: =IF(OR(CL5="",ISBLANK(CL5),CL5=0),0,IF(MOD(CL5,2)=1,1,2)) -> 1 | CT5: {=SUMPRODUCT(--(MOD(CH5:CL5,2)=1))} -> 3 | CU5: =5-CT5 -> 2 | CW5: {=SUMPRODUCT(--(MOD(CH5:CL5,10)>=1), --(MOD(CH5:CL5,10)<=5))} -> 3 | CX5: =5-CW5 -> 2 | CZ5: {=IFERROR(COUNT(_xlfn._xlws.FILTER(CH5:CL5, ISNUMBER(MATCH(CH5:CL5, {2,3,5,7,11,13,17,19,23,29,31,37,41,43}, 0)))), 0)} -> 2 | DA5: {=IFERROR(COUNT(_xlfn._xlws.FILTER(CH5:CL5, ISNUMBER(MATCH(CH5:CL5, {1,4,8,10,14,16,20,22,25,26,28,32,34,35,38,40,44}, 0)))), 0)} -> 2 | DB5: {=IFERROR(COUNT(_xlfn._xlws.FILTER(CH5:CL5, ISNUMBER(MATCH(CH5:CL5, {6,9,12,15,18,21,24,27,30,33,36,39,42,45}, 0)))), 0)} -> 1 | DD5: =#REF! -> #REF! | DE5: =#REF!*2 -> #REF! | DF5: =#REF! -> #REF! | DG5: =#REF!*2 -> #REF! | DH5: =#REF! -> #REF! | DI5: =#REF!*2 -> #REF! | DJ5: =#REF! -> #REF! | DK5: =#REF!*2 -> #REF! | DL5: =#REF! -> #REF! | DM5: =#REF!*2 -> #REF!
B6: 13 | C6: 14 | D6: 18 | E6: 21 | F6: 34 | G6: 44 | I6: =IF(OR(B6="",ISBLANK(B6),B6=0),0,IF(MOD(B6,2)=1,1,2)) -> 1 | J6: =IF(OR(C6="",ISBLANK(C6),C6=0),0,IF(MOD(C6,2)=1,1,2)) -> 2 | K6: =IF(OR(D6="",ISBLANK(D6),D6=0),0,IF(MOD(D6,2)=1,1,2)) -> 2 | L6: =IF(OR(E6="",ISBLANK(E6),E6=0),0,IF(MOD(E6,2)=1,1,2)) -> 1 | M6: =IF(OR(F6="",ISBLANK(F6),F6=0),0,IF(MOD(F6,2)=1,1,2)) -> 2 | N6: =IF(OR(G6="",ISBLANK(G6),G6=0),0,IF(MOD(G6,2)=1,1,2)) -> 2 | P6: {=SUMPRODUCT(--(MOD(B6:G6,2)=1))} -> 2 | Q6: =6-P6 -> 4 | S6: =COUNTIFS(B6:G6,">=1",B6:G6,"<=23") -> 4 | T6: =6-S6 -> 2 | V6: {=SUMPRODUCT(--(MOD(B6:G6,10)>=1), --(MOD(B6:G6,10)<=5))} -> 5 | W6: =6-V6 -> 1 | Y6: {=IFERROR(COUNT(_xlfn._xlws.FILTER(B6:G6, ISNUMBER(MATCH(B6:G6, {2,3,5,7,11,13,17,19,23,29,31,37,41,43}, 0)))), 0)} -> 1 | Z6: {=IFERROR(COUNT(_xlfn._xlws.FILTER(B6:G6, ISNUMBER(MATCH(B6:G6, {1,4,8,10,14,16,20,22,25,26,28,32,34,35,38,40,44}, 0)))), 0)} -> 3 | AA6: {=IFERROR(COUNT(_xlfn._xlws.FILTER(B6:G6, ISNUMBER(MATCH(B6:G6, {6,9,12,15,18,21,24,27,30,33,36,39,42,45}, 0)))), 0)} -> 2 | AJ6: =COUNTIFS(B6:G6,">=1",B6:G6,"<=14") -> 2 | AK6: =COUNTIFS(B6:G6,">=15",B6:G6,"<=31") -> 2 | AL6: =6-AK6-AJ6 -> 2 | AN6: =COUNTIFS($B6:$G6, ">=1",$B6:$G6, "<=9") -> 0 | AO6: =COUNTIFS($B6:$G6, ">=10",$B6:$G6, "<=18") -> 3 | AP6: =COUNTIFS($B6:$G6, ">=19",$B6:$G6, "<=27") -> 1 | AQ6: =COUNTIFS($B6:$G6, ">=28",$B6:$G6, "<=36") -> 1 | AR6: =COUNTIFS($B6:$G6, ">=37",$B6:$G6, "<=45") -> 1 | AS6: =#REF! -> #REF! | AT6: =#REF!*2 -> #REF! | AU6: =#REF! -> #REF! | AV6: =#REF!*2 -> #REF! | AW6: =#REF! -> #REF! | AX6: =#REF!*2 -> #REF! | AY6: =#REF! -> #REF! | AZ6: =#REF!*2 -> #REF! | BA6: =#REF! -> #REF! | BB6: =#REF!*2 -> #REF! | BC6: =#REF! -> #REF! | BD6: =#REF!*2 -> #REF! | BE6: =#REF!-#REF! -> #REF! | BF6: =#REF!-#REF! -> #REF! | BG6: =#REF!-#REF! -> #REF! | BH6: =#REF!-#REF! -> #REF! | BI6: =#REF!-#REF! -> #REF! | BK6: =COUNTIFS(B6:G6, ">=1", B6:G6, "<=9") -> 0 | BL6: =COUNTIFS(B6:G6, ">=10", B6:G6, "<=19") -> 3 | BM6: =COUNTIFS(B6:G6, ">=20", B6:G6, "<=29") -> 1 | BN6: =COUNTIFS(B6:G6, ">=30", B6:G6, "<=39") -> 1 | BO6: =COUNTIFS(B6:G6, ">=40", B6:G6, "<=45") -> 1 | BP6: =#REF! -> #REF! | BQ6: =#REF!*2 -> #REF! | BR6: =#REF! -> #REF! | BS6: =#REF!*2 -> #REF! | BT6: =#REF! -> #REF! | BU6: =#REF!*2 -> #REF! | BV6: =#REF! -> #REF! | BW6: =#REF!*2 -> #REF! | BX6: =#REF! -> #REF! | BY6: =#REF!*2 -> #REF! | BZ6: =#REF! -> #REF! | CA6: =#REF!*2 -> #REF! | CB6: =C6-B6 -> 1 | CC6: =D6-C6 -> 4 | CD6: =E6-D6 -> 3 | CE6: =F6-E6 -> 13 | CF6: =G6-F6 -> 10 | CH6: =C6-B6 -> 1 | CI6: =D6-C6 -> 4 | CJ6: =E6-D6 -> 3 | CK6: =F6-E6 -> 13 | CL6: =G6-F6 -> 10 | CN6: =IF(OR(CH6="",ISBLANK(CH6),CH6=0),0,IF(MOD(CH6,2)=1,1,2)) -> 1 | CO6: =IF(OR(CI6="",ISBLANK(CI6),CI6=0),0,IF(MOD(CI6,2)=1,1,2)) -> 2 | CP6: =IF(OR(CJ6="",ISBLANK(CJ6),CJ6=0),0,IF(MOD(CJ6,2)=1,1,2)) -> 1 | CQ6: =IF(OR(CK6="",ISBLANK(CK6),CK6=0),0,IF(MOD(CK6,2)=1,1,2)) -> 1 | CR6: =IF(OR(CL6="",ISBLANK(CL6),CL6=0),0,IF(MOD(CL6,2)=1,1,2)) -> 2 | CT6: {=SUMPRODUCT(--(MOD(CH6:CL6,2)=1))} -> 3 | CU6: =5-CT6 -> 2 | CW6: {=SUMPRODUCT(--(MOD(CH6:CL6,10)>=1), --(MOD(CH6:CL6,10)<=5))} -> 4 | CX6: =5-CW6 -> 1 | CZ6: {=IFERROR(COUNT(_xlfn._xlws.FILTER(CH6:CL6, ISNUMBER(MATCH(CH6:CL6, {2,3,5,7,11,13,17,19,23,29,31,37,41,43}, 0)))), 0)} -> 2 | DA6: {=IFERROR(COUNT(_xlfn._xlws.FILTER(CH6:CL6, ISNUMBER(MATCH(CH6:CL6, {1,4,8,10,14,16,20,22,25,26,28,32,34,35,38,40,44}, 0)))), 0)} -> 3 | DB6: {=IFERROR(COUNT(_xlfn._xlws.FILTER(CH6:CL6, ISNUMBER(MATCH(CH6:CL6, {6,9,12,15,18,21,24,27,30,33,36,39,42,45}, 0)))), 0)} -> 0 | DD6: =#REF! -> #REF! | DE6: =#REF!*2 -> #REF! | DF6: =#REF! -> #REF! | DG6: =#REF!*2 -> #REF! | DH6: =#REF! -> #REF! | DI6: =#REF!*2 -> #REF! | DJ6: =#REF! -> #REF! | DK6: =#REF!*2 -> #REF! | DL6: =#REF! -> #REF! | DM6: =#REF!*2 -> #REF!
B7: 11 | C7: 21 | D7: 22 | E7: 30 | F7: 39 | G7: 44 | I7: =IF(OR(B7="",ISBLANK(B7),B7=0),0,IF(MOD(B7,2)=1,1,2)) -> 1 | J7: =IF(OR(C7="",ISBLANK(C7),C7=0),0,IF(MOD(C7,2)=1,1,2)) -> 1 | K7: =IF(OR(D7="",ISBLANK(D7),D7=0),0,IF(MOD(D7,2)=1,1,2)) -> 2 | L7: =IF(OR(E7="",ISBLANK(E7),E7=0),0,IF(MOD(E7,2)=1,1,2)) -> 2 | M7: =IF(OR(F7="",ISBLANK(F7),F7=0),0,IF(MOD(F7,2)=1,1,2)) -> 1 | N7: =IF(OR(G7="",ISBLANK(G7),G7=0),0,IF(MOD(G7,2)=1,1,2)) -> 2 | P7: {=SUMPRODUCT(--(MOD(B7:G7,2)=1))} -> 3 | Q7: =6-P7 -> 3 | S7: =COUNTIFS(B7:G7,">=1",B7:G7,"<=23") -> 3 | T7: =6-S7 -> 3 | V7: {=SUMPRODUCT(--(MOD(B7:G7,10)>=1), --(MOD(B7:G7,10)<=5))} -> 4 | W7: =6-V7 -> 2 | Y7: {=IFERROR(COUNT(_xlfn._xlws.FILTER(B7:G7, ISNUMBER(MATCH(B7:G7, {2,3,5,7,11,13,17,19,23,29,31,37,41,43}, 0)))), 0)} -> 1 | Z7: {=IFERROR(COUNT(_xlfn._xlws.FILTER(B7:G7, ISNUMBER(MATCH(B7:G7, {1,4,8,10,14,16,20,22,25,26,28,32,34,35,38,40,44}, 0)))), 0)} -> 2 | AA7: {=IFERROR(COUNT(_xlfn._xlws.FILTER(B7:G7, ISNUMBER(MATCH(B7:G7, {6,9,12,15,18,21,24,27,30,33,36,39,42,45}, 0)))), 0)} -> 3 | AJ7: =COUNTIFS(B7:G7,">=1",B7:G7,"<=14") -> 1 | AK7: =COUNTIFS(B7:G7,">=15",B7:G7,"<=31") -> 3 | AL7: =6-AK7-AJ7 -> 2 | AN7: =COUNTIFS($B7:$G7, ">=1",$B7:$G7, "<=9") -> 0 | AO7: =COUNTIFS($B7:$G7, ">=10",$B7:$G7, "<=18") -> 1 | AP7: =COUNTIFS($B7:$G7, ">=19",$B7:$G7, "<=27") -> 2 | AQ7: =COUNTIFS($B7:$G7, ">=28",$B7:$G7, "<=36") -> 1 | AR7: =COUNTIFS($B7:$G7, ">=37",$B7:$G7, "<=45") -> 2 | AS7: =#REF! -> #REF! | AT7: =#REF!*2 -> #REF! | AU7: =#REF! -> #REF! | AV7: =#REF!*2 -> #REF! | AW7: =#REF! -> #REF! | AX7: =#REF!*2 -> #REF! | AY7: =#REF! -> #REF! | AZ7: =#REF!*2 -> #REF! | BA7: =#REF! -> #REF! | BB7: =#REF!*2 -> #REF! | BC7: =#REF! -> #REF! | BD7: =#REF!*2 -> #REF! | BE7: =#REF!-#REF! -> #REF! | BF7: =#REF!-#REF! -> #REF! | BG7: =#REF!-#REF! -> #REF! | BH7: =#REF!-#REF! -> #REF! | BI7: =#REF!-#REF! -> #REF! | BK7: =COUNTIFS(B7:G7, ">=1", B7:G7, "<=9") -> 0 | BL7: =COUNTIFS(B7:G7, ">=10", B7:G7, "<=19") -> 1 | BM7: =COUNTIFS(B7:G7, ">=20", B7:G7, "<=29") -> 2 | BN7: =COUNTIFS(B7:G7, ">=30", B7:G7, "<=39") -> 2 | BO7: =COUNTIFS(B7:G7, ">=40", B7:G7, "<=45") -> 1 | BP7: =#REF! -> #REF! | BQ7: =#REF!*2 -> #REF! | BR7: =#REF! -> #REF! | BS7: =#REF!*2 -> #REF! | BT7: =#REF! -> #REF! | BU7: =#REF!*2 -> #REF! | BV7: =#REF! -> #REF! | BW7: =#REF!*2 -> #REF! | BX7: =#REF! -> #REF! | BY7: =#REF!*2 -> #REF! | BZ7: =#REF! -> #REF! | CA7: =#REF!*2 -> #REF! | CB7: =C7-B7 -> 10 | CC7: =D7-C7 -> 1 | CD7: =E7-D7 -> 8 | CE7: =F7-E7 -> 9 | CF7: =G7-F7 -> 5 | CH7: =C7-B7 -> 10 | CI7: =D7-C7 -> 1 | CJ7: =E7-D7 -> 8 | CK7: =F7-E7 -> 9 | CL7: =G7-F7 -> 5 | CN7: =IF(OR(CH7="",ISBLANK(CH7),CH7=0),0,IF(MOD(CH7,2)=1,1,2)) -> 2 | CO7: =IF(OR(CI7="",ISBLANK(CI7),CI7=0),0,IF(MOD(CI7,2)=1,1,2)) -> 1 | CP7: =IF(OR(CJ7="",ISBLANK(CJ7),CJ7=0),0,IF(MOD(CJ7,2)=1,1,2)) -> 2 | CQ7: =IF(OR(CK7="",ISBLANK(CK7),CK7=0),0,IF(MOD(CK7,2)=1,1,2)) -> 1 | CR7: =IF(OR(CL7="",ISBLANK(CL7),CL7=0),0,IF(MOD(CL7,2)=1,1,2)) -> 1 | CT7: {=SUMPRODUCT(--(MOD(CH7:CL7,2)=1))} -> 3 | CU7: =5-CT7 -> 2 | CW7: {=SUMPRODUCT(--(MOD(CH7:CL7,10)>=1), --(MOD(CH7:CL7,10)<=5))} -> 2 | CX7: =5-CW7 -> 3 | CZ7: {=IFERROR(COUNT(_xlfn._xlws.FILTER(CH7:CL7, ISNUMBER(MATCH(CH7:CL7, {2,3,5,7,11,13,17,19,23,29,31,37,41,43}, 0)))), 0)} -> 1 | DA7: {=IFERROR(COUNT(_xlfn._xlws.FILTER(CH7:CL7, ISNUMBER(MATCH(CH7:CL7, {1,4,8,10,14,16,20,22,25,26,28,32,34,35,38,40,44}, 0)))), 0)} -> 3 | DB7: {=IFERROR(COUNT(_xlfn._xlws.FILTER(CH7:CL7, ISNUMBER(MATCH(CH7:CL7, {6,9,12,15,18,21,24,27,30,33,36,39,42,45}, 0)))), 0)} -> 1 | DD7: =#REF! -> #REF! | DE7: =#REF!*2 -> #REF! | DF7: =#REF! -> #REF! | DG7: =#REF!*2 -> #REF! | DH7: =#REF! -> #REF! | DI7: =#REF!*2 -> #REF! | DJ7: =#REF! -> #REF! | DK7: =#REF!*2 -> #REF! | DL7: =#REF! -> #REF! | DM7: =#REF!*2 -> #REF!
B8: 4 | C8: 18 | D8: 31 | E8: 37 | F8: 42 | G8: 43 | I8: =IF(OR(B8="",ISBLANK(B8),B8=0),0,IF(MOD(B8,2)=1,1,2)) -> 2 | J8: =IF(OR(C8="",ISBLANK(C8),C8=0),0,IF(MOD(C8,2)=1,1,2)) -> 2 | K8: =IF(OR(D8="",ISBLANK(D8),D8=0),0,IF(MOD(D8,2)=1,1,2)) -> 1 | L8: =IF(OR(E8="",ISBLANK(E8),E8=0),0,IF(MOD(E8,2)=1,1,2)) -> 1 | M8: =IF(OR(F8="",ISBLANK(F8),F8=0),0,IF(MOD(F8,2)=1,1,2)) -> 2 | N8: =IF(OR(G8="",ISBLANK(G8),G8=0),0,IF(MOD(G8,2)=1,1,2)) -> 1 | P8: {=SUMPRODUCT(--(MOD(B8:G8,2)=1))} -> 3 | Q8: =6-P8 -> 3 | S8: =COUNTIFS(B8:G8,">=1",B8:G8,"<=23") -> 2 | T8: =6-S8 -> 4 | V8: {=SUMPRODUCT(--(MOD(B8:G8,10)>=1), --(MOD(B8:G8,10)<=5))} -> 4 | W8: =6-V8 -> 2 | Y8: {=IFERROR(COUNT(_xlfn._xlws.FILTER(B8:G8, ISNUMBER(MATCH(B8:G8, {2,3,5,7,11,13,17,19,23,29,31,37,41,43}, 0)))), 0)} -> 3 | Z8: {=IFERROR(COUNT(_xlfn._xlws.FILTER(B8:G8, ISNUMBER(MATCH(B8:G8, {1,4,8,10,14,16,20,22,25,26,28,32,34,35,38,40,44}, 0)))), 0)} -> 1 | AA8: {=IFERROR(COUNT(_xlfn._xlws.FILTER(B8:G8, ISNUMBER(MATCH(B8:G8, {6,9,12,15,18,21,24,27,30,33,36,39,42,45}, 0)))), 0)} -> 2 | AJ8: =COUNTIFS(B8:G8,">=1",B8:G8,"<=14") -> 1 | AK8: =COUNTIFS(B8:G8,">=15",B8:G8,"<=31") -> 2 | AL8: =6-AK8-AJ8 -> 3 | AN8: =COUNTIFS($B8:$G8, ">=1",$B8:$G8, "<=9") -> 1 | AO8: =COUNTIFS($B8:$G8, ">=10",$B8:$G8, "<=18") -> 1 | AP8: =COUNTIFS($B8:$G8, ">=19",$B8:$G8, "<=27") -> 0 | AQ8: =COUNTIFS($B8:$G8, ">=28",$B8:$G8, "<=36") -> 1 | AR8: =COUNTIFS($B8:$G8, ">=37",$B8:$G8, "<=45") -> 3 | AS8: =#REF! -> #REF! | AT8: =#REF!*2 -> #REF! | AU8: =#REF! -> #REF! | AV8: =#REF!*2 -> #REF! | AW8: =#REF! -> #REF! | AX8: =#REF!*2 -> #REF! | AY8: =#REF! -> #REF! | AZ8: =#REF!*2 -> #REF! | BA8: =#REF! -> #REF! | BB8: =#REF!*2 -> #REF! | BC8: =#REF! -> #REF! | BD8: =#REF!*2 -> #REF! | BE8: =#REF!-#REF! -> #REF! | BF8: =#REF!-#REF! -> #REF! | BG8: =#REF!-#REF! -> #REF! | BH8: =#REF!-#REF! -> #REF! | BI8: =#REF!-#REF! -> #REF! | BK8: =COUNTIFS(B8:G8, ">=1", B8:G8, "<=9") -> 1 | BL8: =COUNTIFS(B8:G8, ">=10", B8:G8, "<=19") -> 1 | BM8: =COUNTIFS(B8:G8, ">=20", B8:G8, "<=29") -> 0 | BN8: =COUNTIFS(B8:G8, ">=30", B8:G8, "<=39") -> 2 | BO8: =COUNTIFS(B8:G8, ">=40", B8:G8, "<=45") -> 2 | BP8: =#REF! -> #REF! | BQ8: =#REF!*2 -> #REF! | BR8: =#REF! -> #REF! | BS8: =#REF!*2 -> #REF! | BT8: =#REF! -> #REF! | BU8: =#REF!*2 -> #REF! | BV8: =#REF! -> #REF! | BW8: =#REF!*2 -> #REF! | BX8: =#REF! -> #REF! | BY8: =#REF!*2 -> #REF! | BZ8: =#REF! -> #REF! | CA8: =#REF!*2 -> #REF! | CB8: =C8-B8 -> 14 | CC8: =D8-C8 -> 13 | CD8: =E8-D8 -> 6 | CE8: =F8-E8 -> 5 | CF8: =G8-F8 -> 1 | CH8: =C8-B8 -> 14 | CI8: =D8-C8 -> 13 | CJ8: =E8-D8 -> 6 | CK8: =F8-E8 -> 5 | CL8: =G8-F8 -> 1 | CN8: =IF(OR(CH8="",ISBLANK(CH8),CH8=0),0,IF(MOD(CH8,2)=1,1,2)) -> 2 | CO8: =IF(OR(CI8="",ISBLANK(CI8),CI8=0),0,IF(MOD(CI8,2)=1,1,2)) -> 1 | CP8: =IF(OR(CJ8="",ISBLANK(CJ8),CJ8=0),0,IF(MOD(CJ8,2)=1,1,2)) -> 2 | CQ8: =IF(OR(CK8="",ISBLANK(CK8),CK8=0),0,IF(MOD(CK8,2)=1,1,2)) -> 1 | CR8: =IF(OR(CL8="",ISBLANK(CL8),CL8=0),0,IF(MOD(CL8,2)=1,1,2)) -> 1 | CT8: {=SUMPRODUCT(--(MOD(CH8:CL8,2)=1))} -> 3 | CU8: =5-CT8 -> 2 | CW8: {=SUMPRODUCT(--(MOD(CH8:CL8,10)>=1), --(MOD(CH8:CL8,10)<=5))} -> 4 | CX8: =5-CW8 -> 1 | CZ8: {=IFERROR(COUNT(_xlfn._xlws.FILTER(CH8:CL8, ISNUMBER(MATCH(CH8:CL8, {2,3,5,7,11,13,17,19,23,29,31,37,41,43}, 0)))), 0)} -> 2 | DA8: {=IFERROR(COUNT(_xlfn._xlws.FILTER(CH8:CL8, ISNUMBER(MATCH(CH8:CL8, {1,4,8,10,14,16,20,22,25,26,28,32,34,35,38,40,44}, 0)))), 0)} -> 2 | DB8: {=IFERROR(COUNT(_xlfn._xlws.FILTER(CH8:CL8, ISNUMBER(MATCH(CH8:CL8, {6,9,12,15,18,21,24,27,30,33,36,39,42,45}, 0)))), 0)} -> 1 | DD8: =#REF! -> #REF! | DE8: =#REF!*2 -> #REF! | DF8: =#REF! -> #REF! | DG8: =#REF!*2 -> #REF! | DH8: =#REF! -> #REF! | DI8: =#REF!*2 -> #REF! | DJ8: =#REF! -> #REF! | DK8: =#REF!*2 -> #REF! | DL8: =#REF! -> #REF! | DM8: =#REF!*2 -> #REF!
B9: 12 | C9: 19 | D9: 21 | E9: 29 | F9: 40 | G9: 45 | I9: =IF(OR(B9="",ISBLANK(B9),B9=0),0,IF(MOD(B9,2)=1,1,2)) -> 2 | J9: =IF(OR(C9="",ISBLANK(C9),C9=0),0,IF(MOD(C9,2)=1,1,2)) -> 1 | K9: =IF(OR(D9="",ISBLANK(D9),D9=0),0,IF(MOD(D9,2)=1,1,2)) -> 1 | L9: =IF(OR(E9="",ISBLANK(E9),E9=0),0,IF(MOD(E9,2)=1,1,2)) -> 1 | M9: =IF(OR(F9="",ISBLANK(F9),F9=0),0,IF(MOD(F9,2)=1,1,2)) -> 2 | N9: =IF(OR(G9="",ISBLANK(G9),G9=0),0,IF(MOD(G9,2)=1,1,2)) -> 1 | P9: {=SUMPRODUCT(--(MOD(B9:G9,2)=1))} -> 4 | Q9: =6-P9 -> 2 | S9: =COUNTIFS(B9:G9,">=1",B9:G9,"<=23") -> 3 | T9: =6-S9 -> 3 | V9: {=SUMPRODUCT(--(MOD(B9:G9,10)>=1), --(MOD(B9:G9,10)<=5))} -> 3 | W9: =6-V9 -> 3 | Y9: {=IFERROR(COUNT(_xlfn._xlws.FILTER(B9:G9, ISNUMBER(MATCH(B9:G9, {2,3,5,7,11,13,17,19,23,29,31,37,41,43}, 0)))), 0)} -> 2 | Z9: {=IFERROR(COUNT(_xlfn._xlws.FILTER(B9:G9, ISNUMBER(MATCH(B9:G9, {1,4,8,10,14,16,20,22,25,26,28,32,34,35,38,40,44}, 0)))), 0)} -> 1 | AA9: {=IFERROR(COUNT(_xlfn._xlws.FILTER(B9:G9, ISNUMBER(MATCH(B9:G9, {6,9,12,15,18,21,24,27,30,33,36,39,42,45}, 0)))), 0)} -> 3 | AJ9: =COUNTIFS(B9:G9,">=1",B9:G9,"<=14") -> 1 | AK9: =COUNTIFS(B9:G9,">=15",B9:G9,"<=31") -> 3 | AL9: =6-AK9-AJ9 -> 2 | AN9: =COUNTIFS($B9:$G9, ">=1",$B9:$G9, "<=9") -> 0 | AO9: =COUNTIFS($B9:$G9, ">=10",$B9:$G9, "<=18") -> 1 | AP9: =COUNTIFS($B9:$G9, ">=19",$B9:$G9, "<=27") -> 2 | AQ9: =COUNTIFS($B9:$G9, ">=28",$B9:$G9, "<=36") -> 1 | AR9: =COUNTIFS($B9:$G9, ">=37",$B9:$G9, "<=45") -> 2 | AS9: =#REF! -> #REF! | AT9: =#REF!*2 -> #REF! | AU9: =#REF! -> #REF! | AV9: =#REF!*2 -> #REF! | AW9: =#REF! -> #REF! | AX9: =#REF!*2 -> #REF! | AY9: =#REF! -> #REF! | AZ9: =#REF!*2 -> #REF! | BA9: =#REF! -> #REF! | BB9: =#REF!*2 -> #REF! | BC9: =#REF! -> #REF! | BD9: =#REF!*2 -> #REF! | BE9: =#REF!-#REF! -> #REF! | BF9: =#REF!-#REF! -> #REF! | BG9: =#REF!-#REF! -> #REF! | BH9: =#REF!-#REF! -> #REF! | BI9: =#REF!-#REF! -> #REF! | BK9: =COUNTIFS(B9:G9, ">=1", B9:G9, "<=9") -> 0 | BL9: =COUNTIFS(B9:G9, ">=10", B9:G9, "<=19") -> 2 | BM9: =COUNTIFS(B9:G9, ">=20", B9:G9, "<=29") -> 2 | BN9: =COUNTIFS(B9:G9, ">=30", B9:G9, "<=39") -> 0 | BO9: =COUNTIFS(B9:G9, ">=40", B9:G9, "<=45") -> 2 | BP9: =#REF! -> #REF! | BQ9: =#REF!*2 -> #REF! | BR9: =#REF! -> #REF! | BS9: =#REF!*2 -> #REF! | BT9: =#REF! -> #REF! | BU9: =#REF!*2 -> #REF! | BV9: =#REF! -> #REF! | BW9: =#REF!*2 -> #REF! | BX9: =#REF! -> #REF! | BY9: =#REF!*2 -> #REF! | BZ9: =#REF! -> #REF! | CA9: =#REF!*2 -> #REF! | CB9: =C9-B9 -> 7 | CC9: =D9-C9 -> 2 | CD9: =E9-D9 -> 8 | CE9: =F9-E9 -> 11 | CF9: =G9-F9 -> 5 | CH9: =C9-B9 -> 7 | CI9: =D9-C9 -> 2 | CJ9: =E9-D9 -> 8 | CK9: =F9-E9 -> 11 | CL9: =G9-F9 -> 5 | CN9: =IF(OR(CH9="",ISBLANK(CH9),CH9=0),0,IF(MOD(CH9,2)=1,1,2)) -> 1 | CO9: =IF(OR(CI9="",ISBLANK(CI9),CI9=0),0,IF(MOD(CI9,2)=1,1,2)) -> 2 | CP9: =IF(OR(CJ9="",ISBLANK(CJ9),CJ9=0),0,IF(MOD(CJ9,2)=1,1,2)) -> 2 | CQ9: =IF(OR(CK9="",ISBLANK(CK9),CK9=0),0,IF(MOD(CK9,2)=1,1,2)) -> 1 | CR9: =IF(OR(CL9="",ISBLANK(CL9),CL9=0),0,IF(MOD(CL9,2)=1,1,2)) -> 1 | CT9: {=SUMPRODUCT(--(MOD(CH9:CL9,2)=1))} -> 3 | CU9: =5-CT9 -> 2 | CW9: {=SUMPRODUCT(--(MOD(CH9:CL9,10)>=1), --(MOD(CH9:CL9,10)<=5))} -> 3 | CX9: =5-CW9 -> 2 | CZ9: {=IFERROR(COUNT(_xlfn._xlws.FILTER(CH9:CL9, ISNUMBER(MATCH(CH9:CL9, {2,3,5,7,11,13,17,19,23,29,31,37,41,43}, 0)))), 0)} -> 4 | DA9: {=IFERROR(COUNT(_xlfn._xlws.FILTER(CH9:CL9, ISNUMBER(MATCH(CH9:CL9, {1,4,8,10,14,16,20,22,25,26,28,32,34,35,38,40,44}, 0)))), 0)} -> 1 | DB9: {=IFERROR(COUNT(_xlfn._xlws.FILTER(CH9:CL9, ISNUMBER(MATCH(CH9:CL9, {6,9,12,15,18,21,24,27,30,33,36,39,42,45}, 0)))), 0)} -> 0 | DD9: =#REF! -> #REF! | DE9: =#REF!*2 -> #REF! | DF9: =#REF! -> #REF! | DG9: =#REF!*2 -> #REF! | DH9: =#REF! -> #REF! | DI9: =#REF!*2 -> #REF! | DJ9: =#REF! -> #REF! | DK9: =#REF!*2 -> #REF! | DL9: =#REF! -> #REF! | DM9: =#REF!*2 -> #REF!
B10: 6 | C10: 20 | D10: 23 | E10: 24 | F10: 28 | G10: 30 | I10: =IF(OR(B10="",ISBLANK(B10),B10=0),0,IF(MOD(B10,2)=1,1,2)) -> 2 | J10: =IF(OR(C10="",ISBLANK(C10),C10=0),0,IF(MOD(C10,2)=1,1,2)) -> 2 | K10: =IF(OR(D10="",ISBLANK(D10),D10=0),0,IF(MOD(D10,2)=1,1,2)) -> 1 | L10: =IF(OR(E10="",ISBLANK(E10),E10=0),0,IF(MOD(E10,2)=1,1,2)) -> 2 | M10: =IF(OR(F10="",ISBLANK(F10),F10=0),0,IF(MOD(F10,2)=1,1,2)) -> 2 | N10: =IF(OR(G10="",ISBLANK(G10),G10=0),0,IF(MOD(G10,2)=1,1,2)) -> 2 | P10: {=SUMPRODUCT(--(MOD(B10:G10,2)=1))} -> 1 | Q10: =6-P10 -> 5 | S10: =COUNTIFS(B10:G10,">=1",B10:G10,"<=23") -> 3 | T10: =6-S10 -> 3 | V10: {=SUMPRODUCT(--(MOD(B10:G10,10)>=1), --(MOD(B10:G10,10)<=5))} -> 2 | W10: =6-V10 -> 4 | Y10: {=IFERROR(COUNT(_xlfn._xlws.FILTER(B10:G10, ISNUMBER(MATCH(B10:G10, {2,3,5,7,11,13,17,19,23,29,31,37,41,43}, 0)))), 0)} -> 1 | Z10: {=IFERROR(COUNT(_xlfn._xlws.FILTER(B10:G10, ISNUMBER(MATCH(B10:G10, {1,4,8,10,14,16,20,22,25,26,28,32,34,35,38,40,44}, 0)))), 0)} -> 2 | AA10: {=IFERROR(COUNT(_xlfn._xlws.FILTER(B10:G10, ISNUMBER(MATCH(B10:G10, {6,9,12,15,18,21,24,27,30,33,36,39,42,45}, 0)))), 0)} -> 3 | AJ10: =COUNTIFS(B10:G10,">=1",B10:G10,"<=14") -> 1 | AK10: =COUNTIFS(B10:G10,">=15",B10:G10,"<=31") -> 5 | AL10: =6-AK10-AJ10 -> 0 | AN10: =COUNTIFS($B10:$G10, ">=1",$B10:$G10, "<=9") -> 1 | AO10: =COUNTIFS($B10:$G10, ">=10",$B10:$G10, "<=18") -> 0 | AP10: =COUNTIFS($B10:$G10, ">=19",$B10:$G10, "<=27") -> 3 | AQ10: =COUNTIFS($B10:$G10, ">=28",$B10:$G10, "<=36") -> 2 | AR10: =COUNTIFS($B10:$G10, ">=37",$B10:$G10, "<=45") -> 0 | AS10: =#REF! -> #REF! | AT10: =#REF!*2 -> #REF! | AU10: =#REF! -> #REF! | AV10: =#REF!*2 -> #REF! | AW10: =#REF! -> #REF! | AX10: =#REF!*2 -> #REF! | AY10: =#REF! -> #REF! | AZ10: =#REF!*2 -> #REF! | BA10: =#REF! -> #REF! | BB10: =#REF!*2 -> #REF! | BC10: =#REF! -> #REF! | BD10: =#REF!*2 -> #REF! | BE10: =#REF!-#REF! -> #REF! | BF10: =#REF!-#REF! -> #REF! | BG10: =#REF!-#REF! -> #REF! | BH10: =#REF!-#REF! -> #REF! | BI10: =#REF!-#REF! -> #REF! | BK10: =COUNTIFS(B10:G10, ">=1", B10:G10, "<=9") -> 1 | BL10: =COUNTIFS(B10:G10, ">=10", B10:G10, "<=19") -> 0 | BM10: =COUNTIFS(B10:G10, ">=20", B10:G10, "<=29") -> 4 | BN10: =COUNTIFS(B10:G10, ">=30", B10:G10, "<=39") -> 1 | BO10: =COUNTIFS(B10:G10, ">=40", B10:G10, "<=45") -> 0 | BP10: =#REF! -> #REF! | BQ10: =#REF!*2 -> #REF! | BR10: =#REF! -> #REF! | BS10: =#REF!*2 -> #REF! | BT10: =#REF! -> #REF! | BU10: =#REF!*2 -> #REF! | BV10: =#REF! -> #REF! | BW10: =#REF!*2 -> #REF! | BX10: =#REF! -> #REF! | BY10: =#REF!*2 -> #REF! | BZ10: =#REF! -> #REF! | CA10: =#REF!*2 -> #REF! | CB10: =C10-B10 -> 14 | CC10: =D10-C10 -> 3 | CD10: =E10-D10 -> 1 | CE10: =F10-E10 -> 4 | CF10: =G10-F10 -> 2 | CH10: =C10-B10 -> 14 | CI10: =D10-C10 -> 3 | CJ10: =E10-D10 -> 1 | CK10: =F10-E10 -> 4 | CL10: =G10-F10 -> 2 | CN10: =IF(OR(CH10="",ISBLANK(CH10),CH10=0),0,IF(MOD(CH10,2)=1,1,2)) -> 2 | CO10: =IF(OR(CI10="",ISBLANK(CI10),CI10=0),0,IF(MOD(CI10,2)=1,1,2)) -> 1 | CP10: =IF(OR(CJ10="",ISBLANK(CJ10),CJ10=0),0,IF(MOD(CJ10,2)=1,1,2)) -> 1 | CQ10: =IF(OR(CK10="",ISBLANK(CK10),CK10=0),0,IF(MOD(CK10,2)=1,1,2)) -> 2 | CR10: =IF(OR(CL10="",ISBLANK(CL10),CL10=0),0,IF(MOD(CL10,2)=1,1,2)) -> 2 | CT10: {=SUMPRODUCT(--(MOD(CH10:CL10,2)=1))} -> 2 | CU10: =5-CT10 -> 3 | CW10: {=SUMPRODUCT(--(MOD(CH10:CL10,10)>=1), --(MOD(CH10:CL10,10)<=5))} -> 5 | CX10: =5-CW10 -> 0 | CZ10: {=IFERROR(COUNT(_xlfn._xlws.FILTER(CH10:CL10, ISNUMBER(MATCH(CH10:CL10, {2,3,5,7,11,13,17,19,23,29,31,37,41,43}, 0)))), 0)} -> 2 | DA10: {=IFERROR(COUNT(_xlfn._xlws.FILTER(CH10:CL10, ISNUMBER(MATCH(CH10:CL10, {1,4,8,10,14,16,20,22,25,26,28,32,34,35,38,40,44}, 0)))), 0)} -> 3 | DB10: {=IFERROR(COUNT(_xlfn._xlws.FILTER(CH10:CL10, ISNUMBER(MATCH(CH10:CL10, {6,9,12,15,18,21,24,27,30,33,36,39,42,45}, 0)))), 0)} -> 0 | DD10: =#REF! -> #REF! | DE10: =#REF!*2 -> #REF! | DF10: =#REF! -> #REF! | DG10: =#REF!*2 -> #REF! | DH10: =#REF! -> #REF! | DI10: =#REF!*2 -> #REF! | DJ10: =#REF! -> #REF! | DK10: =#REF!*2 -> #REF! | DL10: =#REF! -> #REF! | DM10: =#REF!*2 -> #REF!
B11: 7 | C11: 18 | D11: 19 | E11: 26 | F11: 33 | G11: 45 | I11: =IF(OR(B11="",ISBLANK(B11),B11=0),0,IF(MOD(B11,2)=1,1,2)) -> 1 | J11: =IF(OR(C11="",ISBLANK(C11),C11=0),0,IF(MOD(C11,2)=1,1,2)) -> 2 | K11: =IF(OR(D11="",ISBLANK(D11),D11=0),0,IF(MOD(D11,2)=1,1,2)) -> 1 | L11: =IF(OR(E11="",ISBLANK(E11),E11=0),0,IF(MOD(E11,2)=1,1,2)) -> 2 | M11: =IF(OR(F11="",ISBLANK(F11),F11=0),0,IF(MOD(F11,2)=1,1,2)) -> 1 | N11: =IF(OR(G11="",ISBLANK(G11),G11=0),0,IF(MOD(G11,2)=1,1,2)) -> 1 | P11: {=SUMPRODUCT(--(MOD(B11:G11,2)=1))} -> 4 | Q11: =6-P11 -> 2 | S11: =COUNTIFS(B11:G11,">=1",B11:G11,"<=23") -> 3 | T11: =6-S11 -> 3 | V11: {=SUMPRODUCT(--(MOD(B11:G11,10)>=1), --(MOD(B11:G11,10)<=5))} -> 2 | W11: =6-V11 -> 4 | Y11: {=IFERROR(COUNT(_xlfn._xlws.FILTER(B11:G11, ISNUMBER(MATCH(B11:G11, {2,3,5,7,11,13,17,19,23,29,31,37,41,43}, 0)))), 0)} -> 2 | Z11: {=IFERROR(COUNT(_xlfn._xlws.FILTER(B11:G11, ISNUMBER(MATCH(B11:G11, {1,4,8,10,14,16,20,22,25,26,28,32,34,35,38,40,44}, 0)))), 0)} -> 1 | AA11: {=IFERROR(COUNT(_xlfn._xlws.FILTER(B11:G11, ISNUMBER(MATCH(B11:G11, {6,9,12,15,18,21,24,27,30,33,36,39,42,45}, 0)))), 0)} -> 3 | AJ11: =COUNTIFS(B11:G11,">=1",B11:G11,"<=14") -> 1 | AK11: =COUNTIFS(B11:G11,">=15",B11:G11,"<=31") -> 3 | AL11: =6-AK11-AJ11 -> 2 | AN11: =COUNTIFS($B11:$G11, ">=1",$B11:$G11, "<=9") -> 1 | AO11: =COUNTIFS($B11:$G11, ">=10",$B11:$G11, "<=18") -> 1 | AP11: =COUNTIFS($B11:$G11, ">=19",$B11:$G11, "<=27") -> 2 | AQ11: =COUNTIFS($B11:$G11, ">=28",$B11:$G11, "<=36") -> 1 | AR11: =COUNTIFS($B11:$G11, ">=37",$B11:$G11, "<=45") -> 1 | AS11: =#REF! -> #REF! | AT11: =#REF!*2 -> #REF! | AU11: =#REF! -> #REF! | AV11: =#REF!*2 -> #REF! | AW11: =#REF! -> #REF! | AX11: =#REF!*2 -> #REF! | AY11: =#REF! -> #REF! | AZ11: =#REF!*2 -> #REF! | BA11: =#REF! -> #REF! | BB11: =#REF!*2 -> #REF! | BC11: =#REF! -> #REF! | BD11: =#REF!*2 -> #REF! | BE11: =#REF!-#REF! -> #REF! | BF11: =#REF!-#REF! -> #REF! | BG11: =#REF!-#REF! -> #REF! | BH11: =#REF!-#REF! -> #REF! | BI11: =#REF!-#REF! -> #REF! | BK11: =COUNTIFS(B11:G11, ">=1", B11:G11, "<=9") -> 1 | BL11: =COUNTIFS(B11:G11, ">=10", B11:G11, "<=19") -> 2 | BM11: =COUNTIFS(B11:G11, ">=20", B11:G11, "<=29") -> 1 | BN11: =COUNTIFS(B11:G11, ">=30", B11:G11, "<=39") -> 1 | BO11: =COUNTIFS(B11:G11, ">=40", B11:G11, "<=45") -> 1 | BP11: =#REF! -> #REF! | BQ11: =#REF!*2 -> #REF! | BR11: =#REF! -> #REF! | BS11: =#REF!*2 -> #REF! | BT11: =#REF! -> #REF! | BU11: =#REF!*2 -> #REF! | BV11: =#REF! -> #REF! | BW11: =#REF!*2 -> #REF! | BX11: =#REF! -> #REF! | BY11: =#REF!*2 -> #REF! | BZ11: =#REF! -> #REF! | CA11: =#REF!*2 -> #REF! | CB11: =C11-B11 -> 11 | CC11: =D11-C11 -> 1 | CD11: =E11-D11 -> 7 | CE11: =F11-E11 -> 7 | CF11: =G11-F11 -> 12 | CH11: =C11-B11 -> 11 | CI11: =D11-C11 -> 1 | CJ11: =E11-D11 -> 7 | CK11: =F11-E11 -> 7 | CL11: =G11-F11 -> 12 | CN11: =IF(OR(CH11="",ISBLANK(CH11),CH11=0),0,IF(MOD(CH11,2)=1,1,2)) -> 1 | CO11: =IF(OR(CI11="",ISBLANK(CI11),CI11=0),0,IF(MOD(CI11,2)=1,1,2)) -> 1 | CP11: =IF(OR(CJ11="",ISBLANK(CJ11),CJ11=0),0,IF(MOD(CJ11,2)=1,1,2)) -> 1 | CQ11: =IF(OR(CK11="",ISBLANK(CK11),CK11=0),0,IF(MOD(CK11,2)=1,1,2)) -> 1 | CR11: =IF(OR(CL11="",ISBLANK(CL11),CL11=0),0,IF(MOD(CL11,2)=1,1,2)) -> 2 | CT11: {=SUMPRODUCT(--(MOD(CH11:CL11,2)=1))} -> 4 | CU11: =5-CT11 -> 1 | CW11: {=SUMPRODUCT(--(MOD(CH11:CL11,10)>=1), --(MOD(CH11:CL11,10)<=5))} -> 3 | CX11: =5-CW11 -> 2 | CZ11: {=IFERROR(COUNT(_xlfn._xlws.FILTER(CH11:CL11, ISNUMBER(MATCH(CH11:CL11, {2,3,5,7,11,13,17,19,23,29,31,37,41,43}, 0)))), 0)} -> 3 | DA11: {=IFERROR(COUNT(_xlfn._xlws.FILTER(CH11:CL11, ISNUMBER(MATCH(CH11:CL11, {1,4,8,10,14,16,20,22,25,26,28,32,34,35,38,40,44}, 0)))), 0)} -> 1 | DB11: {=IFERROR(COUNT(_xlfn._xlws.FILTER(CH11:CL11, ISNUMBER(MATCH(CH11:CL11, {6,9,12,15,18,21,24,27,30,33,36,39,42,45}, 0)))), 0)} -> 1 | DD11: =#REF! -> #REF! | DE11: =#REF!*2 -> #REF! | DF11: =#REF! -> #REF! | DG11: =#REF!*2 -> #REF! | DH11: =#REF! -> #REF! | DI11: =#REF!*2 -> #REF! | DJ11: =#REF! -> #REF! | DK11: =#REF!*2 -> #REF! | DL11: =#REF! -> #REF! | DM11: =#REF!*2 -> #REF!
B12: 10 | C12: 17 | D12: 22 | E12: 30 | F12: 35 | G12: 43 | I12: =IF(OR(B12="",ISBLANK(B12),B12=0),0,IF(MOD(B12,2)=1,1,2)) -> 2 | J12: =IF(OR(C12="",ISBLANK(C12),C12=0),0,IF(MOD(C12,2)=1,1,2)) -> 1 | K12: =IF(OR(D12="",ISBLANK(D12),D12=0),0,IF(MOD(D12,2)=1,1,2)) -> 2 | L12: =IF(OR(E12="",ISBLANK(E12),E12=0),0,IF(MOD(E12,2)=1,1,2)) -> 2 | M12: =IF(OR(F12="",ISBLANK(F12),F12=0),0,IF(MOD(F12,2)=1,1,2)) -> 1 | N12: =IF(OR(G12="",ISBLANK(G12),G12=0),0,IF(MOD(G12,2)=1,1,2)) -> 1 | P12: {=SUMPRODUCT(--(MOD(B12:G12,2)=1))} -> 3 | Q12: =6-P12 -> 3 | S12: =COUNTIFS(B12:G12,">=1",B12:G12,"<=23") -> 3 | T12: =6-S12 -> 3 | V12: {=SUMPRODUCT(--(MOD(B12:G12,10)>=1), --(MOD(B12:G12,10)<=5))} -> 3 | W12: =6-V12 -> 3 | Y12: {=IFERROR(COUNT(_xlfn._xlws.FILTER(B12:G12, ISNUMBER(MATCH(B12:G12, {2,3,5,7,11,13,17,19,23,29,31,37,41,43}, 0)))), 0)} -> 2 | Z12: {=IFERROR(COUNT(_xlfn._xlws.FILTER(B12:G12, ISNUMBER(MATCH(B12:G12, {1,4,8,10,14,16,20,22,25,26,28,32,34,35,38,40,44}, 0)))), 0)} -> 3 | AA12: {=IFERROR(COUNT(_xlfn._xlws.FILTER(B12:G12, ISNUMBER(MATCH(B12:G12, {6,9,12,15,18,21,24,27,30,33,36,39,42,45}, 0)))), 0)} -> 1 | AJ12: =COUNTIFS(B12:G12,">=1",B12:G12,"<=14") -> 1 | AK12: =COUNTIFS(B12:G12,">=15",B12:G12,"<=31") -> 3 | AL12: =6-AK12-AJ12 -> 2 | AN12: =COUNTIFS($B12:$G12, ">=1",$B12:$G12, "<=9") -> 0 | AO12: =COUNTIFS($B12:$G12, ">=10",$B12:$G12, "<=18") -> 2 | AP12: =COUNTIFS($B12:$G12, ">=19",$B12:$G12, "<=27") -> 1 | AQ12: =COUNTIFS($B12:$G12, ">=28",$B12:$G12, "<=36") -> 2 | AR12: =COUNTIFS($B12:$G12, ">=37",$B12:$G12, "<=45") -> 1 | AS12: =#REF! -> #REF! | AT12: =#REF!*2 -> #REF! | AU12: =#REF! -> #REF! | AV12: =#REF!*2 -> #REF! | AW12: =#REF! -> #REF! | AX12: =#REF!*2 -> #REF! | AY12: =#REF! -> #REF! | AZ12: =#REF!*2 -> #REF! | BA12: =#REF! -> #REF! | BB12: =#REF!*2 -> #REF! | BC12: =#REF! -> #REF! | BD12: =#REF!*2 -> #REF! | BE12: =#REF!-#REF! -> #REF! | BF12: =#REF!-#REF! -> #REF! | BG12: =#REF!-#REF! -> #REF! | BH12: =#REF!-#REF! -> #REF! | BI12: =#REF!-#REF! -> #REF! | BK12: =COUNTIFS(B12:G12, ">=1", B12:G12, "<=9") -> 0 | BL12: =COUNTIFS(B12:G12, ">=10", B12:G12, "<=19") -> 2 | BM12: =COUNTIFS(B12:G12, ">=20", B12:G12, "<=29") -> 1 | BN12: =COUNTIFS(B12:G12, ">=30", B12:G12, "<=39") -> 2 | BO12: =COUNTIFS(B12:G12, ">=40", B12:G12, "<=45") -> 1 | BP12: =#REF! -> #REF! | BQ12: =#REF!*2 -> #REF! | BR12: =#REF! -> #REF! | BS12: =#REF!*2 -> #REF! | BT12: =#REF! -> #REF! | BU12: =#REF!*2 -> #REF! | BV12: =#REF! -> #REF! | BW12: =#REF!*2 -> #REF! | BX12: =#REF! -> #REF! | BY12: =#REF!*2 -> #REF! | BZ12: =#REF! -> #REF! | CA12: =#REF!*2 -> #REF! | CB12: =C12-B12 -> 7 | CC12: =D12-C12 -> 5 | CD12: =E12-D12 -> 8 | CE12: =F12-E12 -> 5 | CF12: =G12-F12 -> 8 | CH12: =C12-B12 -> 7 | CI12: =D12-C12 -> 5 | CJ12: =E12-D12 -> 8 | CK12: =F12-E12 -> 5 | CL12: =G12-F12 -> 8 | CN12: =IF(OR(CH12="",ISBLANK(CH12),CH12=0),0,IF(MOD(CH12,2)=1,1,2)) -> 1 | CO12: =IF(OR(CI12="",ISBLANK(CI12),CI12=0),0,IF(MOD(CI12,2)=1,1,2)) -> 1 | CP12: =IF(OR(CJ12="",ISBLANK(CJ12),CJ12=0),0,IF(MOD(CJ12,2)=1,1,2)) -> 2 | CQ12: =IF(OR(CK12="",ISBLANK(CK12),CK12=0),0,IF(MOD(CK12,2)=1,1,2)) -> 1 | CR12: =IF(OR(CL12="",ISBLANK(CL12),CL12=0),0,IF(MOD(CL12,2)=1,1,2)) -> 2 | CT12: {=SUMPRODUCT(--(MOD(CH12:CL12,2)=1))} -> 3 | CU12: =5-CT12 -> 2 | CW12: {=SUMPRODUCT(--(MOD(CH12:CL12,10)>=1), --(MOD(CH12:CL12,10)<=5))} -> 2 | CX12: =5-CW12 -> 3 | CZ12: {=IFERROR(COUNT(_xlfn._xlws.FILTER(CH12:CL12, ISNUMBER(MATCH(CH12:CL12, {2,3,5,7,11,13,17,19,23,29,31,37,41,43}, 0)))), 0)} -> 3 | DA12: {=IFERROR(COUNT(_xlfn._xlws.FILTER(CH12:CL12, ISNUMBER(MATCH(CH12:CL12, {1,4,8,10,14,16,20,22,25,26,28,32,34,35,38,40,44}, 0)))), 0)} -> 2 | DB12: {=IFERROR(COUNT(_xlfn._xlws.FILTER(CH12:CL12, ISNUMBER(MATCH(CH12:CL12, {6,9,12,15,18,21,24,27,30,33,36,39,42,45}, 0)))), 0)} -> 0 | DD12: =#REF! -> #REF! | DE12: =#REF!*2 -> #REF! | DF12: =#REF! -> #REF! | DG12: =#REF!*2 -> #REF! | DH12: =#REF! -> #REF! | DI12: =#REF!*2 -> #REF! | DJ12: =#REF! -> #REF! | DK12: =#REF!*2 -> #REF! | DL12: =#REF! -> #REF! | DM12: =#REF!*2 -> #REF!
B13: 6 | C13: 7 | D13: 15 | E13: 22 | F13: 26 | G13: 40 | I13: =IF(OR(B13="",ISBLANK(B13),B13=0),0,IF(MOD(B13,2)=1,1,2)) -> 2 | J13: =IF(OR(C13="",ISBLANK(C13),C13=0),0,IF(MOD(C13,2)=1,1,2)) -> 1 | K13: =IF(OR(D13="",ISBLANK(D13),D13=0),0,IF(MOD(D13,2)=1,1,2)) -> 1 | L13: =IF(OR(E13="",ISBLANK(E13),E13=0),0,IF(MOD(E13,2)=1,1,2)) -> 2 | M13: =IF(OR(F13="",ISBLANK(F13),F13=0),0,IF(MOD(F13,2)=1,1,2)) -> 2 | N13: =IF(OR(G13="",ISBLANK(G13),G13=0),0,IF(MOD(G13,2)=1,1,2)) -> 2 | P13: {=SUMPRODUCT(--(MOD(B13:G13,2)=1))} -> 2 | Q13: =6-P13 -> 4 | S13: =COUNTIFS(B13:G13,">=1",B13:G13,"<=23") -> 4 | T13: =6-S13 -> 2 | V13: {=SUMPRODUCT(--(MOD(B13:G13,10)>=1), --(MOD(B13:G13,10)<=5))} -> 2 | W13: =6-V13 -> 4 | Y13: {=IFERROR(COUNT(_xlfn._xlws.FILTER(B13:G13, ISNUMBER(MATCH(B13:G13, {2,3,5,7,11,13,17,19,23,29,31,37,41,43}, 0)))), 0)} -> 1 | Z13: {=IFERROR(COUNT(_xlfn._xlws.FILTER(B13:G13, ISNUMBER(MATCH(B13:G13, {1,4,8,10,14,16,20,22,25,26,28,32,34,35,38,40,44}, 0)))), 0)} -> 3 | AA13: {=IFERROR(COUNT(_xlfn._xlws.FILTER(B13:G13, ISNUMBER(MATCH(B13:G13, {6,9,12,15,18,21,24,27,30,33,36,39,42,45}, 0)))), 0)} -> 2 | AJ13: =COUNTIFS(B13:G13,">=1",B13:G13,"<=14") -> 2 | AK13: =COUNTIFS(B13:G13,">=15",B13:G13,"<=31") -> 3 | AL13: =6-AK13-AJ13 -> 1 | AN13: =COUNTIFS($B13:$G13, ">=1",$B13:$G13, "<=9") -> 2 | AO13: =COUNTIFS($B13:$G13, ">=10",$B13:$G13, "<=18") -> 1 | AP13: =COUNTIFS($B13:$G13, ">=19",$B13:$G13, "<=27") -> 2 | AQ13: =COUNTIFS($B13:$G13, ">=28",$B13:$G13, "<=36") -> 0 | AR13: =COUNTIFS($B13:$G13, ">=37",$B13:$G13, "<=45") -> 1 | AS13: =#REF! -> #REF! | AT13: =#REF!*2 -> #REF! | AU13: =#REF! -> #REF! | AV13: =#REF!*2 -> #REF! | AW13: =#REF! -> #REF! | AX13: =#REF!*2 -> #REF! | AY13: =#REF! -> #REF! | AZ13: =#REF!*2 -> #REF! | BA13: =#REF! -> #REF! | BB13: =#REF!*2 -> #REF! | BC13: =#REF! -> #REF! | BD13: =#REF!*2 -> #REF! | BE13: =#REF!-#REF! -> #REF! | BF13: =#REF!-#REF! -> #REF! | BG13: =#REF!-#REF! -> #REF! | BH13: =#REF!-#REF! -> #REF! | BI13: =#REF!-#REF! -> #REF! | BK13: =COUNTIFS(B13:G13, ">=1", B13:G13, "<=9") -> 2 | BL13: =COUNTIFS(B13:G13, ">=10", B13:G13, "<=19") -> 1 | BM13: =COUNTIFS(B13:G13, ">=20", B13:G13, "<=29") -> 2 | BN13: =COUNTIFS(B13:G13, ">=30", B13:G13, "<=39") -> 0 | BO13: =COUNTIFS(B13:G13, ">=40", B13:G13, "<=45") -> 1 | BP13: =#REF! -> #REF! | BQ13: =#REF!*2 -> #REF! | BR13: =#REF! -> #REF! | BS13: =#REF!*2 -> #REF! | BT13: =#REF! -> #REF! | BU13: =#REF!*2 -> #REF! | BV13: =#REF! -> #REF! | BW13: =#REF!*2 -> #REF! | BX13: =#REF! -> #REF! | BY13: =#REF!*2 -> #REF! | BZ13: =#REF! -> #REF! | CA13: =#REF!*2 -> #REF! | CB13: =C13-B13 -> 1 | CC13: =D13-C13 -> 8 | CD13: =E13-D13 -> 7 | CE13: =F13-E13 -> 4 | CF13: =G13-F13 -> 14 | CH13: =C13-B13 -> 1 | CI13: =D13-C13 -> 8 | CJ13: =E13-D13 -> 7 | CK13: =F13-E13 -> 4 | CL13: =G13-F13 -> 14 | CN13: =IF(OR(CH13="",ISBLANK(CH13),CH13=0),0,IF(MOD(CH13,2)=1,1,2)) -> 1 | CO13: =IF(OR(CI13="",ISBLANK(CI13),CI13=0),0,IF(MOD(CI13,2)=1,1,2)) -> 2 | CP13: =IF(OR(CJ13="",ISBLANK(CJ13),CJ13=0),0,IF(MOD(CJ13,2)=1,1,2)) -> 1 | CQ13: =IF(OR(CK13="",ISBLANK(CK13),CK13=0),0,IF(MOD(CK13,2)=1,1,2)) -> 2 | CR13: =IF(OR(CL13="",ISBLANK(CL13),CL13=0),0,IF(MOD(CL13,2)=1,1,2)) -> 2 | CT13: {=SUMPRODUCT(--(MOD(CH13:CL13,2)=1))} -> 2 | CU13: =5-CT13 -> 3 | CW13: {=SUMPRODUCT(--(MOD(CH13:CL13,10)>=1), --(MOD(CH13:CL13,10)<=5))} -> 3 | CX13: =5-CW13 -> 2 | CZ13: {=IFERROR(COUNT(_xlfn._xlws.FILTER(CH13:CL13, ISNUMBER(MATCH(CH13:CL13, {2,3,5,7,11,13,17,19,23,29,31,37,41,43}, 0)))), 0)} -> 1 | DA13: {=IFERROR(COUNT(_xlfn._xlws.FILTER(CH13:CL13, ISNUMBER(MATCH(CH13:CL13, {1,4,8,10,14,16,20,22,25,26,28,32,34,35,38,40,44}, 0)))), 0)} -> 4 | DB13: {=IFERROR(COUNT(_xlfn._xlws.FILTER(CH13:CL13, ISNUMBER(MATCH(CH13:CL13, {6,9,12,15,18,21,24,27,30,33,36,39,42,45}, 0)))), 0)} -> 0 | DD13: =#REF! -> #REF! | DE13: =#REF!*2 -> #REF! | DF13: =#REF! -> #REF! | DG13: =#REF!*2 -> #REF! | DH13: =#REF! -> #REF! | DI13: =#REF!*2 -> #REF! | DJ13: =#REF! -> #REF! | DK13: =#REF!*2 -> #REF! | DL13: =#REF! -> #REF! | DM13: =#REF!*2 -> #REF!
B14: 8 | C14: 14 | D14: 28 | E14: 29 | F14: 34 | G14: 40 | I14: =IF(OR(B14="",ISBLANK(B14),B14=0),0,IF(MOD(B14,2)=1,1,2)) -> 2 | J14: =IF(OR(C14="",ISBLANK(C14),C14=0),0,IF(MOD(C14,2)=1,1,2)) -> 2 | K14: =IF(OR(D14="",ISBLANK(D14),D14=0),0,IF(MOD(D14,2)=1,1,2)) -> 2 | L14: =IF(OR(E14="",ISBLANK(E14),E14=0),0,IF(MOD(E14,2)=1,1,2)) -> 1 | M14: =IF(OR(F14="",ISBLANK(F14),F14=0),0,IF(MOD(F14,2)=1,1,2)) -> 2 | N14: =IF(OR(G14="",ISBLANK(G14),G14=0),0,IF(MOD(G14,2)=1,1,2)) -> 2 | P14: {=SUMPRODUCT(--(MOD(B14:G14,2)=1))} -> 1 | Q14: =6-P14 -> 5 | S14: =COUNTIFS(B14:G14,">=1",B14:G14,"<=23") -> 2 | T14: =6-S14 -> 4 | V14: {=SUMPRODUCT(--(MOD(B14:G14,10)>=1), --(MOD(B14:G14,10)<=5))} -> 2 | W14: =6-V14 -> 4 | Y14: {=IFERROR(COUNT(_xlfn._xlws.FILTER(B14:G14, ISNUMBER(MATCH(B14:G14, {2,3,5,7,11,13,17,19,23,29,31,37,41,43}, 0)))), 0)} -> 1 | Z14: {=IFERROR(COUNT(_xlfn._xlws.FILTER(B14:G14, ISNUMBER(MATCH(B14:G14, {1,4,8,10,14,16,20,22,25,26,28,32,34,35,38,40,44}, 0)))), 0)} -> 5 | AA14: {=IFERROR(COUNT(_xlfn._xlws.FILTER(B14:G14, ISNUMBER(MATCH(B14:G14, {6,9,12,15,18,21,24,27,30,33,36,39,42,45}, 0)))), 0)} -> 0 | AJ14: =COUNTIFS(B14:G14,">=1",B14:G14,"<=14") -> 2 | AK14: =COUNTIFS(B14:G14,">=15",B14:G14,"<=31") -> 2 | AL14: =6-AK14-AJ14 -> 2 | AN14: =COUNTIFS($B14:$G14, ">=1",$B14:$G14, "<=9") -> 1 | AO14: =COUNTIFS($B14:$G14, ">=10",$B14:$G14, "<=18") -> 1 | AP14: =COUNTIFS($B14:$G14, ">=19",$B14:$G14, "<=27") -> 0 | AQ14: =COUNTIFS($B14:$G14, ">=28",$B14:$G14, "<=36") -> 3 | AR14: =COUNTIFS($B14:$G14, ">=37",$B14:$G14, "<=45") -> 1 | AS14: =#REF! -> #REF! | AT14: =#REF!*2 -> #REF! | AU14: =#REF! -> #REF! | AV14: =#REF!*2 -> #REF! | AW14: =#REF! -> #REF! | AX14: =#REF!*2 -> #REF! | AY14: =#REF! -> #REF! | AZ14: =#REF!*2 -> #REF! | BA14: =#REF! -> #REF! | BB14: =#REF!*2 -> #REF! | BC14: =#REF! -> #REF! | BD14: =#REF!*2 -> #REF! | BE14: =#REF!-#REF! -> #REF! | BF14: =#REF!-#REF! -> #REF! | BG14: =#REF!-#REF! -> #REF! | BH14: =#REF!-#REF! -> #REF! | BI14: =#REF!-#REF! -> #REF! | BK14: =COUNTIFS(B14:G14, ">=1", B14:G14, "<=9") -> 1 | BL14: =COUNTIFS(B14:G14, ">=10", B14:G14, "<=19") -> 1 | BM14: =COUNTIFS(B14:G14, ">=20", B14:G14, "<=29") -> 2 | BN14: =COUNTIFS(B14:G14, ">=30", B14:G14, "<=39") -> 1 | BO14: =COUNTIFS(B14:G14, ">=40", B14:G14, "<=45") -> 1 | BP14: =#REF! -> #REF! | BQ14: =#REF!*2 -> #REF! | BR14: =#REF! -> #REF! | BS14: =#REF!*2 -> #REF! | BT14: =#REF! -> #REF! | BU14: =#REF!*2 -> #REF! | BV14: =#REF! -> #REF! | BW14: =#REF!*2 -> #REF! | BX14: =#REF! -> #REF! | BY14: =#REF!*2 -> #REF! | BZ14: =#REF! -> #REF! | CA14: =#REF!*2 -> #REF! | CB14: =C14-B14 -> 6 | CC14: =D14-C14 -> 14 | CD14: =E14-D14 -> 1 | CE14: =F14-E14 -> 5 | CF14: =G14-F14 -> 6 | CH14: =C14-B14 -> 6 | CI14: =D14-C14 -> 14 | CJ14: =E14-D14 -> 1 | CK14: =F14-E14 -> 5 | CL14: =G14-F14 -> 6 | CN14: =IF(OR(CH14="",ISBLANK(CH14),CH14=0),0,IF(MOD(CH14,2)=1,1,2)) -> 2 | CO14: =IF(OR(CI14="",ISBLANK(CI14),CI14=0),0,IF(MOD(CI14,2)=1,1,2)) -> 2 | CP14: =IF(OR(CJ14="",ISBLANK(CJ14),CJ14=0),0,IF(MOD(CJ14,2)=1,1,2)) -> 1 | CQ14: =IF(OR(CK14="",ISBLANK(CK14),CK14=0),0,IF(MOD(CK14,2)=1,1,2)) -> 1 | CR14: =IF(OR(CL14="",ISBLANK(CL14),CL14=0),0,IF(MOD(CL14,2)=1,1,2)) -> 2 | CT14: {=SUMPRODUCT(--(MOD(CH14:CL14,2)=1))} -> 2 | CU14: =5-CT14 -> 3 | CW14: {=SUMPRODUCT(--(MOD(CH14:CL14,10)>=1), --(MOD(CH14:CL14,10)<=5))} -> 3 | CX14: =5-CW14 -> 2 | CZ14: {=IFERROR(COUNT(_xlfn._xlws.FILTER(CH14:CL14, ISNUMBER(MATCH(CH14:CL14, {2,3,5,7,11,13,17,19,23,29,31,37,41,43}, 0)))), 0)} -> 1 | DA14: {=IFERROR(COUNT(_xlfn._xlws.FILTER(CH14:CL14, ISNUMBER(MATCH(CH14:CL14, {1,4,8,10,14,16,20,22,25,26,28,32,34,35,38,40,44}, 0)))), 0)} -> 2 | DB14: {=IFERROR(COUNT(_xlfn._xlws.FILTER(CH14:CL14, ISNUMBER(MATCH(CH14:CL14, {6,9,12,15,18,21,24,27,30,33,36,39,42,45}, 0)))), 0)} -> 2 | DD14: =#REF! -> #REF! | DE14: =#REF!*2 -> #REF! | DF14: =#REF! -> #REF! | DG14: =#REF!*2 -> #REF! | DH14: =#REF! -> #REF! | DI14: =#REF!*2 -> #REF! | DJ14: =#REF! -> #REF! | DK14: =#REF!*2 -> #REF! | DL14: =#REF! -> #REF! | DM14: =#REF!*2 -> #REF!
B15: 1 | C15: 12 | D15: 16 | E15: 19 | F15: 23 | G15: 43 | I15: =IF(OR(B15="",ISBLANK(B15),B15=0),0,IF(MOD(B15,2)=1,1,2)) -> 1 | J15: =IF(OR(C15="",ISBLANK(C15),C15=0),0,IF(MOD(C15,2)=1,1,2)) -> 2 | K15: =IF(OR(D15="",ISBLANK(D15),D15=0),0,IF(MOD(D15,2)=1,1,2)) -> 2 | L15: =IF(OR(E15="",ISBLANK(E15),E15=0),0,IF(MOD(E15,2)=1,1,2)) -> 1 | M15: =IF(OR(F15="",ISBLANK(F15),F15=0),0,IF(MOD(F15,2)=1,1,2)) -> 1 | N15: =IF(OR(G15="",ISBLANK(G15),G15=0),0,IF(MOD(G15,2)=1,1,2)) -> 1 | P15: {=SUMPRODUCT(--(MOD(B15:G15,2)=1))} -> 4 | Q15: =6-P15 -> 2 | S15: =COUNTIFS(B15:G15,">=1",B15:G15,"<=23") -> 5 | T15: =6-S15 -> 1 | V15: {=SUMPRODUCT(--(MOD(B15:G15,10)>=1), --(MOD(B15:G15,10)<=5))} -> 4 | W15: =6-V15 -> 2 | Y15: {=IFERROR(COUNT(_xlfn._xlws.FILTER(B15:G15, ISNUMBER(MATCH(B15:G15, {2,3,5,7,11,13,17,19,23,29,31,37,41,43}, 0)))), 0)} -> 3 | Z15: {=IFERROR(COUNT(_xlfn._xlws.FILTER(B15:G15, ISNUMBER(MATCH(B15:G15, {1,4,8,10,14,16,20,22,25,26,28,32,34,35,38,40,44}, 0)))), 0)} -> 2 | AA15: {=IFERROR(COUNT(_xlfn._xlws.FILTER(B15:G15, ISNUMBER(MATCH(B15:G15, {6,9,12,15,18,21,24,27,30,33,36,39,42,45}, 0)))), 0)} -> 1 | AJ15: =COUNTIFS(B15:G15,">=1",B15:G15,"<=14") -> 2 | AK15: =COUNTIFS(B15:G15,">=15",B15:G15,"<=31") -> 3 | AL15: =6-AK15-AJ15 -> 1 | AN15: =COUNTIFS($B15:$G15, ">=1",$B15:$G15, "<=9") -> 1 | AO15: =COUNTIFS($B15:$G15, ">=10",$B15:$G15, "<=18") -> 2 | AP15: =COUNTIFS($B15:$G15, ">=19",$B15:$G15, "<=27") -> 2 | AQ15: =COUNTIFS($B15:$G15, ">=28",$B15:$G15, "<=36") -> 0 | AR15: =COUNTIFS($B15:$G15, ">=37",$B15:$G15, "<=45") -> 1 | AS15: =#REF! -> #REF! | AT15: =#REF!*2 -> #REF! | AU15: =#REF! -> #REF! | AV15: =#REF!*2 -> #REF! | AW15: =#REF! -> #REF! | AX15: =#REF!*2 -> #REF! | AY15: =#REF! -> #REF! | AZ15: =#REF!*2 -> #REF! | BA15: =#REF! -> #REF! | BB15: =#REF!*2 -> #REF! | BC15: =#REF! -> #REF! | BD15: =#REF!*2 -> #REF! | BE15: =#REF!-#REF! -> #REF! | BF15: =#REF!-#REF! -> #REF! | BG15: =#REF!-#REF! -> #REF! | BH15: =#REF!-#REF! -> #REF! | BI15: =#REF!-#REF! -> #REF! | BK15: =COUNTIFS(B15:G15, ">=1", B15:G15, "<=9") -> 1 | BL15: =COUNTIFS(B15:G15, ">=10", B15:G15, "<=19") -> 3 | BM15: =COUNTIFS(B15:G15, ">=20", B15:G15, "<=29") -> 1 | BN15: =COUNTIFS(B15:G15, ">=30", B15:G15, "<=39") -> 0 | BO15: =COUNTIFS(B15:G15, ">=40", B15:G15, "<=45") -> 1 | BP15: =#REF! -> #REF! | BQ15: =#REF!*2 -> #REF! | BR15: =#REF! -> #REF! | BS15: =#REF!*2 -> #REF! | BT15: =#REF! -> #REF! | BU15: =#REF!*2 -> #REF! | BV15: =#REF! -> #REF! | BW15: =#REF!*2 -> #REF! | BX15: =#REF! -> #REF! | BY15: =#REF!*2 -> #REF! | BZ15: =#REF! -> #REF! | CA15: =#REF!*2 -> #REF! | CB15: =C15-B15 -> 11 | CC15: =D15-C15 -> 4 | CD15: =E15-D15 -> 3 | CE15: =F15-E15 -> 4 | CF15: =G15-F15 -> 20 | CH15: =C15-B15 -> 11 | CI15: =D15-C15 -> 4 | CJ15: =E15-D15 -> 3 | CK15: =F15-E15 -> 4 | CL15: =G15-F15 -> 20 | CN15: =IF(OR(CH15="",ISBLANK(CH15),CH15=0),0,IF(MOD(CH15,2)=1,1,2)) -> 1 | CO15: =IF(OR(CI15="",ISBLANK(CI15),CI15=0),0,IF(MOD(CI15,2)=1,1,2)) -> 2 | CP15: =IF(OR(CJ15="",ISBLANK(CJ15),CJ15=0),0,IF(MOD(CJ15,2)=1,1,2)) -> 1 | CQ15: =IF(OR(CK15="",ISBLANK(CK15),CK15=0),0,IF(MOD(CK15,2)=1,1,2)) -> 2 | CR15: =IF(OR(CL15="",ISBLANK(CL15),CL15=0),0,IF(MOD(CL15,2)=1,1,2)) -> 2 | CT15: {=SUMPRODUCT(--(MOD(CH15:CL15,2)=1))} -> 2 | CU15: =5-CT15 -> 3 | CW15: {=SUMPRODUCT(--(MOD(CH15:CL15,10)>=1), --(MOD(CH15:CL15,10)<=5))} -> 4 | CX15: =5-CW15 -> 1 | CZ15: {=IFERROR(COUNT(_xlfn._xlws.FILTER(CH15:CL15, ISNUMBER(MATCH(CH15:CL15, {2,3,5,7,11,13,17,19,23,29,31,37,41,43}, 0)))), 0)} -> 2 | DA15: {=IFERROR(COUNT(_xlfn._xlws.FILTER(CH15:CL15, ISNUMBER(MATCH(CH15:CL15, {1,4,8,10,14,16,20,22,25,26,28,32,34,35,38,40,44}, 0)))), 0)} -> 3 | DB15: {=IFERROR(COUNT(_xlfn._xlws.FILTER(CH15:CL15, ISNUMBER(MATCH(CH15:CL15, {6,9,12,15,18,21,24,27,30,33,36,39,42,45}, 0)))), 0)} -> 0 | DD15: =#REF! -> #REF! | DE15: =#REF!*2 -> #REF! | DF15: =#REF! -> #REF! | DG15: =#REF!*2 -> #REF! | DH15: =#REF! -> #REF! | DI15: =#REF!*2 -> #REF! | DJ15: =#REF! -> #REF! | DK15: =#REF!*2 -> #REF! | DL15: =#REF! -> #REF! | DM15: =#REF!*2 -> #REF!
... B42: 13 | C42: 19 | D42: 21 | E42: 24 | F42: 34 | G42: 35 | I42: =IF(OR(B42="",ISBLANK(B42),B42=0),0,IF(MOD(B42,2)=1,1,2)) -> 1 | J42: =IF(OR(C42="",ISBLANK(C42),C42=0),0,IF(MOD(C42,2)=1,1,2)) -> 1 | K42: =IF(OR(D42="",ISBLANK(D42),D42=0),0,IF(MOD(D42,2)=1,1,2)) -> 1 | L42: =IF(OR(E42="",ISBLANK(E42),E42=0),0,IF(MOD(E42,2)=1,1,2)) -> 2 | M42: =IF(OR(F42="",ISBLANK(F42),F42=0),0,IF(MOD(F42,2)=1,1,2)) -> 2 | N42: =IF(OR(G42="",ISBLANK(G42),G42=0),0,IF(MOD(G42,2)=1,1,2)) -> 1 | P42: {=SUMPRODUCT(--(MOD(B42:G42,2)=1))} -> 4 | Q42: =6-P42 -> 2 | S42: =COUNTIFS(B42:G42,">=1",B42:G42,"<=23") -> 3 | T42: =6-S42 -> 3 | V42: {=SUMPRODUCT(--(MOD(B42:G42,10)>=1), --(MOD(B42:G42,10)<=5))} -> 5 | W42: =6-V42 -> 1 | Y42: {=IFERROR(COUNT(_xlfn._xlws.FILTER(B42:G42, ISNUMBER(MATCH(B42:G42, {2,3,5,7,11,13,17,19,23,29,31,37,41,43}, 0)))), 0)} -> 2 | Z42: {=IFERROR(COUNT(_xlfn._xlws.FILTER(B42:G42, ISNUMBER(MATCH(B42:G42, {1,4,8,10,14,16,20,22,25,26,28,32,34,35,38,40,44}, 0)))), 0)} -> 2 | AA42: {=IFERROR(COUNT(_xlfn._xlws.FILTER(B42:G42, ISNUMBER(MATCH(B42:G42, {6,9,12,15,18,21,24,27,30,33,36,39,42,45}, 0)))), 0)} -> 2 | AJ42: =COUNTIFS(B42:G42,">=1",B42:G42,"<=14") -> 1 | AK42: =COUNTIFS(B42:G42,">=15",B42:G42,"<=31") -> 3 | AL42: =6-AK42-AJ42 -> 2 | AN42: =COUNTIFS($B42:$G42, ">=1",$B42:$G42, "<=9") -> 0 | AO42: =COUNTIFS($B42:$G42, ">=10",$B42:$G42, "<=18") -> 1 | AP42: =COUNTIFS($B42:$G42, ">=19",$B42:$G42, "<=27") -> 3 | AQ42: =COUNTIFS($B42:$G42, ">=28",$B42:$G42, "<=36") -> 2 | AR42: =COUNTIFS($B42:$G42, ">=37",$B42:$G42, "<=45") -> 0 | AS42: =#REF! -> #REF! | AT42: =#REF!*2 -> #REF! | AU42: =#REF! -> #REF! | AV42: =#REF!*2 -> #REF! | AW42: =#REF! -> #REF! | AX42: =#REF!*2 -> #REF! | AY42: =#REF! -> #REF! | AZ42: =#REF!*2 -> #REF! | BA42: =#REF! -> #REF! | BB42: =#REF!*2 -> #REF! | BC42: =#REF! -> #REF! | BD42: =#REF!*2 -> #REF! | BE42: =#REF!-#REF! -> #REF! | BF42: =#REF!-#REF! -> #REF! | BG42: =#REF!-#REF! -> #REF! | BH42: =#REF!-#REF! -> #REF! | BI42: =#REF!-#REF! -> #REF! | BK42: =COUNTIFS(B42:G42, ">=1", B42:G42, "<=9") -> 0 | BL42: =COUNTIFS(B42:G42, ">=10", B42:G42, "<=19") -> 2 | BM42: =COUNTIFS(B42:G42, ">=20", B42:G42, "<=29") -> 2 | BN42: =COUNTIFS(B42:G42, ">=30", B42:G42, "<=39") -> 2 | BO42: =COUNTIFS(B42:G42, ">=40", B42:G42, "<=45") -> 0 | BP42: =#REF! -> #REF! | BQ42: =#REF!*2 -> #REF! | BR42: =#REF! -> #REF! | BS42: =#REF!*2 -> #REF! | BT42: =#REF! -> #REF! | BU42: =#REF!*2 -> #REF! | BV42: =#REF! -> #REF! | BW42: =#REF!*2 -> #REF! | BX42: =#REF! -> #REF! | BY42: =#REF!*2 -> #REF! | BZ42: =#REF! -> #REF! | CA42: =#REF!*2 -> #REF! | CB42: =C42-B42 -> 6 | CC42: =D42-C42 -> 2 | CD42: =E42-D42 -> 3 | CE42: =F42-E42 -> 10 | CF42: =G42-F42 -> 1 | CH42: =C42-B42 -> 6 | CI42: =D42-C42 -> 2 | CJ42: =E42-D42 -> 3 | CK42: =F42-E42 -> 10 | CL42: =G42-F42 -> 1 | CN42: =IF(OR(CH42="",ISBLANK(CH42),CH42=0),0,IF(MOD(CH42,2)=1,1,2)) -> 2 | CO42: =IF(OR(CI42="",ISBLANK(CI42),CI42=0),0,IF(MOD(CI42,2)=1,1,2)) -> 2 | CP42: =IF(OR(CJ42="",ISBLANK(CJ42),CJ42=0),0,IF(MOD(CJ42,2)=1,1,2)) -> 1 | CQ42: =IF(OR(CK42="",ISBLANK(CK42),CK42=0),0,IF(MOD(CK42,2)=1,1,2)) -> 2 | CR42: =IF(OR(CL42="",ISBLANK(CL42),CL42=0),0,IF(MOD(CL42,2)=1,1,2)) -> 1 | CT42: {=SUMPRODUCT(--(MOD(CH42:CL42,2)=1))} -> 2 | CU42: =5-CT42 -> 3 | CW42: {=SUMPRODUCT(--(MOD(CH42:CL42,10)>=1), --(MOD(CH42:CL42,10)<=5))} -> 3 | CX42: =5-CW42 -> 2 | CZ42: {=IFERROR(COUNT(_xlfn._xlws.FILTER(CH42:CL42, ISNUMBER(MATCH(CH42:CL42, {2,3,5,7,11,13,17,19,23,29,31,37,41,43}, 0)))), 0)} -> 2 | DA42: {=IFERROR(COUNT(_xlfn._xlws.FILTER(CH42:CL42, ISNUMBER(MATCH(CH42:CL42, {1,4,8,10,14,16,20,22,25,26,28,32,34,35,38,40,44}, 0)))), 0)} -> 2 | DB42: {=IFERROR(COUNT(_xlfn._xlws.FILTER(CH42:CL42, ISNUMBER(MATCH(CH42:CL42, {6,9,12,15,18,21,24,27,30,33,36,39,42,45}, 0)))), 0)} -> 1 | DD42: =#REF! -> #REF! | DE42: =#REF!*2 -> #REF! | DF42: =#REF! -> #REF! | DG42: =#REF!*2 -> #REF! | DH42: =#REF! -> #REF! | DI42: =#REF!*2 -> #REF! | DJ42: =#REF! -> #REF! | DK42: =#REF!*2 -> #REF! | DL42: =#REF! -> #REF! | DM42: =#REF!*2 -> #REF!
B43: 3 | C43: 8 | D43: 17 | E43: 30 | F43: 33 | G43: 34 | I43: =IF(OR(B43="",ISBLANK(B43),B43=0),0,IF(MOD(B43,2)=1,1,2)) -> 1 | J43: =IF(OR(C43="",ISBLANK(C43),C43=0),0,IF(MOD(C43,2)=1,1,2)) -> 2 | K43: =IF(OR(D43="",ISBLANK(D43),D43=0),0,IF(MOD(D43,2)=1,1,2)) -> 1 | L43: =IF(OR(E43="",ISBLANK(E43),E43=0),0,IF(MOD(E43,2)=1,1,2)) -> 2 | M43: =IF(OR(F43="",ISBLANK(F43),F43=0),0,IF(MOD(F43,2)=1,1,2)) -> 1 | N43: =IF(OR(G43="",ISBLANK(G43),G43=0),0,IF(MOD(G43,2)=1,1,2)) -> 2 | P43: {=SUMPRODUCT(--(MOD(B43:G43,2)=1))} -> 3 | Q43: =6-P43 -> 3 | S43: =COUNTIFS(B43:G43,">=1",B43:G43,"<=23") -> 3 | T43: =6-S43 -> 3 | V43: {=SUMPRODUCT(--(MOD(B43:G43,10)>=1), --(MOD(B43:G43,10)<=5))} -> 3 | W43: =6-V43 -> 3 | Y43: {=IFERROR(COUNT(_xlfn._xlws.FILTER(B43:G43, ISNUMBER(MATCH(B43:G43, {2,3,5,7,11,13,17,19,23,29,31,37,41,43}, 0)))), 0)} -> 2 | Z43: {=IFERROR(COUNT(_xlfn._xlws.FILTER(B43:G43, ISNUMBER(MATCH(B43:G43, {1,4,8,10,14,16,20,22,25,26,28,32,34,35,38,40,44}, 0)))), 0)} -> 2 | AA43: {=IFERROR(COUNT(_xlfn._xlws.FILTER(B43:G43, ISNUMBER(MATCH(B43:G43, {6,9,12,15,18,21,24,27,30,33,36,39,42,45}, 0)))), 0)} -> 2 | AJ43: =COUNTIFS(B43:G43,">=1",B43:G43,"<=14") -> 2 | AK43: =COUNTIFS(B43:G43,">=15",B43:G43,"<=31") -> 2 | AL43: =6-AK43-AJ43 -> 2 | AN43: =COUNTIFS($B43:$G43, ">=1",$B43:$G43, "<=9") -> 2 | AO43: =COUNTIFS($B43:$G43, ">=10",$B43:$G43, "<=18") -> 1 | AP43: =COUNTIFS($B43:$G43, ">=19",$B43:$G43, "<=27") -> 0 | AQ43: =COUNTIFS($B43:$G43, ">=28",$B43:$G43, "<=36") -> 3 | AR43: =COUNTIFS($B43:$G43, ">=37",$B43:$G43, "<=45") -> 0 | AS43: =#REF! -> #REF! | AT43: =#REF!*2 -> #REF! | AU43: =#REF! -> #REF! | AV43: =#REF!*2 -> #REF! | AW43: =#REF! -> #REF! | AX43: =#REF!*2 -> #REF! | AY43: =#REF! -> #REF! | AZ43: =#REF!*2 -> #REF! | BA43: =#REF! -> #REF! | BB43: =#REF!*2 -> #REF! | BC43: =#REF! -> #REF! | BD43: =#REF!*2 -> #REF! | BE43: =#REF!-#REF! -> #REF! | BF43: =#REF!-#REF! -> #REF! | BG43: =#REF!-#REF! -> #REF! | BH43: =#REF!-#REF! -> #REF! | BI43: =#REF!-#REF! -> #REF! | BK43: =COUNTIFS(B43:G43, ">=1", B43:G43, "<=9") -> 2 | BL43: =COUNTIFS(B43:G43, ">=10", B43:G43, "<=19") -> 1 | BM43: =COUNTIFS(B43:G43, ">=20", B43:G43, "<=29") -> 0 | BN43: =COUNTIFS(B43:G43, ">=30", B43:G43, "<=39") -> 3 | BO43: =COUNTIFS(B43:G43, ">=40", B43:G43, "<=45") -> 0 | BP43: =#REF! -> #REF! | BQ43: =#REF!*2 -> #REF! | BR43: =#REF! -> #REF! | BS43: =#REF!*2 -> #REF! | BT43: =#REF! -> #REF! | BU43: =#REF!*2 -> #REF! | BV43: =#REF! -> #REF! | BW43: =#REF!*2 -> #REF! | BX43: =#REF! -> #REF! | BY43: =#REF!*2 -> #REF! | BZ43: =#REF! -> #REF! | CA43: =#REF!*2 -> #REF! | CB43: =C43-B43 -> 5 | CC43: =D43-C43 -> 9 | CD43: =E43-D43 -> 13 | CE43: =F43-E43 -> 3 | CF43: =G43-F43 -> 1 | CH43: =C43-B43 -> 5 | CI43: =D43-C43 -> 9 | CJ43: =E43-D43 -> 13 | CK43: =F43-E43 -> 3 | CL43: =G43-F43 -> 1 | CN43: =IF(OR(CH43="",ISBLANK(CH43),CH43=0),0,IF(MOD(CH43,2)=1,1,2)) -> 1 | CO43: =IF(OR(CI43="",ISBLANK(CI43),CI43=0),0,IF(MOD(CI43,2)=1,1,2)) -> 1 | CP43: =IF(OR(CJ43="",ISBLANK(CJ43),CJ43=0),0,IF(MOD(CJ43,2)=1,1,2)) -> 1 | CQ43: =IF(OR(CK43="",ISBLANK(CK43),CK43=0),0,IF(MOD(CK43,2)=1,1,2)) -> 1 | CR43: =IF(OR(CL43="",ISBLANK(CL43),CL43=0),0,IF(MOD(CL43,2)=1,1,2)) -> 1 | CT43: {=SUMPRODUCT(--(MOD(CH43:CL43,2)=1))} -> 5 | CU43: =5-CT43 -> 0 | CW43: {=SUMPRODUCT(--(MOD(CH43:CL43,10)>=1), --(MOD(CH43:CL43,10)<=5))} -> 4 | CX43: =5-CW43 -> 1 | CZ43: {=IFERROR(COUNT(_xlfn._xlws.FILTER(CH43:CL43, ISNUMBER(MATCH(CH43:CL43, {2,3,5,7,11,13,17,19,23,29,31,37,41,43}, 0)))), 0)} -> 3 | DA43: {=IFERROR(COUNT(_xlfn._xlws.FILTER(CH43:CL43, ISNUMBER(MATCH(CH43:CL43, {1,4,8,10,14,16,20,22,25,26,28,32,34,35,38,40,44}, 0)))), 0)} -> 1 | DB43: {=IFERROR(COUNT(_xlfn._xlws.FILTER(CH43:CL43, ISNUMBER(MATCH(CH43:CL43, {6,9,12,15,18,21,24,27,30,33,36,39,42,45}, 0)))), 0)} -> 1 | DD43: =#REF! -> #REF! | DE43: =#REF!*2 -> #REF! | DF43: =#REF! -> #REF! | DG43: =#REF!*2 -> #REF! | DH43: =#REF! -> #REF! | DI43: =#REF!*2 -> #REF! | DJ43: =#REF! -> #REF! | DK43: =#REF!*2 -> #REF! | DL43: =#REF! -> #REF! | DM43: =#REF!*2 -> #REF! | DO43: {=_xlfn.IFS( OR(CH43="",ISBLANK(CH43),CH43=0),0, ISNUMBER(MATCH(CH43,{2,3,5,7,11,13,17,19,23,29,31,37,41,43},0)),"소", AND(ISNUMBER(CH43),MOD(CH43,3)=0),"배", AND(ISNUMBER(CH43),CH43>0),"자" )} -> 소 | DP43: {=_xlfn.IFS( OR(CI43="",ISBLANK(CI43),CI43=0),0, ISNUMBER(MATCH(CI43,{2,3,5,7,11,13,17,19,23,29,31,37,41,43},0)),"소", AND(ISNUMBER(CI43),MOD(CI43,3)=0),"배", AND(ISNUMBER(CI43),CI43>0),"자" )} -> 배 | DQ43: {=_xlfn.IFS( OR(CJ43="",ISBLANK(CJ43),CJ43=0),0, ISNUMBER(MATCH(CJ43,{2,3,5,7,11,13,17,19,23,29,31,37,41,43},0)),"소", AND(ISNUMBER(CJ43),MOD(CJ43,3)=0),"배", AND(ISNUMBER(CJ43),CJ43>0),"자" )} -> 소 | DR43: {=_xlfn.IFS( OR(CK43="",ISBLANK(CK43),CK43=0),0, ISNUMBER(MATCH(CK43,{2,3,5,7,11,13,17,19,23,29,31,37,41,43},0)),"소", AND(ISNUMBER(CK43),MOD(CK43,3)=0),"배", AND(ISNUMBER(CK43),CK43>0),"자" )} -> 소 | DS43: {=_xlfn.IFS( OR(CL43="",ISBLANK(CL43),CL43=0),0, ISNUMBER(MATCH(CL43,{2,3,5,7,11,13,17,19,23,29,31,37,41,43},0)),"소", AND(ISNUMBER(CL43),MOD(CL43,3)=0),"배", AND(ISNUMBER(CL43),CL43>0),"자" )} -> 자
