Workbook

Sheet 전체당첨내역
A1: 회차 | B1: 1구 | C1: 2구 | D1: 3구 | E1: 4구 | F1: 5구 | G1: 6구 | H1: 보너스
A2: 1 | B2: 10 | C2: 23 | D2: 29 | E2: 33 | F2: 37 | G2: 40 | H2: 16
A3: 2 | B3: 9 | C3: 13 | D3: 21 | E3: 25 | F3: 32 | G3: 42 | H3: 2
A4: 3 | B4: 11 | C4: 16 | D4: 19 | E4: 21 | F4: 27 | G4: 31 | H4: 30
A5: 4 | B5: 14 | C5: 27 | D5: 30 | E5: 31 | F5: 40 | G5: 42 | H5: 2
A6: 5 | B6: 16 | C6: 24 | D6: 29 | E6: 40 | F6: 41 | G6: 42 | H6: 3
A7: 6 | B7: 14 | C7: 15 | D7: 26 | E7: 27 | F7: 40 | G7: 42 | H7: 34
A8: 7 | B8: 2 | C8: 9 | D8: 16 | E8: 25 | F8: 26 | G8: 40 | H8: 42
A9: 8 | B9: 8 | C9: 19 | D9: 25 | E9: 34 | F9: 37 | G9: 39 | H9: 9
A10: 9 | B10: 2 | C10: 4 | D10: 16 | E10: 17 | F10: 36 | G10: 39 | H10: 14
A11: 10 | B11: 9 | C11: 25 | D11: 30 | E11: 33 | F11: 41 | G11: 44 | H11: 6
A12: 11 | B12: 1 | C12: 7 | D12: 36 | E12: 37 | F12: 41 | G12: 42 | H12: 14
A13: 12 | B13: 2 | C13: 11 | D13: 21 | E13: 25 | F13: 39 | G13: 45 | H13: 44
... A1244: 1243 | B1244: 9 | C1244: 18 | D1244: 24 | E1244: 38 | F1244: 43 | G1244: 44 | H1244: 35

Sheet 기준100회_후보
A1: 기준빈도 회차수(이 값만 바꾸면 전체 재계산) | B1: 100 | L1: 1 | M1: 2 | N1: 3 | O1: 4 | P1: 5 | Q1: 6 | R1: 7 | S1: 8 | T1: 9 | U1: 10 | V1: 11 | W1: 12 | X1: 13 | Y1: 14 | Z1: 15 | AA1: 16 | AB1: 17 | AC1: 18 | AD1: 19 | AE1: 20 | AF1: 21 | AG1: 22 | AH1: 23 | AI1: 24 | AJ1: 25 | AK1: 26 | AL1: 27 | AM1: 28 | AN1: 29 | AO1: 30 | AP1: 31 | AQ1: 32 | AR1: 33 | AS1: 34 | AT1: 35 | AU1: 36 | AV1: 37 | AW1: 38 | AX1: 39 | AY1: 40 | AZ1: 41 | BA1: 42 | BB1: 43 | BC1: 44 | BD1: 45
K2: ="기준빈도(최근"&$B$1&"회)" -> 기준빈도(최근100회) | L2: =SUMPRODUCT((전체당첨내역!$A$2:$A$1500>=(MAX(전체당첨내역!$A$2:$A$1500)-($B$1-1)))*((전체당첨내역!$B$2:$B$1500=L$1)+(전체당첨내역!$C$2:$C$1500=L$1)+(전체당첨내역!$D$2:$D$1500=L$1)+(전체당첨내역!$E$2:$E$1500=L$1)+(전체당첨내역!$F$2:$F$1500=L$1)+(전체당첨내역!$G$2:$G$1500=L$1))) -> 12 | M2: =SUMPRODUCT((전체당첨내역!$A$2:$A$1500>=(MAX(전체당첨내역!$A$2:$A$1500)-($B$1-1)))*((전체당첨내역!$B$2:$B$1500=M$1)+(전체당첨내역!$C$2:$C$1500=M$1)+(전체당첨내역!$D$2:$D$1500=M$1)+(전체당첨내역!$E$2:$E$1500=M$1)+(전체당첨내역!$F$2:$F$1500=M$1)+(전체당첨내역!$G$2:$G$1500=M$1))) -> 12 | N2: =SUMPRODUCT((전체당첨내역!$A$2:$A$1500>=(MAX(전체당첨내역!$A$2:$A$1500)-($B$1-1)))*((전체당첨내역!$B$2:$B$1500=N$1)+(전체당첨내역!$C$2:$C$1500=N$1)+(전체당첨내역!$D$2:$D$1500=N$1)+(전체당첨내역!$E$2:$E$1500=N$1)+(전체당첨내역!$F$2:$F$1500=N$1)+(전체당첨내역!$G$2:$G$1500=N$1))) -> 17 | O2: =SUMPRODUCT((전체당첨내역!$A$2:$A$1500>=(MAX(전체당첨내역!$A$2:$A$1500)-($B$1-1)))*((전체당첨내역!$B$2:$B$1500=O$1)+(전체당첨내역!$C$2:$C$1500=O$1)+(전체당첨내역!$D$2:$D$1500=O$1)+(전체당첨내역!$E$2:$E$1500=O$1)+(전체당첨내역!$F$2:$F$1500=O$1)+(전체당첨내역!$G$2:$G$1500=O$1))) -> 12 | P2: =SUMPRODUCT((전체당첨내역!$A$2:$A$1500>=(MAX(전체당첨내역!$A$2:$A$1500)-($B$1-1)))*((전체당첨내역!$B$2:$B$1500=P$1)+(전체당첨내역!$C$2:$C$1500=P$1)+(전체당첨내역!$D$2:$D$1500=P$1)+(전체당첨내역!$E$2:$E$1500=P$1)+(전체당첨내역!$F$2:$F$1500=P$1)+(전체당첨내역!$G$2:$G$1500=P$1))) -> 9 | Q2: =SUMPRODUCT((전체당첨내역!$A$2:$A$1500>=(MAX(전체당첨내역!$A$2:$A$1500)-($B$1-1)))*((전체당첨내역!$B$2:$B$1500=Q$1)+(전체당첨내역!$C$2:$C$1500=Q$1)+(전체당첨내역!$D$2:$D$1500=Q$1)+(전체당첨내역!$E$2:$E$1500=Q$1)+(전체당첨내역!$F$2:$F$1500=Q$1)+(전체당첨내역!$G$2:$G$1500=Q$1))) -> 14 | R2: =SUMPRODUCT((전체당첨내역!$A$2:$A$1500>=(MAX(전체당첨내역!$A$2:$A$1500)-($B$1-1)))*((전체당첨내역!$B$2:$B$1500=R$1)+(전체당첨내역!$C$2:$C$1500=R$1)+(전체당첨내역!$D$2:$D$1500=R$1)+(전체당첨내역!$E$2:$E$1500=R$1)+(전체당첨내역!$F$2:$F$1500=R$1)+(전체당첨내역!$G$2:$G$1500=R$1))) -> 15 | S2: =SUMPRODUCT((전체당첨내역!$A$2:$A$1500>=(MAX(전체당첨내역!$A$2:$A$1500)-($B$1-1)))*((전체당첨내역!$B$2:$B$1500=S$1)+(전체당첨내역!$C$2:$C$1500=S$1)+(전체당첨내역!$D$2:$D$1500=S$1)+(전체당첨내역!$E$2:$E$1500=S$1)+(전체당첨내역!$F$2:$F$1500=S$1)+(전체당첨내역!$G$2:$G$1500=S$1))) -> 14 | ... BD2: =SUMPRODUCT((전체당첨내역!$A$2:$A$1500>=(MAX(전체당첨내역!$A$2:$A$1500)-($B$1-1)))*((전체당첨내역!$B$2:$B$1500=BD$1)+(전체당첨내역!$C$2:$C$1500=BD$1)+(전체당첨내역!$D$2:$D$1500=BD$1)+(전체당첨내역!$E$2:$E$1500=BD$1)+(전체당첨내역!$F$2:$F$1500=BD$1)+(전체당첨내역!$G$2:$G$1500=BD$1))) -> 11
A3: 순위 | B3: 후보숫자 | K3: 최근50회 빈도(고정) | L3: =SUMPRODUCT((전체당첨내역!$A$2:$A$1500>=(MAX(전체당첨내역!$A$2:$A$1500)-49))*((전체당첨내역!$B$2:$B$1500=L$1)+(전체당첨내역!$C$2:$C$1500=L$1)+(전체당첨내역!$D$2:$D$1500=L$1)+(전체당첨내역!$E$2:$E$1500=L$1)+(전체당첨내역!$F$2:$F$1500=L$1)+(전체당첨내역!$G$2:$G$1500=L$1))) -> 8 | M3: =SUMPRODUCT((전체당첨내역!$A$2:$A$1500>=(MAX(전체당첨내역!$A$2:$A$1500)-49))*((전체당첨내역!$B$2:$B$1500=M$1)+(전체당첨내역!$C$2:$C$1500=M$1)+(전체당첨내역!$D$2:$D$1500=M$1)+(전체당첨내역!$E$2:$E$1500=M$1)+(전체당첨내역!$F$2:$F$1500=M$1)+(전체당첨내역!$G$2:$G$1500=M$1))) -> 7 | N3: =SUMPRODUCT((전체당첨내역!$A$2:$A$1500>=(MAX(전체당첨내역!$A$2:$A$1500)-49))*((전체당첨내역!$B$2:$B$1500=N$1)+(전체당첨내역!$C$2:$C$1500=N$1)+(전체당첨내역!$D$2:$D$1500=N$1)+(전체당첨내역!$E$2:$E$1500=N$1)+(전체당첨내역!$F$2:$F$1500=N$1)+(전체당첨내역!$G$2:$G$1500=N$1))) -> 7 | O3: =SUMPRODUCT((전체당첨내역!$A$2:$A$1500>=(MAX(전체당첨내역!$A$2:$A$1500)-49))*((전체당첨내역!$B$2:$B$1500=O$1)+(전체당첨내역!$C$2:$C$1500=O$1)+(전체당첨내역!$D$2:$D$1500=O$1)+(전체당첨내역!$E$2:$E$1500=O$1)+(전체당첨내역!$F$2:$F$1500=O$1)+(전체당첨내역!$G$2:$G$1500=O$1))) -> 6 | P3: =SUMPRODUCT((전체당첨내역!$A$2:$A$1500>=(MAX(전체당첨내역!$A$2:$A$1500)-49))*((전체당첨내역!$B$2:$B$1500=P$1)+(전체당첨내역!$C$2:$C$1500=P$1)+(전체당첨내역!$D$2:$D$1500=P$1)+(전체당첨내역!$E$2:$E$1500=P$1)+(전체당첨내역!$F$2:$F$1500=P$1)+(전체당첨내역!$G$2:$G$1500=P$1))) -> 4 | Q3: =SUMPRODUCT((전체당첨내역!$A$2:$A$1500>=(MAX(전체당첨내역!$A$2:$A$1500)-49))*((전체당첨내역!$B$2:$B$1500=Q$1)+(전체당첨내역!$C$2:$C$1500=Q$1)+(전체당첨내역!$D$2:$D$1500=Q$1)+(전체당첨내역!$E$2:$E$1500=Q$1)+(전체당첨내역!$F$2:$F$1500=Q$1)+(전체당첨내역!$G$2:$G$1500=Q$1))) -> 5 | R3: =SUMPRODUCT((전체당첨내역!$A$2:$A$1500>=(MAX(전체당첨내역!$A$2:$A$1500)-49))*((전체당첨내역!$B$2:$B$1500=R$1)+(전체당첨내역!$C$2:$C$1500=R$1)+(전체당첨내역!$D$2:$D$1500=R$1)+(전체당첨내역!$E$2:$E$1500=R$1)+(전체당첨내역!$F$2:$F$1500=R$1)+(전체당첨내역!$G$2:$G$1500=R$1))) -> 6 | S3: =SUMPRODUCT((전체당첨내역!$A$2:$A$1500>=(MAX(전체당첨내역!$A$2:$A$1500)-49))*((전체당첨내역!$B$2:$B$1500=S$1)+(전체당첨내역!$C$2:$C$1500=S$1)+(전체당첨내역!$D$2:$D$1500=S$1)+(전체당첨내역!$E$2:$E$1500=S$1)+(전체당첨내역!$F$2:$F$1500=S$1)+(전체당첨내역!$G$2:$G$1500=S$1))) -> 6 | ... BD3: =SUMPRODUCT((전체당첨내역!$A$2:$A$1500>=(MAX(전체당첨내역!$A$2:$A$1500)-49))*((전체당첨내역!$B$2:$B$1500=BD$1)+(전체당첨내역!$C$2:$C$1500=BD$1)+(전체당첨내역!$D$2:$D$1500=BD$1)+(전체당첨내역!$E$2:$E$1500=BD$1)+(전체당첨내역!$F$2:$F$1500=BD$1)+(전체당첨내역!$G$2:$G$1500=BD$1))) -> 6
A4: 1 | B4: =INDEX($L$1:$BD$1,MATCH(A4,$L$5:$BD$5,0)) -> 6 | K4: 오차(출현임박) | L4: =(RANK(L$3,$L$3:$BD$3,0)+COUNTIFS($L$3:$BD$3,L$3,$L$1:$BD$1,"<"&L$1))-(RANK(L$2,$L$2:$BD$2,0)+COUNTIFS($L$2:$BD$2,L$2,$L$1:$BD$1,"<"&L$1)) -> -22 | M4: =(RANK(M$3,$L$3:$BD$3,0)+COUNTIFS($L$3:$BD$3,M$3,$L$1:$BD$1,"<"&M$1))-(RANK(M$2,$L$2:$BD$2,0)+COUNTIFS($L$2:$BD$2,M$2,$L$1:$BD$1,"<"&M$1)) -> -18 | N4: =(RANK(N$3,$L$3:$BD$3,0)+COUNTIFS($L$3:$BD$3,N$3,$L$1:$BD$1,"<"&N$1))-(RANK(N$2,$L$2:$BD$2,0)+COUNTIFS($L$2:$BD$2,N$2,$L$1:$BD$1,"<"&N$1)) -> 8 | O4: =(RANK(O$3,$L$3:$BD$3,0)+COUNTIFS($L$3:$BD$3,O$3,$L$1:$BD$1,"<"&O$1))-(RANK(O$2,$L$2:$BD$2,0)+COUNTIFS($L$2:$BD$2,O$2,$L$1:$BD$1,"<"&O$1)) -> -10 | P4: =(RANK(P$3,$L$3:$BD$3,0)+COUNTIFS($L$3:$BD$3,P$3,$L$1:$BD$1,"<"&P$1))-(RANK(P$2,$L$2:$BD$2,0)+COUNTIFS($L$2:$BD$2,P$2,$L$1:$BD$1,"<"&P$1)) -> -1 | Q4: =(RANK(Q$3,$L$3:$BD$3,0)+COUNTIFS($L$3:$BD$3,Q$3,$L$1:$BD$1,"<"&Q$1))-(RANK(Q$2,$L$2:$BD$2,0)+COUNTIFS($L$2:$BD$2,Q$2,$L$1:$BD$1,"<"&Q$1)) -> 22 | R4: =(RANK(R$3,$L$3:$BD$3,0)+COUNTIFS($L$3:$BD$3,R$3,$L$1:$BD$1,"<"&R$1))-(RANK(R$2,$L$2:$BD$2,0)+COUNTIFS($L$2:$BD$2,R$2,$L$1:$BD$1,"<"&R$1)) -> 11 | S4: =(RANK(S$3,$L$3:$BD$3,0)+COUNTIFS($L$3:$BD$3,S$3,$L$1:$BD$1,"<"&S$1))-(RANK(S$2,$L$2:$BD$2,0)+COUNTIFS($L$2:$BD$2,S$2,$L$1:$BD$1,"<"&S$1)) -> 8 | ... BD4: =(RANK(BD$3,$L$3:$BD$3,0)+COUNTIFS($L$3:$BD$3,BD$3,$L$1:$BD$1,"<"&BD$1))-(RANK(BD$2,$L$2:$BD$2,0)+COUNTIFS($L$2:$BD$2,BD$2,$L$1:$BD$1,"<"&BD$1)) -> -4
A5: 2 | B5: =INDEX($L$1:$BD$1,MATCH(A5,$L$5:$BD$5,0)) -> 37 | K5: 순위(1~45) | L5: =RANK(L4,$L$4:$BD$4,0)+COUNTIFS($L$4:$BD$4,L4,$L$1:$BD$1,"<"&L$1) -> 45 | M5: =RANK(M4,$L$4:$BD$4,0)+COUNTIFS($L$4:$BD$4,M4,$L$1:$BD$1,"<"&M$1) -> 41 | N5: =RANK(N4,$L$4:$BD$4,0)+COUNTIFS($L$4:$BD$4,N4,$L$1:$BD$1,"<"&N$1) -> 11 | O5: =RANK(O4,$L$4:$BD$4,0)+COUNTIFS($L$4:$BD$4,O4,$L$1:$BD$1,"<"&O$1) -> 37 | P5: =RANK(P4,$L$4:$BD$4,0)+COUNTIFS($L$4:$BD$4,P4,$L$1:$BD$1,"<"&P$1) -> 24 | Q5: =RANK(Q4,$L$4:$BD$4,0)+COUNTIFS($L$4:$BD$4,Q4,$L$1:$BD$1,"<"&Q$1) -> 1 | R5: =RANK(R4,$L$4:$BD$4,0)+COUNTIFS($L$4:$BD$4,R4,$L$1:$BD$1,"<"&R$1) -> 8 | S5: =RANK(S4,$L$4:$BD$4,0)+COUNTIFS($L$4:$BD$4,S4,$L$1:$BD$1,"<"&S$1) -> 12 | ... BD5: =RANK(BD4,$L$4:$BD$4,0)+COUNTIFS($L$4:$BD$4,BD4,$L$1:$BD$1,"<"&BD$1) -> 28
A6: 3 | B6: =INDEX($L$1:$BD$1,MATCH(A6,$L$5:$BD$5,0)) -> 39 | K6: 적중회수(현재순위 기준, 최근50회 실적) | L6: =SUMPRODUCT(($L$13:$L$62=$B$13:$B$62)+($L$13:$L$62=$C$13:$C$62)+($L$13:$L$62=$D$13:$D$62)+($L$13:$L$62=$E$13:$E$62)+($L$13:$L$62=$F$13:$F$62)+($L$13:$L$62=$G$13:$G$62)) -> 7 | M6: =SUMPRODUCT(($M$13:$M$62=$B$13:$B$62)+($M$13:$M$62=$C$13:$C$62)+($M$13:$M$62=$D$13:$D$62)+($M$13:$M$62=$E$13:$E$62)+($M$13:$M$62=$F$13:$F$62)+($M$13:$M$62=$G$13:$G$62)) -> 9 | N6: =SUMPRODUCT(($N$13:$N$62=$B$13:$B$62)+($N$13:$N$62=$C$13:$C$62)+($N$13:$N$62=$D$13:$D$62)+($N$13:$N$62=$E$13:$E$62)+($N$13:$N$62=$F$13:$F$62)+($N$13:$N$62=$G$13:$G$62)) -> 6 | O6: =SUMPRODUCT(($O$13:$O$62=$B$13:$B$62)+($O$13:$O$62=$C$13:$C$62)+($O$13:$O$62=$D$13:$D$62)+($O$13:$O$62=$E$13:$E$62)+($O$13:$O$62=$F$13:$F$62)+($O$13:$O$62=$G$13:$G$62)) -> 8 | P6: =SUMPRODUCT(($P$13:$P$62=$B$13:$B$62)+($P$13:$P$62=$C$13:$C$62)+($P$13:$P$62=$D$13:$D$62)+($P$13:$P$62=$E$13:$E$62)+($P$13:$P$62=$F$13:$F$62)+($P$13:$P$62=$G$13:$G$62)) -> 7 | Q6: =SUMPRODUCT(($Q$13:$Q$62=$B$13:$B$62)+($Q$13:$Q$62=$C$13:$C$62)+($Q$13:$Q$62=$D$13:$D$62)+($Q$13:$Q$62=$E$13:$E$62)+($Q$13:$Q$62=$F$13:$F$62)+($Q$13:$Q$62=$G$13:$G$62)) -> 8 | R6: =SUMPRODUCT(($R$13:$R$62=$B$13:$B$62)+($R$13:$R$62=$C$13:$C$62)+($R$13:$R$62=$D$13:$D$62)+($R$13:$R$62=$E$13:$E$62)+($R$13:$R$62=$F$13:$F$62)+($R$13:$R$62=$G$13:$G$62)) -> 3 | S6: =SUMPRODUCT(($S$13:$S$62=$B$13:$B$62)+($S$13:$S$62=$C$13:$C$62)+($S$13:$S$62=$D$13:$D$62)+($S$13:$S$62=$E$13:$E$62)+($S$13:$S$62=$F$13:$F$62)+($S$13:$S$62=$G$13:$G$62)) -> 5 | T6: =SUMPRODUCT(($T$13:$T$62=$B$13:$B$62)+($T$13:$T$62=$C$13:$C$62)+($T$13:$T$62=$D$13:$D$62)+($T$13:$T$62=$E$13:$E$62)+($T$13:$T$62=$F$13:$F$62)+($T$13:$T$62=$G$13:$G$62)) -> 7 | U6: =SUMPRODUCT(($U$13:$U$62=$B$13:$B$62)+($U$13:$U$62=$C$13:$C$62)+($U$13:$U$62=$D$13:$D$62)+($U$13:$U$62=$E$13:$E$62)+($U$13:$U$62=$F$13:$F$62)+($U$13:$U$62=$G$13:$G$62)) -> 7 | V6: =SUMPRODUCT(($V$13:$V$62=$B$13:$B$62)+($V$13:$V$62=$C$13:$C$62)+($V$13:$V$62=$D$13:$D$62)+($V$13:$V$62=$E$13:$E$62)+($V$13:$V$62=$F$13:$F$62)+($V$13:$V$62=$G$13:$G$62)) -> 8 | W6: =SUMPRODUCT(($W$13:$W$62=$B$13:$B$62)+($W$13:$W$62=$C$13:$C$62)+($W$13:$W$62=$D$13:$D$62)+($W$13:$W$62=$E$13:$E$62)+($W$13:$W$62=$F$13:$F$62)+($W$13:$W$62=$G$13:$G$62)) -> 7 | X6: =SUMPRODUCT(($X$13:$X$62=$B$13:$B$62)+($X$13:$X$62=$C$13:$C$62)+($X$13:$X$62=$D$13:$D$62)+($X$13:$X$62=$E$13:$E$62)+($X$13:$X$62=$F$13:$F$62)+($X$13:$X$62=$G$13:$G$62)) -> 7 | Y6: =SUMPRODUCT(($Y$13:$Y$62=$B$13:$B$62)+($Y$13:$Y$62=$C$13:$C$62)+($Y$13:$Y$62=$D$13:$D$62)+($Y$13:$Y$62=$E$13:$E$62)+($Y$13:$Y$62=$F$13:$F$62)+($Y$13:$Y$62=$G$13:$G$62)) -> 8 | Z6: =SUMPRODUCT(($Z$13:$Z$62=$B$13:$B$62)+($Z$13:$Z$62=$C$13:$C$62)+($Z$13:$Z$62=$D$13:$D$62)+($Z$13:$Z$62=$E$13:$E$62)+($Z$13:$Z$62=$F$13:$F$62)+($Z$13:$Z$62=$G$13:$G$62)) -> 7 | AA6: =SUMPRODUCT(($AA$13:$AA$62=$B$13:$B$62)+($AA$13:$AA$62=$C$13:$C$62)+($AA$13:$AA$62=$D$13:$D$62)+($AA$13:$AA$62=$E$13:$E$62)+($AA$13:$AA$62=$F$13:$F$62)+($AA$13:$AA$62=$G$13:$G$62)) -> 9 | AB6: =SUMPRODUCT(($AB$13:$AB$62=$B$13:$B$62)+($AB$13:$AB$62=$C$13:$C$62)+($AB$13:$AB$62=$D$13:$D$62)+($AB$13:$AB$62=$E$13:$E$62)+($AB$13:$AB$62=$F$13:$F$62)+($AB$13:$AB$62=$G$13:$G$62)) -> 9 | AC6: =SUMPRODUCT(($AC$13:$AC$62=$B$13:$B$62)+($AC$13:$AC$62=$C$13:$C$62)+($AC$13:$AC$62=$D$13:$D$62)+($AC$13:$AC$62=$E$13:$E$62)+($AC$13:$AC$62=$F$13:$F$62)+($AC$13:$AC$62=$G$13:$G$62)) -> 7 | AD6: =SUMPRODUCT(($AD$13:$AD$62=$B$13:$B$62)+($AD$13:$AD$62=$C$13:$C$62)+($AD$13:$AD$62=$D$13:$D$62)+($AD$13:$AD$62=$E$13:$E$62)+($AD$13:$AD$62=$F$13:$F$62)+($AD$13:$AD$62=$G$13:$G$62)) -> 5 | AE6: =SUMPRODUCT(($AE$13:$AE$62=$B$13:$B$62)+($AE$13:$AE$62=$C$13:$C$62)+($AE$13:$AE$62=$D$13:$D$62)+($AE$13:$AE$62=$E$13:$E$62)+($AE$13:$AE$62=$F$13:$F$62)+($AE$13:$AE$62=$G$13:$G$62)) -> 7 | AF6: =SUMPRODUCT(($AF$13:$AF$62=$B$13:$B$62)+($AF$13:$AF$62=$C$13:$C$62)+($AF$13:$AF$62=$D$13:$D$62)+($AF$13:$AF$62=$E$13:$E$62)+($AF$13:$AF$62=$F$13:$F$62)+($AF$13:$AF$62=$G$13:$G$62)) -> 8 | AG6: =SUMPRODUCT(($AG$13:$AG$62=$B$13:$B$62)+($AG$13:$AG$62=$C$13:$C$62)+($AG$13:$AG$62=$D$13:$D$62)+($AG$13:$AG$62=$E$13:$E$62)+($AG$13:$AG$62=$F$13:$F$62)+($AG$13:$AG$62=$G$13:$G$62)) -> 12 | AH6: =SUMPRODUCT(($AH$13:$AH$62=$B$13:$B$62)+($AH$13:$AH$62=$C$13:$C$62)+($AH$13:$AH$62=$D$13:$D$62)+($AH$13:$AH$62=$E$13:$E$62)+($AH$13:$AH$62=$F$13:$F$62)+($AH$13:$AH$62=$G$13:$G$62)) -> 6 | AI6: =SUMPRODUCT(($AI$13:$AI$62=$B$13:$B$62)+($AI$13:$AI$62=$C$13:$C$62)+($AI$13:$AI$62=$D$13:$D$62)+($AI$13:$AI$62=$E$13:$E$62)+($AI$13:$AI$62=$F$13:$F$62)+($AI$13:$AI$62=$G$13:$G$62)) -> 8 | AJ6: =SUMPRODUCT(($AJ$13:$AJ$62=$B$13:$B$62)+($AJ$13:$AJ$62=$C$13:$C$62)+($AJ$13:$AJ$62=$D$13:$D$62)+($AJ$13:$AJ$62=$E$13:$E$62)+($AJ$13:$AJ$62=$F$13:$F$62)+($AJ$13:$AJ$62=$G$13:$G$62)) -> 6 | AK6: =SUMPRODUCT(($AK$13:$AK$62=$B$13:$B$62)+($AK$13:$AK$62=$C$13:$C$62)+($AK$13:$AK$62=$D$13:$D$62)+($AK$13:$AK$62=$E$13:$E$62)+($AK$13:$AK$62=$F$13:$F$62)+($AK$13:$AK$62=$G$13:$G$62)) -> 8 | AL6: =SUMPRODUCT(($AL$13:$AL$62=$B$13:$B$62)+($AL$13:$AL$62=$C$13:$C$62)+($AL$13:$AL$62=$D$13:$D$62)+($AL$13:$AL$62=$E$13:$E$62)+($AL$13:$AL$62=$F$13:$F$62)+($AL$13:$AL$62=$G$13:$G$62)) -> 7 | AM6: =SUMPRODUCT(($AM$13:$AM$62=$B$13:$B$62)+($AM$13:$AM$62=$C$13:$C$62)+($AM$13:$AM$62=$D$13:$D$62)+($AM$13:$AM$62=$E$13:$E$62)+($AM$13:$AM$62=$F$13:$F$62)+($AM$13:$AM$62=$G$13:$G$62)) -> 4 | AN6: =SUMPRODUCT(($AN$13:$AN$62=$B$13:$B$62)+($AN$13:$AN$62=$C$13:$C$62)+($AN$13:$AN$62=$D$13:$D$62)+($AN$13:$AN$62=$E$13:$E$62)+($AN$13:$AN$62=$F$13:$F$62)+($AN$13:$AN$62=$G$13:$G$62)) -> 8 | AO6: =SUMPRODUCT(($AO$13:$AO$62=$B$13:$B$62)+($AO$13:$AO$62=$C$13:$C$62)+($AO$13:$AO$62=$D$13:$D$62)+($AO$13:$AO$62=$E$13:$E$62)+($AO$13:$AO$62=$F$13:$F$62)+($AO$13:$AO$62=$G$13:$G$62)) -> 8 | AP6: =SUMPRODUCT(($AP$13:$AP$62=$B$13:$B$62)+($AP$13:$AP$62=$C$13:$C$62)+($AP$13:$AP$62=$D$13:$D$62)+($AP$13:$AP$62=$E$13:$E$62)+($AP$13:$AP$62=$F$13:$F$62)+($AP$13:$AP$62=$G$13:$G$62)) -> 5 | AQ6: =SUMPRODUCT(($AQ$13:$AQ$62=$B$13:$B$62)+($AQ$13:$AQ$62=$C$13:$C$62)+($AQ$13:$AQ$62=$D$13:$D$62)+($AQ$13:$AQ$62=$E$13:$E$62)+($AQ$13:$AQ$62=$F$13:$F$62)+($AQ$13:$AQ$62=$G$13:$G$62)) -> 6 | AR6: =SUMPRODUCT(($AR$13:$AR$62=$B$13:$B$62)+($AR$13:$AR$62=$C$13:$C$62)+($AR$13:$AR$62=$D$13:$D$62)+($AR$13:$AR$62=$E$13:$E$62)+($AR$13:$AR$62=$F$13:$F$62)+($AR$13:$AR$62=$G$13:$G$62)) -> 6 | AS6: =SUMPRODUCT(($AS$13:$AS$62=$B$13:$B$62)+($AS$13:$AS$62=$C$13:$C$62)+($AS$13:$AS$62=$D$13:$D$62)+($AS$13:$AS$62=$E$13:$E$62)+($AS$13:$AS$62=$F$13:$F$62)+($AS$13:$AS$62=$G$13:$G$62)) -> 4 | AT6: =SUMPRODUCT(($AT$13:$AT$62=$B$13:$B$62)+($AT$13:$AT$62=$C$13:$C$62)+($AT$13:$AT$62=$D$13:$D$62)+($AT$13:$AT$62=$E$13:$E$62)+($AT$13:$AT$62=$F$13:$F$62)+($AT$13:$AT$62=$G$13:$G$62)) -> 6 | AU6: =SUMPRODUCT(($AU$13:$AU$62=$B$13:$B$62)+($AU$13:$AU$62=$C$13:$C$62)+($AU$13:$AU$62=$D$13:$D$62)+($AU$13:$AU$62=$E$13:$E$62)+($AU$13:$AU$62=$F$13:$F$62)+($AU$13:$AU$62=$G$13:$G$62)) -> 7 | AV6: =SUMPRODUCT(($AV$13:$AV$62=$B$13:$B$62)+($AV$13:$AV$62=$C$13:$C$62)+($AV$13:$AV$62=$D$13:$D$62)+($AV$13:$AV$62=$E$13:$E$62)+($AV$13:$AV$62=$F$13:$F$62)+($AV$13:$AV$62=$G$13:$G$62)) -> 7 | AW6: =SUMPRODUCT(($AW$13:$AW$62=$B$13:$B$62)+($AW$13:$AW$62=$C$13:$C$62)+($AW$13:$AW$62=$D$13:$D$62)+($AW$13:$AW$62=$E$13:$E$62)+($AW$13:$AW$62=$F$13:$F$62)+($AW$13:$AW$62=$G$13:$G$62)) -> 11 | AX6: =SUMPRODUCT(($AX$13:$AX$62=$B$13:$B$62)+($AX$13:$AX$62=$C$13:$C$62)+($AX$13:$AX$62=$D$13:$D$62)+($AX$13:$AX$62=$E$13:$E$62)+($AX$13:$AX$62=$F$13:$F$62)+($AX$13:$AX$62=$G$13:$G$62)) -> 1 | AY6: =SUMPRODUCT(($AY$13:$AY$62=$B$13:$B$62)+($AY$13:$AY$62=$C$13:$C$62)+($AY$13:$AY$62=$D$13:$D$62)+($AY$13:$AY$62=$E$13:$E$62)+($AY$13:$AY$62=$F$13:$F$62)+($AY$13:$AY$62=$G$13:$G$62)) -> 5 | AZ6: =SUMPRODUCT(($AZ$13:$AZ$62=$B$13:$B$62)+($AZ$13:$AZ$62=$C$13:$C$62)+($AZ$13:$AZ$62=$D$13:$D$62)+($AZ$13:$AZ$62=$E$13:$E$62)+($AZ$13:$AZ$62=$F$13:$F$62)+($AZ$13:$AZ$62=$G$13:$G$62)) -> 4 | BA6: =SUMPRODUCT(($BA$13:$BA$62=$B$13:$B$62)+($BA$13:$BA$62=$C$13:$C$62)+($BA$13:$BA$62=$D$13:$D$62)+($BA$13:$BA$62=$E$13:$E$62)+($BA$13:$BA$62=$F$13:$F$62)+($BA$13:$BA$62=$G$13:$G$62)) -> 8 | BB6: =SUMPRODUCT(($BB$13:$BB$62=$B$13:$B$62)+($BB$13:$BB$62=$C$13:$C$62)+($BB$13:$BB$62=$D$13:$D$62)+($BB$13:$BB$62=$E$13:$E$62)+($BB$13:$BB$62=$F$13:$F$62)+($BB$13:$BB$62=$G$13:$G$62)) -> 6 | BC6: =SUMPRODUCT(($BC$13:$BC$62=$B$13:$B$62)+($BC$13:$BC$62=$C$13:$C$62)+($BC$13:$BC$62=$D$13:$D$62)+($BC$13:$BC$62=$E$13:$E$62)+($BC$13:$BC$62=$F$13:$F$62)+($BC$13:$BC$62=$G$13:$G$62)) -> 4 | BD6: =SUMPRODUCT(($BD$13:$BD$62=$B$13:$B$62)+($BD$13:$BD$62=$C$13:$C$62)+($BD$13:$BD$62=$D$13:$D$62)+($BD$13:$BD$62=$E$13:$E$62)+($BD$13:$BD$62=$F$13:$F$62)+($BD$13:$BD$62=$G$13:$G$62)) -> 4
A7: 4 | B7: =INDEX($L$1:$BD$1,MATCH(A7,$L$5:$BD$5,0)) -> 11
A8: 5 | B8: =INDEX($L$1:$BD$1,MATCH(A8,$L$5:$BD$5,0)) -> 12
A9: ▼ 회차별 후보숫자 순위표 (자동 재계산 — B1 변경 시 전체 회차 재계산됨)
A10: 회차 | B10: 1구 | C10: 2구 | D10: 3구 | E10: 4구 | F10: 5구 | G10: 6구 | H10: 보너스 | L10: 상위(1~15위) | AA10: 중위(16~30위) | AP10: 하위(31~45위)
A11: 회차 | B11: 1구 | C11: 2구 | D11: 3구 | E11: 4구 | F11: 5구 | G11: 6구 | H11: 보너스 | I11: 상위 | J11: 중위 | K11: 하위 | L11: 1 | M11: 2 | N11: 3 | O11: 4 | P11: 5 | Q11: 6 | R11: 7 | S11: 8 | T11: 9 | U11: 10 | V11: 11 | W11: 12 | X11: 13 | Y11: 14 | Z11: 15 | AA11: 16 | AB11: 17 | AC11: 18 | AD11: 19 | AE11: 20 | AF11: 21 | AG11: 22 | AH11: 23 | AI11: 24 | AJ11: 25 | AK11: 26 | AL11: 27 | AM11: 28 | AN11: 29 | AO11: 30 | AP11: 31 | AQ11: 32 | AR11: 33 | AS11: 34 | AT11: 35 | AU11: 36 | AV11: 37 | AW11: 38 | AX11: 39 | AY11: 40 | AZ11: 41 | BA11: 42 | BB11: 43 | BC11: 44 | BD11: 45
A12: =MAX(전체당첨내역!$A$2:$A$1500)+1 -> 1244 | B12: =IFERROR(INDEX(전체당첨내역!$B:$B,MATCH($A12,전체당첨내역!$A:$A,0)),"") | C12: =IFERROR(INDEX(전체당첨내역!$C:$C,MATCH($A12,전체당첨내역!$A:$A,0)),"") | D12: =IFERROR(INDEX(전체당첨내역!$D:$D,MATCH($A12,전체당첨내역!$A:$A,0)),"") | E12: =IFERROR(INDEX(전체당첨내역!$E:$E,MATCH($A12,전체당첨내역!$A:$A,0)),"") | F12: =IFERROR(INDEX(전체당첨내역!$F:$F,MATCH($A12,전체당첨내역!$A:$A,0)),"") | G12: =IFERROR(INDEX(전체당첨내역!$G:$G,MATCH($A12,전체당첨내역!$A:$A,0)),"") | H12: =IFERROR(INDEX(전체당첨내역!$H:$H,MATCH($A12,전체당첨내역!$A:$A,0)),"") | I12: =IFERROR((INDEX(_calc_기준100!$CN$2:$EF$2,1,$B12)>0)*(INDEX(_calc_기준100!$CN$2:$EF$2,1,$B12)<=15)+(INDEX(_calc_기준100!$CN$2:$EF$2,1,$C12)>0)*(INDEX(_calc_기준100!$CN$2:$EF$2,1,$C12)<=15)+(INDEX(_calc_기준100!$CN$2:$EF$2,1,$D12)>0)*(INDEX(_calc_기준100!$CN$2:$EF$2,1,$D12)<=15)+(INDEX(_calc_기준100!$CN$2:$EF$2,1,$E12)>0)*(INDEX(_calc_기준100!$CN$2:$EF$2,1,$E12)<=15)+(INDEX(_calc_기준100!$CN$2:$EF$2,1,$F12)>0)*(INDEX(_calc_기준100!$CN$2:$EF$2,1,$F12)<=15)+(INDEX(_calc_기준100!$CN$2:$EF$2,1,$G12)>0)*(INDEX(_calc_기준100!$CN$2:$EF$2,1,$G12)<=15),"") | J12: =IFERROR((INDEX(_calc_기준100!$CN$2:$EF$2,1,$B12)>15)*(INDEX(_calc_기준100!$CN$2:$EF$2,1,$B12)<=30)+(INDEX(_calc_기준100!$CN$2:$EF$2,1,$C12)>15)*(INDEX(_calc_기준100!$CN$2:$EF$2,1,$C12)<=30)+(INDEX(_calc_기준100!$CN$2:$EF$2,1,$D12)>15)*(INDEX(_calc_기준100!$CN$2:$EF$2,1,$D12)<=30)+(INDEX(_calc_기준100!$CN$2:$EF$2,1,$E12)>15)*(INDEX(_calc_기준100!$CN$2:$EF$2,1,$E12)<=30)+(INDEX(_calc_기준100!$CN$2:$EF$2,1,$F12)>15)*(INDEX(_calc_기준100!$CN$2:$EF$2,1,$F12)<=30)+(INDEX(_calc_기준100!$CN$2:$EF$2,1,$G12)>15)*(INDEX(_calc_기준100!$CN$2:$EF$2,1,$G12)<=30),"") | K12: =IFERROR((INDEX(_calc_기준100!$CN$2:$EF$2,1,$B12)>30)+(INDEX(_calc_기준100!$CN$2:$EF$2,1,$C12)>30)+(INDEX(_calc_기준100!$CN$2:$EF$2,1,$D12)>30)+(INDEX(_calc_기준100!$CN$2:$EF$2,1,$E12)>30)+(INDEX(_calc_기준100!$CN$2:$EF$2,1,$F12)>30)+(INDEX(_calc_기준100!$CN$2:$EF$2,1,$G12)>30),"") | L12: =IFERROR(MATCH(L$11,_calc_기준100!$CN$2:$EF$2,0),"") -> 6 | M12: =IFERROR(MATCH(M$11,_calc_기준100!$CN$2:$EF$2,0),"") -> 37 | N12: =IFERROR(MATCH(N$11,_calc_기준100!$CN$2:$EF$2,0),"") -> 39 | O12: =IFERROR(MATCH(O$11,_calc_기준100!$CN$2:$EF$2,0),"") -> 11 | P12: =IFERROR(MATCH(P$11,_calc_기준100!$CN$2:$EF$2,0),"") -> 12 | Q12: =IFERROR(MATCH(Q$11,_calc_기준100!$CN$2:$EF$2,0),"") -> 23 | R12: =IFERROR(MATCH(R$11,_calc_기준100!$CN$2:$EF$2,0),"") -> 9 | S12: =IFERROR(MATCH(S$11,_calc_기준100!$CN$2:$EF$2,0),"") -> 7 | ... BD12: =IFERROR(MATCH(BD$11,_calc_기준100!$CN$2:$EF$2,0),"") -> 1
A13: =MAX(전체당첨내역!$A$2:$A$1500) -> 1243 | B13: =IFERROR(INDEX(전체당첨내역!$B:$B,MATCH($A13,전체당첨내역!$A:$A,0)),"") -> 9 | C13: =IFERROR(INDEX(전체당첨내역!$C:$C,MATCH($A13,전체당첨내역!$A:$A,0)),"") -> 18 | D13: =IFERROR(INDEX(전체당첨내역!$D:$D,MATCH($A13,전체당첨내역!$A:$A,0)),"") -> 24 | E13: =IFERROR(INDEX(전체당첨내역!$E:$E,MATCH($A13,전체당첨내역!$A:$A,0)),"") -> 38 | F13: =IFERROR(INDEX(전체당첨내역!$F:$F,MATCH($A13,전체당첨내역!$A:$A,0)),"") -> 43 | G13: =IFERROR(INDEX(전체당첨내역!$G:$G,MATCH($A13,전체당첨내역!$A:$A,0)),"") -> 44 | H13: =IFERROR(INDEX(전체당첨내역!$H:$H,MATCH($A13,전체당첨내역!$A:$A,0)),"") -> 35 | I13: =IFERROR((INDEX(_calc_기준100!$CN$3:$EF$3,1,$B13)>0)*(INDEX(_calc_기준100!$CN$3:$EF$3,1,$B13)<=15)+(INDEX(_calc_기준100!$CN$3:$EF$3,1,$C13)>0)*(INDEX(_calc_기준100!$CN$3:$EF$3,1,$C13)<=15)+(INDEX(_calc_기준100!$CN$3:$EF$3,1,$D13)>0)*(INDEX(_calc_기준100!$CN$3:$EF$3,1,$D13)<=15)+(INDEX(_calc_기준100!$CN$3:$EF$3,1,$E13)>0)*(INDEX(_calc_기준100!$CN$3:$EF$3,1,$E13)<=15)+(INDEX(_calc_기준100!$CN$3:$EF$3,1,$F13)>0)*(INDEX(_calc_기준100!$CN$3:$EF$3,1,$F13)<=15)+(INDEX(_calc_기준100!$CN$3:$EF$3,1,$G13)>0)*(INDEX(_calc_기준100!$CN$3:$EF$3,1,$G13)<=15),"") -> 1 | J13: =IFERROR((INDEX(_calc_기준100!$CN$3:$EF$3,1,$B13)>15)*(INDEX(_calc_기준100!$CN$3:$EF$3,1,$B13)<=30)+(INDEX(_calc_기준100!$CN$3:$EF$3,1,$C13)>15)*(INDEX(_calc_기준100!$CN$3:$EF$3,1,$C13)<=30)+(INDEX(_calc_기준100!$CN$3:$EF$3,1,$D13)>15)*(INDEX(_calc_기준100!$CN$3:$EF$3,1,$D13)<=30)+(INDEX(_calc_기준100!$CN$3:$EF$3,1,$E13)>15)*(INDEX(_calc_기준100!$CN$3:$EF$3,1,$E13)<=30)+(INDEX(_calc_기준100!$CN$3:$EF$3,1,$F13)>15)*(INDEX(_calc_기준100!$CN$3:$EF$3,1,$F13)<=30)+(INDEX(_calc_기준100!$CN$3:$EF$3,1,$G13)>15)*(INDEX(_calc_기준100!$CN$3:$EF$3,1,$G13)<=30),"") -> 2 | K13: =IFERROR((INDEX(_calc_기준100!$CN$3:$EF$3,1,$B13)>30)+(INDEX(_calc_기준100!$CN$3:$EF$3,1,$C13)>30)+(INDEX(_calc_기준100!$CN$3:$EF$3,1,$D13)>30)+(INDEX(_calc_기준100!$CN$3:$EF$3,1,$E13)>30)+(INDEX(_calc_기준100!$CN$3:$EF$3,1,$F13)>30)+(INDEX(_calc_기준100!$CN$3:$EF$3,1,$G13)>30),"") -> 3 | L13: =IFERROR(MATCH(L$11,_calc_기준100!$CN$3:$EF$3,0),"") -> 37 | M13: =IFERROR(MATCH(M$11,_calc_기준100!$CN$3:$EF$3,0),"") -> 39 | N13: =IFERROR(MATCH(N$11,_calc_기준100!$CN$3:$EF$3,0),"") -> 11 | O13: =IFERROR(MATCH(O$11,_calc_기준100!$CN$3:$EF$3,0),"") -> 12 | P13: =IFERROR(MATCH(P$11,_calc_기준100!$CN$3:$EF$3,0),"") -> 23 | Q13: =IFERROR(MATCH(Q$11,_calc_기준100!$CN$3:$EF$3,0),"") -> 9 | R13: =IFERROR(MATCH(R$11,_calc_기준100!$CN$3:$EF$3,0),"") -> 7 | S13: =IFERROR(MATCH(S$11,_calc_기준100!$CN$3:$EF$3,0),"") -> 8 | ... BD13: =IFERROR(MATCH(BD$11,_calc_기준100!$CN$3:$EF$3,0),"") -> 33
A14: =A13-1 -> 1242 | B14: =IFERROR(INDEX(전체당첨내역!$B:$B,MATCH($A14,전체당첨내역!$A:$A,0)),"") -> 2 | C14: =IFERROR(INDEX(전체당첨내역!$C:$C,MATCH($A14,전체당첨내역!$A:$A,0)),"") -> 4 | D14: =IFERROR(INDEX(전체당첨내역!$D:$D,MATCH($A14,전체당첨내역!$A:$A,0)),"") -> 10 | E14: =IFERROR(INDEX(전체당첨내역!$E:$E,MATCH($A14,전체당첨내역!$A:$A,0)),"") -> 16 | F14: =IFERROR(INDEX(전체당첨내역!$F:$F,MATCH($A14,전체당첨내역!$A:$A,0)),"") -> 31 | G14: =IFERROR(INDEX(전체당첨내역!$G:$G,MATCH($A14,전체당첨내역!$A:$A,0)),"") -> 41 | H14: =IFERROR(INDEX(전체당첨내역!$H:$H,MATCH($A14,전체당첨내역!$A:$A,0)),"") -> 9 | I14: =IFERROR((INDEX(_calc_기준100!$CN$4:$EF$4,1,$B14)>0)*(INDEX(_calc_기준100!$CN$4:$EF$4,1,$B14)<=15)+(INDEX(_calc_기준100!$CN$4:$EF$4,1,$C14)>0)*(INDEX(_calc_기준100!$CN$4:$EF$4,1,$C14)<=15)+(INDEX(_calc_기준100!$CN$4:$EF$4,1,$D14)>0)*(INDEX(_calc_기준100!$CN$4:$EF$4,1,$D14)<=15)+(INDEX(_calc_기준100!$CN$4:$EF$4,1,$E14)>0)*(INDEX(_calc_기준100!$CN$4:$EF$4,1,$E14)<=15)+(INDEX(_calc_기준100!$CN$4:$EF$4,1,$F14)>0)*(INDEX(_calc_기준100!$CN$4:$EF$4,1,$F14)<=15)+(INDEX(_calc_기준100!$CN$4:$EF$4,1,$G14)>0)*(INDEX(_calc_기준100!$CN$4:$EF$4,1,$G14)<=15),"") -> 0 | J14: =IFERROR((INDEX(_calc_기준100!$CN$4:$EF$4,1,$B14)>15)*(INDEX(_calc_기준100!$CN$4:$EF$4,1,$B14)<=30)+(INDEX(_calc_기준100!$CN$4:$EF$4,1,$C14)>15)*(INDEX(_calc_기준100!$CN$4:$EF$4,1,$C14)<=30)+(INDEX(_calc_기준100!$CN$4:$EF$4,1,$D14)>15)*(INDEX(_calc_기준100!$CN$4:$EF$4,1,$D14)<=30)+(INDEX(_calc_기준100!$CN$4:$EF$4,1,$E14)>15)*(INDEX(_calc_기준100!$CN$4:$EF$4,1,$E14)<=30)+(INDEX(_calc_기준100!$CN$4:$EF$4,1,$F14)>15)*(INDEX(_calc_기준100!$CN$4:$EF$4,1,$F14)<=30)+(INDEX(_calc_기준100!$CN$4:$EF$4,1,$G14)>15)*(INDEX(_calc_기준100!$CN$4:$EF$4,1,$G14)<=30),"") -> 3 | K14: =IFERROR((INDEX(_calc_기준100!$CN$4:$EF$4,1,$B14)>30)+(INDEX(_calc_기준100!$CN$4:$EF$4,1,$C14)>30)+(INDEX(_calc_기준100!$CN$4:$EF$4,1,$D14)>30)+(INDEX(_calc_기준100!$CN$4:$EF$4,1,$E14)>30)+(INDEX(_calc_기준100!$CN$4:$EF$4,1,$F14)>30)+(INDEX(_calc_기준100!$CN$4:$EF$4,1,$G14)>30),"") -> 3 | L14: =IFERROR(MATCH(L$11,_calc_기준100!$CN$4:$EF$4,0),"") -> 37 | M14: =IFERROR(MATCH(M$11,_calc_기준100!$CN$4:$EF$4,0),"") -> 11 | N14: =IFERROR(MATCH(N$11,_calc_기준100!$CN$4:$EF$4,0),"") -> 12 | O14: =IFERROR(MATCH(O$11,_calc_기준100!$CN$4:$EF$4,0),"") -> 7 | P14: =IFERROR(MATCH(P$11,_calc_기준100!$CN$4:$EF$4,0),"") -> 8 | Q14: =IFERROR(MATCH(Q$11,_calc_기준100!$CN$4:$EF$4,0),"") -> 9 | R14: =IFERROR(MATCH(R$11,_calc_기준100!$CN$4:$EF$4,0),"") -> 17 | S14: =IFERROR(MATCH(S$11,_calc_기준100!$CN$4:$EF$4,0),"") -> 26 | ... BD14: =IFERROR(MATCH(BD$11,_calc_기준100!$CN$4:$EF$4,0),"") -> 33
A15: =A14-1 -> 1241 | B15: =IFERROR(INDEX(전체당첨내역!$B:$B,MATCH($A15,전체당첨내역!$A:$A,0)),"") -> 7 | C15: =IFERROR(INDEX(전체당첨내역!$C:$C,MATCH($A15,전체당첨내역!$A:$A,0)),"") -> 13 | D15: =IFERROR(INDEX(전체당첨내역!$D:$D,MATCH($A15,전체당첨내역!$A:$A,0)),"") -> 16 | E15: =IFERROR(INDEX(전체당첨내역!$E:$E,MATCH($A15,전체당첨내역!$A:$A,0)),"") -> 23 | F15: =IFERROR(INDEX(전체당첨내역!$F:$F,MATCH($A15,전체당첨내역!$A:$A,0)),"") -> 24 | G15: =IFERROR(INDEX(전체당첨내역!$G:$G,MATCH($A15,전체당첨내역!$A:$A,0)),"") -> 43 | H15: =IFERROR(INDEX(전체당첨내역!$H:$H,MATCH($A15,전체당첨내역!$A:$A,0)),"") -> 9 | I15: =IFERROR((INDEX(_calc_기준100!$CN$5:$EF$5,1,$B15)>0)*(INDEX(_calc_기준100!$CN$5:$EF$5,1,$B15)<=15)+(INDEX(_calc_기준100!$CN$5:$EF$5,1,$C15)>0)*(INDEX(_calc_기준100!$CN$5:$EF$5,1,$C15)<=15)+(INDEX(_calc_기준100!$CN$5:$EF$5,1,$D15)>0)*(INDEX(_calc_기준100!$CN$5:$EF$5,1,$D15)<=15)+(INDEX(_calc_기준100!$CN$5:$EF$5,1,$E15)>0)*(INDEX(_calc_기준100!$CN$5:$EF$5,1,$E15)<=15)+(INDEX(_calc_기준100!$CN$5:$EF$5,1,$F15)>0)*(INDEX(_calc_기준100!$CN$5:$EF$5,1,$F15)<=15)+(INDEX(_calc_기준100!$CN$5:$EF$5,1,$G15)>0)*(INDEX(_calc_기준100!$CN$5:$EF$5,1,$G15)<=15),"") -> 2 | J15: =IFERROR((INDEX(_calc_기준100!$CN$5:$EF$5,1,$B15)>15)*(INDEX(_calc_기준100!$CN$5:$EF$5,1,$B15)<=30)+(INDEX(_calc_기준100!$CN$5:$EF$5,1,$C15)>15)*(INDEX(_calc_기준100!$CN$5:$EF$5,1,$C15)<=30)+(INDEX(_calc_기준100!$CN$5:$EF$5,1,$D15)>15)*(INDEX(_calc_기준100!$CN$5:$EF$5,1,$D15)<=30)+(INDEX(_calc_기준100!$CN$5:$EF$5,1,$E15)>15)*(INDEX(_calc_기준100!$CN$5:$EF$5,1,$E15)<=30)+(INDEX(_calc_기준100!$CN$5:$EF$5,1,$F15)>15)*(INDEX(_calc_기준100!$CN$5:$EF$5,1,$F15)<=30)+(INDEX(_calc_기준100!$CN$5:$EF$5,1,$G15)>15)*(INDEX(_calc_기준100!$CN$5:$EF$5,1,$G15)<=30),"") -> 3 | K15: =IFERROR((INDEX(_calc_기준100!$CN$5:$EF$5,1,$B15)>30)+(INDEX(_calc_기준100!$CN$5:$EF$5,1,$C15)>30)+(INDEX(_calc_기준100!$CN$5:$EF$5,1,$D15)>30)+(INDEX(_calc_기준100!$CN$5:$EF$5,1,$E15)>30)+(INDEX(_calc_기준100!$CN$5:$EF$5,1,$F15)>30)+(INDEX(_calc_기준100!$CN$5:$EF$5,1,$G15)>30),"") -> 1 | L15: =IFERROR(MATCH(L$11,_calc_기준100!$CN$5:$EF$5,0),"") -> 37 | M15: =IFERROR(MATCH(M$11,_calc_기준100!$CN$5:$EF$5,0),"") -> 7 | N15: =IFERROR(MATCH(N$11,_calc_기준100!$CN$5:$EF$5,0),"") -> 26 | O15: =IFERROR(MATCH(O$11,_calc_기준100!$CN$5:$EF$5,0),"") -> 35 | P15: =IFERROR(MATCH(P$11,_calc_기준100!$CN$5:$EF$5,0),"") -> 8 | Q15: =IFERROR(MATCH(Q$11,_calc_기준100!$CN$5:$EF$5,0),"") -> 9 | R15: =IFERROR(MATCH(R$11,_calc_기준100!$CN$5:$EF$5,0),"") -> 11 | S15: =IFERROR(MATCH(S$11,_calc_기준100!$CN$5:$EF$5,0),"") -> 12 | ... BD15: =IFERROR(MATCH(BD$11,_calc_기준100!$CN$5:$EF$5,0),"") -> 1
A16: =A15-1 -> 1240 | B16: =IFERROR(INDEX(전체당첨내역!$B:$B,MATCH($A16,전체당첨내역!$A:$A,0)),"") -> 11 | C16: =IFERROR(INDEX(전체당첨내역!$C:$C,MATCH($A16,전체당첨내역!$A:$A,0)),"") -> 13 | D16: =IFERROR(INDEX(전체당첨내역!$D:$D,MATCH($A16,전체당첨내역!$A:$A,0)),"") -> 19 | E16: =IFERROR(INDEX(전체당첨내역!$E:$E,MATCH($A16,전체당첨내역!$A:$A,0)),"") -> 20 | F16: =IFERROR(INDEX(전체당첨내역!$F:$F,MATCH($A16,전체당첨내역!$A:$A,0)),"") -> 31 | G16: =IFERROR(INDEX(전체당첨내역!$G:$G,MATCH($A16,전체당첨내역!$A:$A,0)),"") -> 44 | H16: =IFERROR(INDEX(전체당첨내역!$H:$H,MATCH($A16,전체당첨내역!$A:$A,0)),"") -> 27 | I16: =IFERROR((INDEX(_calc_기준100!$CN$6:$EF$6,1,$B16)>0)*(INDEX(_calc_기준100!$CN$6:$EF$6,1,$B16)<=15)+(INDEX(_calc_기준100!$CN$6:$EF$6,1,$C16)>0)*(INDEX(_calc_기준100!$CN$6:$EF$6,1,$C16)<=15)+(INDEX(_calc_기준100!$CN$6:$EF$6,1,$D16)>0)*(INDEX(_calc_기준100!$CN$6:$EF$6,1,$D16)<=15)+(INDEX(_calc_기준100!$CN$6:$EF$6,1,$E16)>0)*(INDEX(_calc_기준100!$CN$6:$EF$6,1,$E16)<=15)+(INDEX(_calc_기준100!$CN$6:$EF$6,1,$F16)>0)*(INDEX(_calc_기준100!$CN$6:$EF$6,1,$F16)<=15)+(INDEX(_calc_기준100!$CN$6:$EF$6,1,$G16)>0)*(INDEX(_calc_기준100!$CN$6:$EF$6,1,$G16)<=15),"") -> 1 | J16: =IFERROR((INDEX(_calc_기준100!$CN$6:$EF$6,1,$B16)>15)*(INDEX(_calc_기준100!$CN$6:$EF$6,1,$B16)<=30)+(INDEX(_calc_기준100!$CN$6:$EF$6,1,$C16)>15)*(INDEX(_calc_기준100!$CN$6:$EF$6,1,$C16)<=30)+(INDEX(_calc_기준100!$CN$6:$EF$6,1,$D16)>15)*(INDEX(_calc_기준100!$CN$6:$EF$6,1,$D16)<=30)+(INDEX(_calc_기준100!$CN$6:$EF$6,1,$E16)>15)*(INDEX(_calc_기준100!$CN$6:$EF$6,1,$E16)<=30)+(INDEX(_calc_기준100!$CN$6:$EF$6,1,$F16)>15)*(INDEX(_calc_기준100!$CN$6:$EF$6,1,$F16)<=30)+(INDEX(_calc_기준100!$CN$6:$EF$6,1,$G16)>15)*(INDEX(_calc_기준100!$CN$6:$EF$6,1,$G16)<=30),"") -> 3 | K16: =IFERROR((INDEX(_calc_기준100!$CN$6:$EF$6,1,$B16)>30)+(INDEX(_calc_기준100!$CN$6:$EF$6,1,$C16)>30)+(INDEX(_calc_기준100!$CN$6:$EF$6,1,$D16)>30)+(INDEX(_calc_기준100!$CN$6:$EF$6,1,$E16)>30)+(INDEX(_calc_기준100!$CN$6:$EF$6,1,$F16)>30)+(INDEX(_calc_기준100!$CN$6:$EF$6,1,$G16)>30),"") -> 2 | L16: =IFERROR(MATCH(L$11,_calc_기준100!$CN$6:$EF$6,0),"") -> 37 | M16: =IFERROR(MATCH(M$11,_calc_기준100!$CN$6:$EF$6,0),"") -> 11 | N16: =IFERROR(MATCH(N$11,_calc_기준100!$CN$6:$EF$6,0),"") -> 7 | O16: =IFERROR(MATCH(O$11,_calc_기준100!$CN$6:$EF$6,0),"") -> 35 | P16: =IFERROR(MATCH(P$11,_calc_기준100!$CN$6:$EF$6,0),"") -> 29 | Q16: =IFERROR(MATCH(Q$11,_calc_기준100!$CN$6:$EF$6,0),"") -> 8 | R16: =IFERROR(MATCH(R$11,_calc_기준100!$CN$6:$EF$6,0),"") -> 12 | S16: =IFERROR(MATCH(S$11,_calc_기준100!$CN$6:$EF$6,0),"") -> 6 | ... BD16: =IFERROR(MATCH(BD$11,_calc_기준100!$CN$6:$EF$6,0),"") -> 1
A17: =A16-1 -> 1239 | B17: =IFERROR(INDEX(전체당첨내역!$B:$B,MATCH($A17,전체당첨내역!$A:$A,0)),"") -> 11 | C17: =IFERROR(INDEX(전체당첨내역!$C:$C,MATCH($A17,전체당첨내역!$A:$A,0)),"") -> 13 | D17: =IFERROR(INDEX(전체당첨내역!$D:$D,MATCH($A17,전체당첨내역!$A:$A,0)),"") -> 22 | E17: =IFERROR(INDEX(전체당첨내역!$E:$E,MATCH($A17,전체당첨내역!$A:$A,0)),"") -> 32 | F17: =IFERROR(INDEX(전체당첨내역!$F:$F,MATCH($A17,전체당첨내역!$A:$A,0)),"") -> 33 | G17: =IFERROR(INDEX(전체당첨내역!$G:$G,MATCH($A17,전체당첨내역!$A:$A,0)),"") -> 36 | H17: =IFERROR(INDEX(전체당첨내역!$H:$H,MATCH($A17,전체당첨내역!$A:$A,0)),"") -> 8 | I17: =IFERROR((INDEX(_calc_기준100!$CN$7:$EF$7,1,$B17)>0)*(INDEX(_calc_기준100!$CN$7:$EF$7,1,$B17)<=15)+(INDEX(_calc_기준100!$CN$7:$EF$7,1,$C17)>0)*(INDEX(_calc_기준100!$CN$7:$EF$7,1,$C17)<=15)+(INDEX(_calc_기준100!$CN$7:$EF$7,1,$D17)>0)*(INDEX(_calc_기준100!$CN$7:$EF$7,1,$D17)<=15)+(INDEX(_calc_기준100!$CN$7:$EF$7,1,$E17)>0)*(INDEX(_calc_기준100!$CN$7:$EF$7,1,$E17)<=15)+(INDEX(_calc_기준100!$CN$7:$EF$7,1,$F17)>0)*(INDEX(_calc_기준100!$CN$7:$EF$7,1,$F17)<=15)+(INDEX(_calc_기준100!$CN$7:$EF$7,1,$G17)>0)*(INDEX(_calc_기준100!$CN$7:$EF$7,1,$G17)<=15),"") -> 2 | J17: =IFERROR((INDEX(_calc_기준100!$CN$7:$EF$7,1,$B17)>15)*(INDEX(_calc_기준100!$CN$7:$EF$7,1,$B17)<=30)+(INDEX(_calc_기준100!$CN$7:$EF$7,1,$C17)>15)*(INDEX(_calc_기준100!$CN$7:$EF$7,1,$C17)<=30)+(INDEX(_calc_기준100!$CN$7:$EF$7,1,$D17)>15)*(INDEX(_calc_기준100!$CN$7:$EF$7,1,$D17)<=30)+(INDEX(_calc_기준100!$CN$7:$EF$7,1,$E17)>15)*(INDEX(_calc_기준100!$CN$7:$EF$7,1,$E17)<=30)+(INDEX(_calc_기준100!$CN$7:$EF$7,1,$F17)>15)*(INDEX(_calc_기준100!$CN$7:$EF$7,1,$F17)<=30)+(INDEX(_calc_기준100!$CN$7:$EF$7,1,$G17)>15)*(INDEX(_calc_기준100!$CN$7:$EF$7,1,$G17)<=30),"") -> 2 | K17: =IFERROR((INDEX(_calc_기준100!$CN$7:$EF$7,1,$B17)>30)+(INDEX(_calc_기준100!$CN$7:$EF$7,1,$C17)>30)+(INDEX(_calc_기준100!$CN$7:$EF$7,1,$D17)>30)+(INDEX(_calc_기준100!$CN$7:$EF$7,1,$E17)>30)+(INDEX(_calc_기준100!$CN$7:$EF$7,1,$F17)>30)+(INDEX(_calc_기준100!$CN$7:$EF$7,1,$G17)>30),"") -> 2 | L17: =IFERROR(MATCH(L$11,_calc_기준100!$CN$7:$EF$7,0),"") -> 7 | M17: =IFERROR(MATCH(M$11,_calc_기준100!$CN$7:$EF$7,0),"") -> 8 | N17: =IFERROR(MATCH(N$11,_calc_기준100!$CN$7:$EF$7,0),"") -> 12 | O17: =IFERROR(MATCH(O$11,_calc_기준100!$CN$7:$EF$7,0),"") -> 37 | P17: =IFERROR(MATCH(P$11,_calc_기준100!$CN$7:$EF$7,0),"") -> 11 | Q17: =IFERROR(MATCH(Q$11,_calc_기준100!$CN$7:$EF$7,0),"") -> 40 | R17: =IFERROR(MATCH(R$11,_calc_기준100!$CN$7:$EF$7,0),"") -> 6 | S17: =IFERROR(MATCH(S$11,_calc_기준100!$CN$7:$EF$7,0),"") -> 25 | ... BD17: =IFERROR(MATCH(BD$11,_calc_기준100!$CN$7:$EF$7,0),"") -> 1
A18: =A17-1 -> 1238 | B18: =IFERROR(INDEX(전체당첨내역!$B:$B,MATCH($A18,전체당첨내역!$A:$A,0)),"") -> 2 | C18: =IFERROR(INDEX(전체당첨내역!$C:$C,MATCH($A18,전체당첨내역!$A:$A,0)),"") -> 13 | D18: =IFERROR(INDEX(전체당첨내역!$D:$D,MATCH($A18,전체당첨내역!$A:$A,0)),"") -> 18 | E18: =IFERROR(INDEX(전체당첨내역!$E:$E,MATCH($A18,전체당첨내역!$A:$A,0)),"") -> 32 | F18: =IFERROR(INDEX(전체당첨내역!$F:$F,MATCH($A18,전체당첨내역!$A:$A,0)),"") -> 38 | G18: =IFERROR(INDEX(전체당첨내역!$G:$G,MATCH($A18,전체당첨내역!$A:$A,0)),"") -> 42 | H18: =IFERROR(INDEX(전체당첨내역!$H:$H,MATCH($A18,전체당첨내역!$A:$A,0)),"") -> 22 | I18: =IFERROR((INDEX(_calc_기준100!$CN$8:$EF$8,1,$B18)>0)*(INDEX(_calc_기준100!$CN$8:$EF$8,1,$B18)<=15)+(INDEX(_calc_기준100!$CN$8:$EF$8,1,$C18)>0)*(INDEX(_calc_기준100!$CN$8:$EF$8,1,$C18)<=15)+(INDEX(_calc_기준100!$CN$8:$EF$8,1,$D18)>0)*(INDEX(_calc_기준100!$CN$8:$EF$8,1,$D18)<=15)+(INDEX(_calc_기준100!$CN$8:$EF$8,1,$E18)>0)*(INDEX(_calc_기준100!$CN$8:$EF$8,1,$E18)<=15)+(INDEX(_calc_기준100!$CN$8:$EF$8,1,$F18)>0)*(INDEX(_calc_기준100!$CN$8:$EF$8,1,$F18)<=15)+(INDEX(_calc_기준100!$CN$8:$EF$8,1,$G18)>0)*(INDEX(_calc_기준100!$CN$8:$EF$8,1,$G18)<=15),"") -> 3 | J18: =IFERROR((INDEX(_calc_기준100!$CN$8:$EF$8,1,$B18)>15)*(INDEX(_calc_기준100!$CN$8:$EF$8,1,$B18)<=30)+(INDEX(_calc_기준100!$CN$8:$EF$8,1,$C18)>15)*(INDEX(_calc_기준100!$CN$8:$EF$8,1,$C18)<=30)+(INDEX(_calc_기준100!$CN$8:$EF$8,1,$D18)>15)*(INDEX(_calc_기준100!$CN$8:$EF$8,1,$D18)<=30)+(INDEX(_calc_기준100!$CN$8:$EF$8,1,$E18)>15)*(INDEX(_calc_기준100!$CN$8:$EF$8,1,$E18)<=30)+(INDEX(_calc_기준100!$CN$8:$EF$8,1,$F18)>15)*(INDEX(_calc_기준100!$CN$8:$EF$8,1,$F18)<=30)+(INDEX(_calc_기준100!$CN$8:$EF$8,1,$G18)>15)*(INDEX(_calc_기준100!$CN$8:$EF$8,1,$G18)<=30),"") -> 3 | K18: =IFERROR((INDEX(_calc_기준100!$CN$8:$EF$8,1,$B18)>30)+(INDEX(_calc_기준100!$CN$8:$EF$8,1,$C18)>30)+(INDEX(_calc_기준100!$CN$8:$EF$8,1,$D18)>30)+(INDEX(_calc_기준100!$CN$8:$EF$8,1,$E18)>30)+(INDEX(_calc_기준100!$CN$8:$EF$8,1,$F18)>30)+(INDEX(_calc_기준100!$CN$8:$EF$8,1,$G18)>30),"") -> 0 | L18: =IFERROR(MATCH(L$11,_calc_기준100!$CN$8:$EF$8,0),"") -> 7 | M18: =IFERROR(MATCH(M$11,_calc_기준100!$CN$8:$EF$8,0),"") -> 37 | N18: =IFERROR(MATCH(N$11,_calc_기준100!$CN$8:$EF$8,0),"") -> 8 | O18: =IFERROR(MATCH(O$11,_calc_기준100!$CN$8:$EF$8,0),"") -> 11 | P18: =IFERROR(MATCH(P$11,_calc_기준100!$CN$8:$EF$8,0),"") -> 13 | Q18: =IFERROR(MATCH(Q$11,_calc_기준100!$CN$8:$EF$8,0),"") -> 17 | R18: =IFERROR(MATCH(R$11,_calc_기준100!$CN$8:$EF$8,0),"") -> 40 | S18: =IFERROR(MATCH(S$11,_calc_기준100!$CN$8:$EF$8,0),"") -> 25 | ... BD18: =IFERROR(MATCH(BD$11,_calc_기준100!$CN$8:$EF$8,0),"") -> 1
A19: =A18-1 -> 1237 | B19: =IFERROR(INDEX(전체당첨내역!$B:$B,MATCH($A19,전체당첨내역!$A:$A,0)),"") -> 10 | C19: =IFERROR(INDEX(전체당첨내역!$C:$C,MATCH($A19,전체당첨내역!$A:$A,0)),"") -> 20 | D19: =IFERROR(INDEX(전체당첨내역!$D:$D,MATCH($A19,전체당첨내역!$A:$A,0)),"") -> 23 | E19: =IFERROR(INDEX(전체당첨내역!$E:$E,MATCH($A19,전체당첨내역!$A:$A,0)),"") -> 34 | F19: =IFERROR(INDEX(전체당첨내역!$F:$F,MATCH($A19,전체당첨내역!$A:$A,0)),"") -> 37 | G19: =IFERROR(INDEX(전체당첨내역!$G:$G,MATCH($A19,전체당첨내역!$A:$A,0)),"") -> 40 | H19: =IFERROR(INDEX(전체당첨내역!$H:$H,MATCH($A19,전체당첨내역!$A:$A,0)),"") -> 36 | I19: =IFERROR((INDEX(_calc_기준100!$CN$9:$EF$9,1,$B19)>0)*(INDEX(_calc_기준100!$CN$9:$EF$9,1,$B19)<=15)+(INDEX(_calc_기준100!$CN$9:$EF$9,1,$C19)>0)*(INDEX(_calc_기준100!$CN$9:$EF$9,1,$C19)<=15)+(INDEX(_calc_기준100!$CN$9:$EF$9,1,$D19)>0)*(INDEX(_calc_기준100!$CN$9:$EF$9,1,$D19)<=15)+(INDEX(_calc_기준100!$CN$9:$EF$9,1,$E19)>0)*(INDEX(_calc_기준100!$CN$9:$EF$9,1,$E19)<=15)+(INDEX(_calc_기준100!$CN$9:$EF$9,1,$F19)>0)*(INDEX(_calc_기준100!$CN$9:$EF$9,1,$F19)<=15)+(INDEX(_calc_기준100!$CN$9:$EF$9,1,$G19)>0)*(INDEX(_calc_기준100!$CN$9:$EF$9,1,$G19)<=15),"") -> 2 | J19: =IFERROR((INDEX(_calc_기준100!$CN$9:$EF$9,1,$B19)>15)*(INDEX(_calc_기준100!$CN$9:$EF$9,1,$B19)<=30)+(INDEX(_calc_기준100!$CN$9:$EF$9,1,$C19)>15)*(INDEX(_calc_기준100!$CN$9:$EF$9,1,$C19)<=30)+(INDEX(_calc_기준100!$CN$9:$EF$9,1,$D19)>15)*(INDEX(_calc_기준100!$CN$9:$EF$9,1,$D19)<=30)+(INDEX(_calc_기준100!$CN$9:$EF$9,1,$E19)>15)*(INDEX(_calc_기준100!$CN$9:$EF$9,1,$E19)<=30)+(INDEX(_calc_기준100!$CN$9:$EF$9,1,$F19)>15)*(INDEX(_calc_기준100!$CN$9:$EF$9,1,$F19)<=30)+(INDEX(_calc_기준100!$CN$9:$EF$9,1,$G19)>15)*(INDEX(_calc_기준100!$CN$9:$EF$9,1,$G19)<=30),"") -> 3 | K19: =IFERROR((INDEX(_calc_기준100!$CN$9:$EF$9,1,$B19)>30)+(INDEX(_calc_기준100!$CN$9:$EF$9,1,$C19)>30)+(INDEX(_calc_기준100!$CN$9:$EF$9,1,$D19)>30)+(INDEX(_calc_기준100!$CN$9:$EF$9,1,$E19)>30)+(INDEX(_calc_기준100!$CN$9:$EF$9,1,$F19)>30)+(INDEX(_calc_기준100!$CN$9:$EF$9,1,$G19)>30),"") -> 1 | L19: =IFERROR(MATCH(L$11,_calc_기준100!$CN$9:$EF$9,0),"") -> 7 | M19: =IFERROR(MATCH(M$11,_calc_기준100!$CN$9:$EF$9,0),"") -> 11 | N19: =IFERROR(MATCH(N$11,_calc_기준100!$CN$9:$EF$9,0),"") -> 8 | O19: =IFERROR(MATCH(O$11,_calc_기준100!$CN$9:$EF$9,0),"") -> 37 | P19: =IFERROR(MATCH(P$11,_calc_기준100!$CN$9:$EF$9,0),"") -> 17 | Q19: =IFERROR(MATCH(Q$11,_calc_기준100!$CN$9:$EF$9,0),"") -> 6 | R19: =IFERROR(MATCH(R$11,_calc_기준100!$CN$9:$EF$9,0),"") -> 21 | S19: =IFERROR(MATCH(S$11,_calc_기준100!$CN$9:$EF$9,0),"") -> 25 | ... BD19: =IFERROR(MATCH(BD$11,_calc_기준100!$CN$9:$EF$9,0),"") -> 1
A20: =A19-1 -> 1236 | B20: =IFERROR(INDEX(전체당첨내역!$B:$B,MATCH($A20,전체당첨내역!$A:$A,0)),"") -> 12 | C20: =IFERROR(INDEX(전체당첨내역!$C:$C,MATCH($A20,전체당첨내역!$A:$A,0)),"") -> 18 | D20: =IFERROR(INDEX(전체당첨내역!$D:$D,MATCH($A20,전체당첨내역!$A:$A,0)),"") -> 21 | E20: =IFERROR(INDEX(전체당첨내역!$E:$E,MATCH($A20,전체당첨내역!$A:$A,0)),"") -> 29 | F20: =IFERROR(INDEX(전체당첨내역!$F:$F,MATCH($A20,전체당첨내역!$A:$A,0)),"") -> 34 | G20: =IFERROR(INDEX(전체당첨내역!$G:$G,MATCH($A20,전체당첨내역!$A:$A,0)),"") -> 38 | H20: =IFERROR(INDEX(전체당첨내역!$H:$H,MATCH($A20,전체당첨내역!$A:$A,0)),"") -> 10 | I20: =IFERROR((INDEX(_calc_기준100!$CN$10:$EF$10,1,$B20)>0)*(INDEX(_calc_기준100!$CN$10:$EF$10,1,$B20)<=15)+(INDEX(_calc_기준100!$CN$10:$EF$10,1,$C20)>0)*(INDEX(_calc_기준100!$CN$10:$EF$10,1,$C20)<=15)+(INDEX(_calc_기준100!$CN$10:$EF$10,1,$D20)>0)*(INDEX(_calc_기준100!$CN$10:$EF$10,1,$D20)<=15)+(INDEX(_calc_기준100!$CN$10:$EF$10,1,$E20)>0)*(INDEX(_calc_기준100!$CN$10:$EF$10,1,$E20)<=15)+(INDEX(_calc_기준100!$CN$10:$EF$10,1,$F20)>0)*(INDEX(_calc_기준100!$CN$10:$EF$10,1,$F20)<=15)+(INDEX(_calc_기준100!$CN$10:$EF$10,1,$G20)>0)*(INDEX(_calc_기준100!$CN$10:$EF$10,1,$G20)<=15),"") -> 4 | J20: =IFERROR((INDEX(_calc_기준100!$CN$10:$EF$10,1,$B20)>15)*(INDEX(_calc_기준100!$CN$10:$EF$10,1,$B20)<=30)+(INDEX(_calc_기준100!$CN$10:$EF$10,1,$C20)>15)*(INDEX(_calc_기준100!$CN$10:$EF$10,1,$C20)<=30)+(INDEX(_calc_기준100!$CN$10:$EF$10,1,$D20)>15)*(INDEX(_calc_기준100!$CN$10:$EF$10,1,$D20)<=30)+(INDEX(_calc_기준100!$CN$10:$EF$10,1,$E20)>15)*(INDEX(_calc_기준100!$CN$10:$EF$10,1,$E20)<=30)+(INDEX(_calc_기준100!$CN$10:$EF$10,1,$F20)>15)*(INDEX(_calc_기준100!$CN$10:$EF$10,1,$F20)<=30)+(INDEX(_calc_기준100!$CN$10:$EF$10,1,$G20)>15)*(INDEX(_calc_기준100!$CN$10:$EF$10,1,$G20)<=30),"") -> 2 | K20: =IFERROR((INDEX(_calc_기준100!$CN$10:$EF$10,1,$B20)>30)+(INDEX(_calc_기준100!$CN$10:$EF$10,1,$C20)>30)+(INDEX(_calc_기준100!$CN$10:$EF$10,1,$D20)>30)+(INDEX(_calc_기준100!$CN$10:$EF$10,1,$E20)>30)+(INDEX(_calc_기준100!$CN$10:$EF$10,1,$F20)>30)+(INDEX(_calc_기준100!$CN$10:$EF$10,1,$G20)>30),"") -> 0 | L20: =IFERROR(MATCH(L$11,_calc_기준100!$CN$10:$EF$10,0),"") -> 7 | M20: =IFERROR(MATCH(M$11,_calc_기준100!$CN$10:$EF$10,0),"") -> 12 | N20: =IFERROR(MATCH(N$11,_calc_기준100!$CN$10:$EF$10,0),"") -> 11 | O20: =IFERROR(MATCH(O$11,_calc_기준100!$CN$10:$EF$10,0),"") -> 37 | P20: =IFERROR(MATCH(P$11,_calc_기준100!$CN$10:$EF$10,0),"") -> 6 | Q20: =IFERROR(MATCH(Q$11,_calc_기준100!$CN$10:$EF$10,0),"") -> 17 | R20: =IFERROR(MATCH(R$11,_calc_기준100!$CN$10:$EF$10,0),"") -> 25 | S20: =IFERROR(MATCH(S$11,_calc_기준100!$CN$10:$EF$10,0),"") -> 42 | ... BD20: =IFERROR(MATCH(BD$11,_calc_기준100!$CN$10:$EF$10,0),"") -> 1
A21: =A20-1 -> 1235 | B21: =IFERROR(INDEX(전체당첨내역!$B:$B,MATCH($A21,전체당첨내역!$A:$A,0)),"") -> 6 | C21: =IFERROR(INDEX(전체당첨내역!$C:$C,MATCH($A21,전체당첨내역!$A:$A,0)),"") -> 7 | D21: =IFERROR(INDEX(전체당첨내역!$D:$D,MATCH($A21,전체당첨내역!$A:$A,0)),"") -> 11 | E21: =IFERROR(INDEX(전체당첨내역!$E:$E,MATCH($A21,전체당첨내역!$A:$A,0)),"") -> 15 | F21: =IFERROR(INDEX(전체당첨내역!$F:$F,MATCH($A21,전체당첨내역!$A:$A,0)),"") -> 39 | G21: =IFERROR(INDEX(전체당첨내역!$G:$G,MATCH($A21,전체당첨내역!$A:$A,0)),"") -> 43 | H21: =IFERROR(INDEX(전체당첨내역!$H:$H,MATCH($A21,전체당첨내역!$A:$A,0)),"") -> 20 | I21: =IFERROR((INDEX(_calc_기준100!$CN$11:$EF$11,1,$B21)>0)*(INDEX(_calc_기준100!$CN$11:$EF$11,1,$B21)<=15)+(INDEX(_calc_기준100!$CN$11:$EF$11,1,$C21)>0)*(INDEX(_calc_기준100!$CN$11:$EF$11,1,$C21)<=15)+(INDEX(_calc_기준100!$CN$11:$EF$11,1,$D21)>0)*(INDEX(_calc_기준100!$CN$11:$EF$11,1,$D21)<=15)+(INDEX(_calc_기준100!$CN$11:$EF$11,1,$E21)>0)*(INDEX(_calc_기준100!$CN$11:$EF$11,1,$E21)<=15)+(INDEX(_calc_기준100!$CN$11:$EF$11,1,$F21)>0)*(INDEX(_calc_기준100!$CN$11:$EF$11,1,$F21)<=15)+(INDEX(_calc_기준100!$CN$11:$EF$11,1,$G21)>0)*(INDEX(_calc_기준100!$CN$11:$EF$11,1,$G21)<=15),"") -> 4 | J21: =IFERROR((INDEX(_calc_기준100!$CN$11:$EF$11,1,$B21)>15)*(INDEX(_calc_기준100!$CN$11:$EF$11,1,$B21)<=30)+(INDEX(_calc_기준100!$CN$11:$EF$11,1,$C21)>15)*(INDEX(_calc_기준100!$CN$11:$EF$11,1,$C21)<=30)+(INDEX(_calc_기준100!$CN$11:$EF$11,1,$D21)>15)*(INDEX(_calc_기준100!$CN$11:$EF$11,1,$D21)<=30)+(INDEX(_calc_기준100!$CN$11:$EF$11,1,$E21)>15)*(INDEX(_calc_기준100!$CN$11:$EF$11,1,$E21)<=30)+(INDEX(_calc_기준100!$CN$11:$EF$11,1,$F21)>15)*(INDEX(_calc_기준100!$CN$11:$EF$11,1,$F21)<=30)+(INDEX(_calc_기준100!$CN$11:$EF$11,1,$G21)>15)*(INDEX(_calc_기준100!$CN$11:$EF$11,1,$G21)<=30),"") -> 2 | K21: =IFERROR((INDEX(_calc_기준100!$CN$11:$EF$11,1,$B21)>30)+(INDEX(_calc_기준100!$CN$11:$EF$11,1,$C21)>30)+(INDEX(_calc_기준100!$CN$11:$EF$11,1,$D21)>30)+(INDEX(_calc_기준100!$CN$11:$EF$11,1,$E21)>30)+(INDEX(_calc_기준100!$CN$11:$EF$11,1,$F21)>30)+(INDEX(_calc_기준100!$CN$11:$EF$11,1,$G21)>30),"") -> 0 | L21: =IFERROR(MATCH(L$11,_calc_기준100!$CN$11:$EF$11,0),"") -> 7 | M21: =IFERROR(MATCH(M$11,_calc_기준100!$CN$11:$EF$11,0),"") -> 37 | N21: =IFERROR(MATCH(N$11,_calc_기준100!$CN$11:$EF$11,0),"") -> 12 | O21: =IFERROR(MATCH(O$11,_calc_기준100!$CN$11:$EF$11,0),"") -> 21 | P21: =IFERROR(MATCH(P$11,_calc_기준100!$CN$11:$EF$11,0),"") -> 39 | Q21: =IFERROR(MATCH(Q$11,_calc_기준100!$CN$11:$EF$11,0),"") -> 6 | R21: =IFERROR(MATCH(R$11,_calc_기준100!$CN$11:$EF$11,0),"") -> 42 | S21: =IFERROR(MATCH(S$11,_calc_기준100!$CN$11:$EF$11,0),"") -> 25 | ... BD21: =IFERROR(MATCH(BD$11,_calc_기준100!$CN$11:$EF$11,0),"") -> 22
A22: =A21-1 -> 1234 | B22: =IFERROR(INDEX(전체당첨내역!$B:$B,MATCH($A22,전체당첨내역!$A:$A,0)),"") -> 1 | C22: =IFERROR(INDEX(전체당첨내역!$C:$C,MATCH($A22,전체당첨내역!$A:$A,0)),"") -> 15 | D22: =IFERROR(INDEX(전체당첨내역!$D:$D,MATCH($A22,전체당첨내역!$A:$A,0)),"") -> 19 | E22: =IFERROR(INDEX(전체당첨내역!$E:$E,MATCH($A22,전체당첨내역!$A:$A,0)),"") -> 31 | F22: =IFERROR(INDEX(전체당첨내역!$F:$F,MATCH($A22,전체당첨내역!$A:$A,0)),"") -> 35 | G22: =IFERROR(INDEX(전체당첨내역!$G:$G,MATCH($A22,전체당첨내역!$A:$A,0)),"") -> 43 | H22: =IFERROR(INDEX(전체당첨내역!$H:$H,MATCH($A22,전체당첨내역!$A:$A,0)),"") -> 27 | I22: =IFERROR((INDEX(_calc_기준100!$CN$12:$EF$12,1,$B22)>0)*(INDEX(_calc_기준100!$CN$12:$EF$12,1,$B22)<=15)+(INDEX(_calc_기준100!$CN$12:$EF$12,1,$C22)>0)*(INDEX(_calc_기준100!$CN$12:$EF$12,1,$C22)<=15)+(INDEX(_calc_기준100!$CN$12:$EF$12,1,$D22)>0)*(INDEX(_calc_기준100!$CN$12:$EF$12,1,$D22)<=15)+(INDEX(_calc_기준100!$CN$12:$EF$12,1,$E22)>0)*(INDEX(_calc_기준100!$CN$12:$EF$12,1,$E22)<=15)+(INDEX(_calc_기준100!$CN$12:$EF$12,1,$F22)>0)*(INDEX(_calc_기준100!$CN$12:$EF$12,1,$F22)<=15)+(INDEX(_calc_기준100!$CN$12:$EF$12,1,$G22)>0)*(INDEX(_calc_기준100!$CN$12:$EF$12,1,$G22)<=15),"") -> 1 | J22: =IFERROR((INDEX(_calc_기준100!$CN$12:$EF$12,1,$B22)>15)*(INDEX(_calc_기준100!$CN$12:$EF$12,1,$B22)<=30)+(INDEX(_calc_기준100!$CN$12:$EF$12,1,$C22)>15)*(INDEX(_calc_기준100!$CN$12:$EF$12,1,$C22)<=30)+(INDEX(_calc_기준100!$CN$12:$EF$12,1,$D22)>15)*(INDEX(_calc_기준100!$CN$12:$EF$12,1,$D22)<=30)+(INDEX(_calc_기준100!$CN$12:$EF$12,1,$E22)>15)*(INDEX(_calc_기준100!$CN$12:$EF$12,1,$E22)<=30)+(INDEX(_calc_기준100!$CN$12:$EF$12,1,$F22)>15)*(INDEX(_calc_기준100!$CN$12:$EF$12,1,$F22)<=30)+(INDEX(_calc_기준100!$CN$12:$EF$12,1,$G22)>15)*(INDEX(_calc_기준100!$CN$12:$EF$12,1,$G22)<=30),"") -> 2 | K22: =IFERROR((INDEX(_calc_기준100!$CN$12:$EF$12,1,$B22)>30)+(INDEX(_calc_기준100!$CN$12:$EF$12,1,$C22)>30)+(INDEX(_calc_기준100!$CN$12:$EF$12,1,$D22)>30)+(INDEX(_calc_기준100!$CN$12:$EF$12,1,$E22)>30)+(INDEX(_calc_기준100!$CN$12:$EF$12,1,$F22)>30)+(INDEX(_calc_기준100!$CN$12:$EF$12,1,$G22)>30),"") -> 3 | L22: =IFERROR(MATCH(L$11,_calc_기준100!$CN$12:$EF$12,0),"") -> 7 | M22: =IFERROR(MATCH(M$11,_calc_기준100!$CN$12:$EF$12,0),"") -> 12 | N22: =IFERROR(MATCH(N$11,_calc_기준100!$CN$12:$EF$12,0),"") -> 21 | O22: =IFERROR(MATCH(O$11,_calc_기준100!$CN$12:$EF$12,0),"") -> 35 | P22: =IFERROR(MATCH(P$11,_calc_기준100!$CN$12:$EF$12,0),"") -> 39 | Q22: =IFERROR(MATCH(Q$11,_calc_기준100!$CN$12:$EF$12,0),"") -> 6 | R22: =IFERROR(MATCH(R$11,_calc_기준100!$CN$12:$EF$12,0),"") -> 42 | S22: =IFERROR(MATCH(S$11,_calc_기준100!$CN$12:$EF$12,0),"") -> 11 | ... BD22: =IFERROR(MATCH(BD$11,_calc_기준100!$CN$12:$EF$12,0),"") -> 23
A23: =A22-1 -> 1233 | B23: =IFERROR(INDEX(전체당첨내역!$B:$B,MATCH($A23,전체당첨내역!$A:$A,0)),"") -> 2 | C23: =IFERROR(INDEX(전체당첨내역!$C:$C,MATCH($A23,전체당첨내역!$A:$A,0)),"") -> 7 | D23: =IFERROR(INDEX(전체당첨내역!$D:$D,MATCH($A23,전체당첨내역!$A:$A,0)),"") -> 20 | E23: =IFERROR(INDEX(전체당첨내역!$E:$E,MATCH($A23,전체당첨내역!$A:$A,0)),"") -> 25 | F23: =IFERROR(INDEX(전체당첨내역!$F:$F,MATCH($A23,전체당첨내역!$A:$A,0)),"") -> 37 | G23: =IFERROR(INDEX(전체당첨내역!$G:$G,MATCH($A23,전체당첨내역!$A:$A,0)),"") -> 40 | H23: =IFERROR(INDEX(전체당첨내역!$H:$H,MATCH($A23,전체당첨내역!$A:$A,0)),"") -> 29 | I23: =IFERROR((INDEX(_calc_기준100!$CN$13:$EF$13,1,$B23)>0)*(INDEX(_calc_기준100!$CN$13:$EF$13,1,$B23)<=15)+(INDEX(_calc_기준100!$CN$13:$EF$13,1,$C23)>0)*(INDEX(_calc_기준100!$CN$13:$EF$13,1,$C23)<=15)+(INDEX(_calc_기준100!$CN$13:$EF$13,1,$D23)>0)*(INDEX(_calc_기준100!$CN$13:$EF$13,1,$D23)<=15)+(INDEX(_calc_기준100!$CN$13:$EF$13,1,$E23)>0)*(INDEX(_calc_기준100!$CN$13:$EF$13,1,$E23)<=15)+(INDEX(_calc_기준100!$CN$13:$EF$13,1,$F23)>0)*(INDEX(_calc_기준100!$CN$13:$EF$13,1,$F23)<=15)+(INDEX(_calc_기준100!$CN$13:$EF$13,1,$G23)>0)*(INDEX(_calc_기준100!$CN$13:$EF$13,1,$G23)<=15),"") -> 3 | J23: =IFERROR((INDEX(_calc_기준100!$CN$13:$EF$13,1,$B23)>15)*(INDEX(_calc_기준100!$CN$13:$EF$13,1,$B23)<=30)+(INDEX(_calc_기준100!$CN$13:$EF$13,1,$C23)>15)*(INDEX(_calc_기준100!$CN$13:$EF$13,1,$C23)<=30)+(INDEX(_calc_기준100!$CN$13:$EF$13,1,$D23)>15)*(INDEX(_calc_기준100!$CN$13:$EF$13,1,$D23)<=30)+(INDEX(_calc_기준100!$CN$13:$EF$13,1,$E23)>15)*(INDEX(_calc_기준100!$CN$13:$EF$13,1,$E23)<=30)+(INDEX(_calc_기준100!$CN$13:$EF$13,1,$F23)>15)*(INDEX(_calc_기준100!$CN$13:$EF$13,1,$F23)<=30)+(INDEX(_calc_기준100!$CN$13:$EF$13,1,$G23)>15)*(INDEX(_calc_기준100!$CN$13:$EF$13,1,$G23)<=30),"") -> 1 | K23: =IFERROR((INDEX(_calc_기준100!$CN$13:$EF$13,1,$B23)>30)+(INDEX(_calc_기준100!$CN$13:$EF$13,1,$C23)>30)+(INDEX(_calc_기준100!$CN$13:$EF$13,1,$D23)>30)+(INDEX(_calc_기준100!$CN$13:$EF$13,1,$E23)>30)+(INDEX(_calc_기준100!$CN$13:$EF$13,1,$F23)>30)+(INDEX(_calc_기준100!$CN$13:$EF$13,1,$G23)>30),"") -> 2 | L23: =IFERROR(MATCH(L$11,_calc_기준100!$CN$13:$EF$13,0),"") -> 7 | M23: =IFERROR(MATCH(M$11,_calc_기준100!$CN$13:$EF$13,0),"") -> 21 | N23: =IFERROR(MATCH(N$11,_calc_기준100!$CN$13:$EF$13,0),"") -> 12 | O23: =IFERROR(MATCH(O$11,_calc_기준100!$CN$13:$EF$13,0),"") -> 37 | P23: =IFERROR(MATCH(P$11,_calc_기준100!$CN$13:$EF$13,0),"") -> 35 | Q23: =IFERROR(MATCH(Q$11,_calc_기준100!$CN$13:$EF$13,0),"") -> 39 | R23: =IFERROR(MATCH(R$11,_calc_기준100!$CN$13:$EF$13,0),"") -> 11 | S23: =IFERROR(MATCH(S$11,_calc_기준100!$CN$13:$EF$13,0),"") -> 20 | ... BD23: =IFERROR(MATCH(BD$11,_calc_기준100!$CN$13:$EF$13,0),"") -> 23
A24: =A23-1 -> 1232 | B24: =IFERROR(INDEX(전체당첨내역!$B:$B,MATCH($A24,전체당첨내역!$A:$A,0)),"") -> 12 | C24: =IFERROR(INDEX(전체당첨내역!$C:$C,MATCH($A24,전체당첨내역!$A:$A,0)),"") -> 15 | D24: =IFERROR(INDEX(전체당첨내역!$D:$D,MATCH($A24,전체당첨내역!$A:$A,0)),"") -> 19 | E24: =IFERROR(INDEX(전체당첨내역!$E:$E,MATCH($A24,전체당첨내역!$A:$A,0)),"") -> 22 | F24: =IFERROR(INDEX(전체당첨내역!$F:$F,MATCH($A24,전체당첨내역!$A:$A,0)),"") -> 24 | G24: =IFERROR(INDEX(전체당첨내역!$G:$G,MATCH($A24,전체당첨내역!$A:$A,0)),"") -> 36 | H24: =IFERROR(INDEX(전체당첨내역!$H:$H,MATCH($A24,전체당첨내역!$A:$A,0)),"") -> 3 | I24: =IFERROR((INDEX(_calc_기준100!$CN$14:$EF$14,1,$B24)>0)*(INDEX(_calc_기준100!$CN$14:$EF$14,1,$B24)<=15)+(INDEX(_calc_기준100!$CN$14:$EF$14,1,$C24)>0)*(INDEX(_calc_기준100!$CN$14:$EF$14,1,$C24)<=15)+(INDEX(_calc_기준100!$CN$14:$EF$14,1,$D24)>0)*(INDEX(_calc_기준100!$CN$14:$EF$14,1,$D24)<=15)+(INDEX(_calc_기준100!$CN$14:$EF$14,1,$E24)>0)*(INDEX(_calc_기준100!$CN$14:$EF$14,1,$E24)<=15)+(INDEX(_calc_기준100!$CN$14:$EF$14,1,$F24)>0)*(INDEX(_calc_기준100!$CN$14:$EF$14,1,$F24)<=15)+(INDEX(_calc_기준100!$CN$14:$EF$14,1,$G24)>0)*(INDEX(_calc_기준100!$CN$14:$EF$14,1,$G24)<=15),"") -> 1 | J24: =IFERROR((INDEX(_calc_기준100!$CN$14:$EF$14,1,$B24)>15)*(INDEX(_calc_기준100!$CN$14:$EF$14,1,$B24)<=30)+(INDEX(_calc_기준100!$CN$14:$EF$14,1,$C24)>15)*(INDEX(_calc_기준100!$CN$14:$EF$14,1,$C24)<=30)+(INDEX(_calc_기준100!$CN$14:$EF$14,1,$D24)>15)*(INDEX(_calc_기준100!$CN$14:$EF$14,1,$D24)<=30)+(INDEX(_calc_기준100!$CN$14:$EF$14,1,$E24)>15)*(INDEX(_calc_기준100!$CN$14:$EF$14,1,$E24)<=30)+(INDEX(_calc_기준100!$CN$14:$EF$14,1,$F24)>15)*(INDEX(_calc_기준100!$CN$14:$EF$14,1,$F24)<=30)+(INDEX(_calc_기준100!$CN$14:$EF$14,1,$G24)>15)*(INDEX(_calc_기준100!$CN$14:$EF$14,1,$G24)<=30),"") -> 3 | K24: =IFERROR((INDEX(_calc_기준100!$CN$14:$EF$14,1,$B24)>30)+(INDEX(_calc_기준100!$CN$14:$EF$14,1,$C24)>30)+(INDEX(_calc_기준100!$CN$14:$EF$14,1,$D24)>30)+(INDEX(_calc_기준100!$CN$14:$EF$14,1,$E24)>30)+(INDEX(_calc_기준100!$CN$14:$EF$14,1,$F24)>30)+(INDEX(_calc_기준100!$CN$14:$EF$14,1,$G24)>30),"") -> 2 | L24: =IFERROR(MATCH(L$11,_calc_기준100!$CN$14:$EF$14,0),"") -> 7 | M24: =IFERROR(MATCH(M$11,_calc_기준100!$CN$14:$EF$14,0),"") -> 12 | N24: =IFERROR(MATCH(N$11,_calc_기준100!$CN$14:$EF$14,0),"") -> 6 | O24: =IFERROR(MATCH(O$11,_calc_기준100!$CN$14:$EF$14,0),"") -> 21 | P24: =IFERROR(MATCH(P$11,_calc_기준100!$CN$14:$EF$14,0),"") -> 37 | Q24: =IFERROR(MATCH(Q$11,_calc_기준100!$CN$14:$EF$14,0),"") -> 20 | R24: =IFERROR(MATCH(R$11,_calc_기준100!$CN$14:$EF$14,0),"") -> 11 | S24: =IFERROR(MATCH(S$11,_calc_기준100!$CN$14:$EF$14,0),"") -> 35 | ... BD24: =IFERROR(MATCH(BD$11,_calc_기준100!$CN$14:$EF$14,0),"") -> 23
A25: =A24-1 -> 1231 | B25: =IFERROR(INDEX(전체당첨내역!$B:$B,MATCH($A25,전체당첨내역!$A:$A,0)),"") -> 4 | C25: =IFERROR(INDEX(전체당첨내역!$C:$C,MATCH($A25,전체당첨내역!$A:$A,0)),"") -> 13 | D25: =IFERROR(INDEX(전체당첨내역!$D:$D,MATCH($A25,전체당첨내역!$A:$A,0)),"") -> 14 | E25: =IFERROR(INDEX(전체당첨내역!$E:$E,MATCH($A25,전체당첨내역!$A:$A,0)),"") -> 18 | F25: =IFERROR(INDEX(전체당첨내역!$F:$F,MATCH($A25,전체당첨내역!$A:$A,0)),"") -> 31 | G25: =IFERROR(INDEX(전체당첨내역!$G:$G,MATCH($A25,전체당첨내역!$A:$A,0)),"") -> 38 | H25: =IFERROR(INDEX(전체당첨내역!$H:$H,MATCH($A25,전체당첨내역!$A:$A,0)),"") -> 15 | I25: =IFERROR((INDEX(_calc_기준100!$CN$15:$EF$15,1,$B25)>0)*(INDEX(_calc_기준100!$CN$15:$EF$15,1,$B25)<=15)+(INDEX(_calc_기준100!$CN$15:$EF$15,1,$C25)>0)*(INDEX(_calc_기준100!$CN$15:$EF$15,1,$C25)<=15)+(INDEX(_calc_기준100!$CN$15:$EF$15,1,$D25)>0)*(INDEX(_calc_기준100!$CN$15:$EF$15,1,$D25)<=15)+(INDEX(_calc_기준100!$CN$15:$EF$15,1,$E25)>0)*(INDEX(_calc_기준100!$CN$15:$EF$15,1,$E25)<=15)+(INDEX(_calc_기준100!$CN$15:$EF$15,1,$F25)>0)*(INDEX(_calc_기준100!$CN$15:$EF$15,1,$F25)<=15)+(INDEX(_calc_기준100!$CN$15:$EF$15,1,$G25)>0)*(INDEX(_calc_기준100!$CN$15:$EF$15,1,$G25)<=15),"") -> 1 | J25: =IFERROR((INDEX(_calc_기준100!$CN$15:$EF$15,1,$B25)>15)*(INDEX(_calc_기준100!$CN$15:$EF$15,1,$B25)<=30)+(INDEX(_calc_기준100!$CN$15:$EF$15,1,$C25)>15)*(INDEX(_calc_기준100!$CN$15:$EF$15,1,$C25)<=30)+(INDEX(_calc_기준100!$CN$15:$EF$15,1,$D25)>15)*(INDEX(_calc_기준100!$CN$15:$EF$15,1,$D25)<=30)+(INDEX(_calc_기준100!$CN$15:$EF$15,1,$E25)>15)*(INDEX(_calc_기준100!$CN$15:$EF$15,1,$E25)<=30)+(INDEX(_calc_기준100!$CN$15:$EF$15,1,$F25)>15)*(INDEX(_calc_기준100!$CN$15:$EF$15,1,$F25)<=30)+(INDEX(_calc_기준100!$CN$15:$EF$15,1,$G25)>15)*(INDEX(_calc_기준100!$CN$15:$EF$15,1,$G25)<=30),"") -> 2 | K25: =IFERROR((INDEX(_calc_기준100!$CN$15:$EF$15,1,$B25)>30)+(INDEX(_calc_기준100!$CN$15:$EF$15,1,$C25)>30)+(INDEX(_calc_기준100!$CN$15:$EF$15,1,$D25)>30)+(INDEX(_calc_기준100!$CN$15:$EF$15,1,$E25)>30)+(INDEX(_calc_기준100!$CN$15:$EF$15,1,$F25)>30)+(INDEX(_calc_기준100!$CN$15:$EF$15,1,$G25)>30),"") -> 3 | L25: =IFERROR(MATCH(L$11,_calc_기준100!$CN$15:$EF$15,0),"") -> 7 | M25: =IFERROR(MATCH(M$11,_calc_기준100!$CN$15:$EF$15,0),"") -> 12 | N25: =IFERROR(MATCH(N$11,_calc_기준100!$CN$15:$EF$15,0),"") -> 6 | O25: =IFERROR(MATCH(O$11,_calc_기준100!$CN$15:$EF$15,0),"") -> 38 | P25: =IFERROR(MATCH(P$11,_calc_기준100!$CN$15:$EF$15,0),"") -> 21 | Q25: =IFERROR(MATCH(Q$11,_calc_기준100!$CN$15:$EF$15,0),"") -> 35 | R25: =IFERROR(MATCH(R$11,_calc_기준100!$CN$15:$EF$15,0),"") -> 37 | S25: =IFERROR(MATCH(S$11,_calc_기준100!$CN$15:$EF$15,0),"") -> 39 | ... BD25: =IFERROR(MATCH(BD$11,_calc_기준100!$CN$15:$EF$15,0),"") -> 23
A26: =A25-1 -> 1230 | B26: =IFERROR(INDEX(전체당첨내역!$B:$B,MATCH($A26,전체당첨내역!$A:$A,0)),"") -> 3 | C26: =IFERROR(INDEX(전체당첨내역!$C:$C,MATCH($A26,전체당첨내역!$A:$A,0)),"") -> 8 | D26: =IFERROR(INDEX(전체당첨내역!$D:$D,MATCH($A26,전체당첨내역!$A:$A,0)),"") -> 9 | E26: =IFERROR(INDEX(전체당첨내역!$E:$E,MATCH($A26,전체당첨내역!$A:$A,0)),"") -> 22 | F26: =IFERROR(INDEX(전체당첨내역!$F:$F,MATCH($A26,전체당첨내역!$A:$A,0)),"") -> 28 | G26: =IFERROR(INDEX(전체당첨내역!$G:$G,MATCH($A26,전체당첨내역!$A:$A,0)),"") -> 42 | H26: =IFERROR(INDEX(전체당첨내역!$H:$H,MATCH($A26,전체당첨내역!$A:$A,0)),"") -> 45 | I26: =IFERROR((INDEX(_calc_기준100!$CN$16:$EF$16,1,$B26)>0)*(INDEX(_calc_기준100!$CN$16:$EF$16,1,$B26)<=15)+(INDEX(_calc_기준100!$CN$16:$EF$16,1,$C26)>0)*(INDEX(_calc_기준100!$CN$16:$EF$16,1,$C26)<=15)+(INDEX(_calc_기준100!$CN$16:$EF$16,1,$D26)>0)*(INDEX(_calc_기준100!$CN$16:$EF$16,1,$D26)<=15)+(INDEX(_calc_기준100!$CN$16:$EF$16,1,$E26)>0)*(INDEX(_calc_기준100!$CN$16:$EF$16,1,$E26)<=15)+(INDEX(_calc_기준100!$CN$16:$EF$16,1,$F26)>0)*(INDEX(_calc_기준100!$CN$16:$EF$16,1,$F26)<=15)+(INDEX(_calc_기준100!$CN$16:$EF$16,1,$G26)>0)*(INDEX(_calc_기준100!$CN$16:$EF$16,1,$G26)<=15),"") -> 3 | J26: =IFERROR((INDEX(_calc_기준100!$CN$16:$EF$16,1,$B26)>15)*(INDEX(_calc_기준100!$CN$16:$EF$16,1,$B26)<=30)+(INDEX(_calc_기준100!$CN$16:$EF$16,1,$C26)>15)*(INDEX(_calc_기준100!$CN$16:$EF$16,1,$C26)<=30)+(INDEX(_calc_기준100!$CN$16:$EF$16,1,$D26)>15)*(INDEX(_calc_기준100!$CN$16:$EF$16,1,$D26)<=30)+(INDEX(_calc_기준100!$CN$16:$EF$16,1,$E26)>15)*(INDEX(_calc_기준100!$CN$16:$EF$16,1,$E26)<=30)+(INDEX(_calc_기준100!$CN$16:$EF$16,1,$F26)>15)*(INDEX(_calc_기준100!$CN$16:$EF$16,1,$F26)<=30)+(INDEX(_calc_기준100!$CN$16:$EF$16,1,$G26)>15)*(INDEX(_calc_기준100!$CN$16:$EF$16,1,$G26)<=30),"") -> 2 | K26: =IFERROR((INDEX(_calc_기준100!$CN$16:$EF$16,1,$B26)>30)+(INDEX(_calc_기준100!$CN$16:$EF$16,1,$C26)>30)+(INDEX(_calc_기준100!$CN$16:$EF$16,1,$D26)>30)+(INDEX(_calc_기준100!$CN$16:$EF$16,1,$E26)>30)+(INDEX(_calc_기준100!$CN$16:$EF$16,1,$F26)>30)+(INDEX(_calc_기준100!$CN$16:$EF$16,1,$G26)>30),"") -> 1 | L26: =IFERROR(MATCH(L$11,_calc_기준100!$CN$16:$EF$16,0),"") -> 7 | M26: =IFERROR(MATCH(M$11,_calc_기준100!$CN$16:$EF$16,0),"") -> 21 | N26: =IFERROR(MATCH(N$11,_calc_기준100!$CN$16:$EF$16,0),"") -> 38 | O26: =IFERROR(MATCH(O$11,_calc_기준100!$CN$16:$EF$16,0),"") -> 12 | P26: =IFERROR(MATCH(P$11,_calc_기준100!$CN$16:$EF$16,0),"") -> 35 | Q26: =IFERROR(MATCH(Q$11,_calc_기준100!$CN$16:$EF$16,0),"") -> 39 | R26: =IFERROR(MATCH(R$11,_calc_기준100!$CN$16:$EF$16,0),"") -> 11 | S26: =IFERROR(MATCH(S$11,_calc_기준100!$CN$16:$EF$16,0),"") -> 42 | ... BD26: =IFERROR(MATCH(BD$11,_calc_기준100!$CN$16:$EF$16,0),"") -> 23
A27: =A26-1 -> 1229 | B27: =IFERROR(INDEX(전체당첨내역!$B:$B,MATCH($A27,전체당첨내역!$A:$A,0)),"") -> 12 | C27: =IFERROR(INDEX(전체당첨내역!$C:$C,MATCH($A27,전체당첨내역!$A:$A,0)),"") -> 13 | D27: =IFERROR(INDEX(전체당첨내역!$D:$D,MATCH($A27,전체당첨내역!$A:$A,0)),"") -> 29 | E27: =IFERROR(INDEX(전체당첨내역!$E:$E,MATCH($A27,전체당첨내역!$A:$A,0)),"") -> 34 | F27: =IFERROR(INDEX(전체당첨내역!$F:$F,MATCH($A27,전체당첨내역!$A:$A,0)),"") -> 37 | G27: =IFERROR(INDEX(전체당첨내역!$G:$G,MATCH($A27,전체당첨내역!$A:$A,0)),"") -> 42 | H27: =IFERROR(INDEX(전체당첨내역!$H:$H,MATCH($A27,전체당첨내역!$A:$A,0)),"") -> 16 | I27: =IFERROR((INDEX(_calc_기준100!$CN$17:$EF$17,1,$B27)>0)*(INDEX(_calc_기준100!$CN$17:$EF$17,1,$B27)<=15)+(INDEX(_calc_기준100!$CN$17:$EF$17,1,$C27)>0)*(INDEX(_calc_기준100!$CN$17:$EF$17,1,$C27)<=15)+(INDEX(_calc_기준100!$CN$17:$EF$17,1,$D27)>0)*(INDEX(_calc_기준100!$CN$17:$EF$17,1,$D27)<=15)+(INDEX(_calc_기준100!$CN$17:$EF$17,1,$E27)>0)*(INDEX(_calc_기준100!$CN$17:$EF$17,1,$E27)<=15)+(INDEX(_calc_기준100!$CN$17:$EF$17,1,$F27)>0)*(INDEX(_calc_기준100!$CN$17:$EF$17,1,$F27)<=15)+(INDEX(_calc_기준100!$CN$17:$EF$17,1,$G27)>0)*(INDEX(_calc_기준100!$CN$17:$EF$17,1,$G27)<=15),"") -> 4 | J27: =IFERROR((INDEX(_calc_기준100!$CN$17:$EF$17,1,$B27)>15)*(INDEX(_calc_기준100!$CN$17:$EF$17,1,$B27)<=30)+(INDEX(_calc_기준100!$CN$17:$EF$17,1,$C27)>15)*(INDEX(_calc_기준100!$CN$17:$EF$17,1,$C27)<=30)+(INDEX(_calc_기준100!$CN$17:$EF$17,1,$D27)>15)*(INDEX(_calc_기준100!$CN$17:$EF$17,1,$D27)<=30)+(INDEX(_calc_기준100!$CN$17:$EF$17,1,$E27)>15)*(INDEX(_calc_기준100!$CN$17:$EF$17,1,$E27)<=30)+(INDEX(_calc_기준100!$CN$17:$EF$17,1,$F27)>15)*(INDEX(_calc_기준100!$CN$17:$EF$17,1,$F27)<=30)+(INDEX(_calc_기준100!$CN$17:$EF$17,1,$G27)>15)*(INDEX(_calc_기준100!$CN$17:$EF$17,1,$G27)<=30),"") -> 2 | K27: =IFERROR((INDEX(_calc_기준100!$CN$17:$EF$17,1,$B27)>30)+(INDEX(_calc_기준100!$CN$17:$EF$17,1,$C27)>30)+(INDEX(_calc_기준100!$CN$17:$EF$17,1,$D27)>30)+(INDEX(_calc_기준100!$CN$17:$EF$17,1,$E27)>30)+(INDEX(_calc_기준100!$CN$17:$EF$17,1,$F27)>30)+(INDEX(_calc_기준100!$CN$17:$EF$17,1,$G27)>30),"") -> 0 | L27: =IFERROR(MATCH(L$11,_calc_기준100!$CN$17:$EF$17,0),"") -> 7 | M27: =IFERROR(MATCH(M$11,_calc_기준100!$CN$17:$EF$17,0),"") -> 38 | N27: =IFERROR(MATCH(N$11,_calc_기준100!$CN$17:$EF$17,0),"") -> 21 | O27: =IFERROR(MATCH(O$11,_calc_기준100!$CN$17:$EF$17,0),"") -> 11 | P27: =IFERROR(MATCH(P$11,_calc_기준100!$CN$17:$EF$17,0),"") -> 12 | Q27: =IFERROR(MATCH(Q$11,_calc_기준100!$CN$17:$EF$17,0),"") -> 35 | R27: =IFERROR(MATCH(R$11,_calc_기준100!$CN$17:$EF$17,0),"") -> 39 | S27: =IFERROR(MATCH(S$11,_calc_기준100!$CN$17:$EF$17,0),"") -> 37 | ... BD27: =IFERROR(MATCH(BD$11,_calc_기준100!$CN$17:$EF$17,0),"") -> 23
